Workbook

Sheet Summary
A1: CRM × ERP Matched Contacts Summary
A2: Contacts present in both the CRM contact list and the active ERP customer list, matched by account/customer name.
A4: Metric | B4: Count | C4: % of matched
A5: Matched contacts (this sheet) | B5: =COUNTA('Matched Contacts'!A2:A996) -> 995 | C5: =B5/$B$5 -> 1
A6: Unique accounts represented | B6: =SUMPRODUCT(1/COUNTIF('Matched Contacts'!B2:B996,'Matched Contacts'!B2:B996)) -> 664 | C6: =B6/$B$5 -> 0.66733668
A7: Match (owner & email align) | B7: =COUNTIF('Matched Contacts'!L2:L996,"Match") -> 53 | C7: =B7/$B$5 -> 0.053266332
A8: Different owner only | B8: =COUNTIF('Matched Contacts'!L2:L996,"Different owner") -> 221 | C8: =B8/$B$5 -> 0.22211055
A9: Different contact only | B9: =COUNTIF('Matched Contacts'!L2:L996,"Different contact") -> 206 | C9: =B9/$B$5 -> 0.20703518
A10: Different owner & contact | B10: =COUNTIF('Matched Contacts'!L2:L996,"Different owner & contact") -> 515 | C10: =B10/$B$5 -> 0.51758794

Sheet Matched Contacts
A1: Contact Name | B1: Account Name | C1: Contact Email | D1: Contact Phone | E1: CRM Contact Owner | F1: Customer ID | G1: Customer Class | H1: Customer Region | I1: Route Name | J1: ERP Sales Rep | K1: ERP Account Email | L1: Owner Match
A2: Faith Aganda | B2: 254 Brewing Company | C2: procurement@global-slacker.com | D2: 0726150112 | E2: Susan Ngina | F2: CUST102400 | G2: KPSERVICE | H2: Nairobi Central | I2: Kikuyu Town | J2: Diana Wendy | K2: procurement@global-slacker.com | L2: =IF(AND(TRIM(LOWER(E2))=TRIM(LOWER(J2)),TRIM(LOWER(C2))=TRIM(LOWER(K2))),"Match",IF(AND(NOT(TRIM(LOWER(E2))=TRIM(LOWER(J2))),TRIM(LOWER(C2))=TRIM(LOWER(K2))),"Different owner",IF(AND(TRIM(LOWER(E2))=TRIM(LOWER(J2)),NOT(TRIM(LOWER(C2))=TRIM(LOWER(K2)))),"Different contact","Different owner & contact"))) -> Different owner
A3: Lilian | B3: 254 Brewing Company | E3: Berna Piwang | F3: CUST102400 | G3: KPSERVICE | H3: Nairobi Central | I3: Kikuyu Town | J3: Diana Wendy | K3: procurement@global-slacker.com | L3: =IF(AND(TRIM(LOWER(E3))=TRIM(LOWER(J3)),TRIM(LOWER(C3))=TRIM(LOWER(K3))),"Match",IF(AND(NOT(TRIM(LOWER(E3))=TRIM(LOWER(J3))),TRIM(LOWER(C3))=TRIM(LOWER(K3))),"Different owner",IF(AND(TRIM(LOWER(E3))=TRIM(LOWER(J3)),NOT(TRIM(LOWER(C3))=TRIM(LOWER(K3)))),"Different contact","Different owner & contact"))) -> Different owner & contact
A4: Samantha | B4: 254 Brewing Company | E4: Berna Piwang | F4: CUST102400 | G4: KPSERVICE | H4: Nairobi Central | I4: Kikuyu Town | J4: Diana Wendy | K4: procurement@global-slacker.com | L4: =IF(AND(TRIM(LOWER(E4))=TRIM(LOWER(J4)),TRIM(LOWER(C4))=TRIM(LOWER(K4))),"Match",IF(AND(NOT(TRIM(LOWER(E4))=TRIM(LOWER(J4))),TRIM(LOWER(C4))=TRIM(LOWER(K4))),"Different owner",IF(AND(TRIM(LOWER(E4))=TRIM(LOWER(J4)),NOT(TRIM(LOWER(C4))=TRIM(LOWER(K4)))),"Different contact","Different owner & contact"))) -> Different owner & contact
A5: Mercy Wamboi | B5: 5Th Avenue Management Office | D5: 0708017933 | E5: Berna Piwang | F5: CUST100003 | G5: KPPMGR | H5: Nairobi West | I5: Ngong Road | J5: Berna Piwang | K5: 5thavenuemgmt@gmail.com | L5: =IF(AND(TRIM(LOWER(E5))=TRIM(LOWER(J5)),TRIM(LOWER(C5))=TRIM(LOWER(K5))),"Match",IF(AND(NOT(TRIM(LOWER(E5))=TRIM(LOWER(J5))),TRIM(LOWER(C5))=TRIM(LOWER(K5))),"Different owner",IF(AND(TRIM(LOWER(E5))=TRIM(LOWER(J5)),NOT(TRIM(LOWER(C5))=TRIM(LOWER(K5)))),"Different contact","Different owner & contact"))) -> Different contact
A6: Mirriam Waithera | B6: A.I.C Cure International Hospital | C6: mirriam.waithera@cureinternational.org | E6: Maureen | F6: CUST101927 | G6: KPHEALTH | H6: South Rift | I6: Kijabe | J6: June Chesire | K6: mirriam.waithera@cureinternational.org | L6: =IF(AND(TRIM(LOWER(E6))=TRIM(LOWER(J6)),TRIM(LOWER(C6))=TRIM(LOWER(K6))),"Match",IF(AND(NOT(TRIM(LOWER(E6))=TRIM(LOWER(J6))),TRIM(LOWER(C6))=TRIM(LOWER(K6))),"Different owner",IF(AND(TRIM(LOWER(E6))=TRIM(LOWER(J6)),NOT(TRIM(LOWER(C6))=TRIM(LOWER(K6)))),"Different contact","Different owner & contact"))) -> Different owner
A7: Kevin Wasike | B7: AACC Guest House | C7: kevin@aacc-ceta.org | E7: Mercy Irungu | F7: CUST100007 | G7: KPHOTEL | H7: Nairobi West | I7: Waiyaki Way | J7: Mercyline Kemunto | K7: stores@aacc-ceta.org | L7: =IF(AND(TRIM(LOWER(E7))=TRIM(LOWER(J7)),TRIM(LOWER(C7))=TRIM(LOWER(K7))),"Match",IF(AND(NOT(TRIM(LOWER(E7))=TRIM(LOWER(J7))),TRIM(LOWER(C7))=TRIM(LOWER(K7))),"Different owner",IF(AND(TRIM(LOWER(E7))=TRIM(LOWER(J7)),NOT(TRIM(LOWER(C7))=TRIM(LOWER(K7)))),"Different contact","Different owner & contact"))) -> Different owner & contact
A8: Allan Were | B8: AAR Hospital Limited | C8: allan.were@aarhospital.com | D8: 0725880147 | E8: Doreen Mugwika | F8: CUST101857 | G8: KPHEALTH | H8: Nairobi East | I8: Kiambu | J8: Doreen Mugwika | K8: james.mwaura@aarhospital.com | L8: =IF(AND(TRIM(LOWER(E8))=TRIM(LOWER(J8)),TRIM(LOWER(C8))=TRIM(LOWER(K8))),"Match",IF(AND(NOT(TRIM(LOWER(E8))=TRIM(LOWER(J8))),TRIM(LOWER(C8))=TRIM(LOWER(K8))),"Different owner",IF(AND(TRIM(LOWER(E8))=TRIM(LOWER(J8)),NOT(TRIM(LOWER(C8))=TRIM(LOWER(K8)))),"Different contact","Different owner & contact"))) -> Different contact
A9: Chris Otieno | B9: AAR Hospital Limited | C9: chris.otieno@aarhospital.com | E9: Doreen Mugwika | F9: CUST101857 | G9: KPHEALTH | H9: Nairobi East | I9: Kiambu | J9: Doreen Mugwika | K9: james.mwaura@aarhospital.com | L9: =IF(AND(TRIM(LOWER(E9))=TRIM(LOWER(J9)),TRIM(LOWER(C9))=TRIM(LOWER(K9))),"Match",IF(AND(NOT(TRIM(LOWER(E9))=TRIM(LOWER(J9))),TRIM(LOWER(C9))=TRIM(LOWER(K9))),"Different owner",IF(AND(TRIM(LOWER(E9))=TRIM(LOWER(J9)),NOT(TRIM(LOWER(C9))=TRIM(LOWER(K9)))),"Different contact","Different owner & contact"))) -> Different contact
A10: Christine muema | B10: AAR Hospital Limited | C10: Christine.muema@aarhospital.com | D10: 0793 410 850 | E10: Doreen Mugwika | F10: CUST101857 | G10: KPHEALTH | H10: Nairobi East | I10: Kiambu | J10: Doreen Mugwika | K10: james.mwaura@aarhospital.com | L10: =IF(AND(TRIM(LOWER(E10))=TRIM(LOWER(J10)),TRIM(LOWER(C10))=TRIM(LOWER(K10))),"Match",IF(AND(NOT(TRIM(LOWER(E10))=TRIM(LOWER(J10))),TRIM(LOWER(C10))=TRIM(LOWER(K10))),"Different owner",IF(AND(TRIM(LOWER(E10))=TRIM(LOWER(J10)),NOT(TRIM(LOWER(C10))=TRIM(LOWER(K10)))),"Different contact","Different owner & contact"))) -> Different contact
A11: Sylvia Njeru | B11: AAR Hospital Limited | C11: sylvia.njeru@aarhospital.com | D11: 0723346023 | E11: Doreen Mugwika | F11: CUST101857 | G11: KPHEALTH | H11: Nairobi East | I11: Kiambu | J11: Doreen Mugwika | K11: james.mwaura@aarhospital.com | L11: =IF(AND(TRIM(LOWER(E11))=TRIM(LOWER(J11)),TRIM(LOWER(C11))=TRIM(LOWER(K11))),"Match",IF(AND(NOT(TRIM(LOWER(E11))=TRIM(LOWER(J11))),TRIM(LOWER(C11))=TRIM(LOWER(K11))),"Different owner",IF(AND(TRIM(LOWER(E11))=TRIM(LOWER(J11)),NOT(TRIM(LOWER(C11))=TRIM(LOWER(K11)))),"Different contact","Different owner & contact"))) -> Different contact
A12: Teresa Maina | B12: AAR Insurance Kenya Limited | C12: teresa.maina@aar.co.ke | D12: 0736691196 | E12: Doreen Mugwika | F12: CUST100008 | G12: KPINDUSTRY | H12: Nairobi West | I12: Upper Hill | J12: Doreen Mugwika | K12: rkisese@aar.co.ke | L12: =IF(AND(TRIM(LOWER(E12))=TRIM(LOWER(J12)),TRIM(LOWER(C12))=TRIM(LOWER(K12))),"Match",IF(AND(NOT(TRIM(LOWER(E12))=TRIM(LOWER(J12))),TRIM(LOWER(C12))=TRIM(LOWER(K12))),"Different owner",IF(AND(TRIM(LOWER(E12))=TRIM(LOWER(J12)),NOT(TRIM(LOWER(C12))=TRIM(LOWER(K12)))),"Different contact","Different owner & contact"))) -> Different contact
A13: Benard Kambutu | B13: AHN Kenya Limited | C13: benard@africahealthcarenetwork.com | D13: 0796258271 | E13: Yvonne Otieno | F13: CUST100043 | G13: KPHEALTH | H13: Nairobi West | I13: Mombasa Road | J13: Yvonne Achieng | K13: donie@africahealthcarenetwork.com | L13: =IF(AND(TRIM(LOWER(E13))=TRIM(LOWER(J13)),TRIM(LOWER(C13))=TRIM(LOWER(K13))),"Match",IF(AND(NOT(TRIM(LOWER(E13))=TRIM(LOWER(J13))),TRIM(LOWER(C13))=TRIM(LOWER(K13))),"Different owner",IF(AND(TRIM(LOWER(E13))=TRIM(LOWER(J13)),NOT(TRIM(LOWER(C13))=TRIM(LOWER(K13)))),"Different contact","Different owner & contact"))) -> Different owner & contact
A14: Gillian Kibugi | B14: AIG Kenya Insurance Company Ltd | C14: gillian.kibugi@aig.com | E14: Doreen Mugwika | F14: CUST100045 | G14: KPBANK | H14: Nairobi West | I14: Westlands | J14: Shirleen Chebet | K14: gillian.kibugi@aig.com | L14: =IF(AND(TRIM(LOWER(E14))=TRIM(LOWER(J14)),TRIM(LOWER(C14))=TRIM(LOWER(K14))),"Match",IF(AND(NOT(TRIM(LOWER(E14))=TRIM(LOWER(J14))),TRIM(LOWER(C14))=TRIM(LOWER(K14))),"Different owner",IF(AND(TRIM(LOWER(E14))=TRIM(LOWER(J14)),NOT(TRIM(LOWER(C14))=TRIM(LOWER(K14)))),"Different contact","Different owner & contact"))) -> Different owner
A15: Patrick Angoiya | B15: AMREF Health Africa | C15: patrick.angoiya@amref.org | E15: Irene Luketelo | F15: CUST100067 | G15: KPHEALTH | H15: Nairobi West | I15: Langata Road | J15: Irene Luketelo | K15: samuel.amwata@amref.org | L15: =IF(AND(TRIM(LOWER(E15))=TRIM(LOWER(J15)),TRIM(LOWER(C15))=TRIM(LOWER(K15))),"Match",IF(AND(NOT(TRIM(LOWER(E15))=TRIM(LOWER(J15))),TRIM(LOWER(C15))=TRIM(LOWER(K15))),"Different owner",IF(AND(TRIM(LOWER(E15))=TRIM(LOWER(J15)),NOT(TRIM(LOWER(C15))=TRIM(LOWER(K15)))),"Different contact","Different owner & contact"))) -> Different contact
A16: Kennedy . | B16: Abai Lodges Limited | C16: info@abailodges.com | D16: 0707222555 | E16: John Kaguai | F16: CUST102706 | G16: KPHOTEL | H16: Lower Mountain | I16: Kerugoya | J16: John Kaguai | K16: accounts@abailodges.com | L16: =IF(AND(TRIM(LOWER(E16))=TRIM(LOWER(J16)),TRIM(LOWER(C16))=TRIM(LOWER(K16))),"Match",IF(AND(NOT(TRIM(LOWER(E16))=TRIM(LOWER(J16))),TRIM(LOWER(C16))=TRIM(LOWER(K16))),"Different owner",IF(AND(TRIM(LOWER(E16))=TRIM(LOWER(J16)),NOT(TRIM(LOWER(C16))=TRIM(LOWER(K16)))),"Different contact","Different owner & contact"))) -> Different contact
A17: Winnie Mwangi | B17: Abgai Hygiene Ltd | C17: waynmuhia@gmail.com | D17: 0712636287 | E17: Irene Luketelo | F17: CUST103185 | G17: KPCCLNRS | H17: Nairobi Central | I17: CBD | J17: Irene Luketelo | K17: waynmuhia@gmail.com | L17: =IF(AND(TRIM(LOWER(E17))=TRIM(LOWER(J17)),TRIM(LOWER(C17))=TRIM(LOWER(K17))),"Match",IF(AND(NOT(TRIM(LOWER(E17))=TRIM(LOWER(J17))),TRIM(LOWER(C17))=TRIM(LOWER(K17))),"Different owner",IF(AND(TRIM(LOWER(E17))=TRIM(LOWER(J17)),NOT(TRIM(LOWER(C17))=TRIM(LOWER(K17)))),"Different contact","Different owner & contact"))) -> Match
A18: Tabitha Tabitha | B18: Academy Of Dance And Arts Ltd | C18: origins@academyonline.me | E18: Yvonne Otieno | F18: CUST100010 | G18: KPEDU | H18: Nairobi West | I18: Karen | J18: Diana Wendy | K18: dance@academyonline.me | L18: =IF(AND(TRIM(LOWER(E18))=TRIM(LOWER(J18)),TRIM(LOWER(C18))=TRIM(LOWER(K18))),"Match",IF(AND(NOT(TRIM(LOWER(E18))=TRIM(LOWER(J18))),TRIM(LOWER(C18))=TRIM(LOWER(K18))),"Different owner",IF(AND(TRIM(LOWER(E18))=TRIM(LOWER(J18)),NOT(TRIM(LOWER(C18))=TRIM(LOWER(K18)))),"Different contact","Different owner & contact"))) -> Different owner & contact
A19: Jane Awuor | B19: Adamji Multi Supplies Limited | C19: finance@adamji.co.ke | D19: 0732673200 | E19: June Chesire | F19: CUST100012 | G19: KPDIST | H19: Nairobi East | I19: Mombasa Road | J19: June Chesire | K19: finance@adamji.co.ke | L19: =IF(AND(TRIM(LOWER(E19))=TRIM(LOWER(J19)),TRIM(LOWER(C19))=TRIM(LOWER(K19))),"Match",IF(AND(NOT(TRIM(LOWER(E19))=TRIM(LOWER(J19))),TRIM(LOWER(C19))=TRIM(LOWER(K19))),"Different owner",IF(AND(TRIM(LOWER(E19))=TRIM(LOWER(J19)),NOT(TRIM(LOWER(C19))=TRIM(LOWER(K19)))),"Different contact","Different owner & contact"))) -> Match
A20: Jane Jane | B20: Adamji Multi Supplies Limited | C20: stockcontrol@adamji.co.ke | E20: June Chesire | F20: CUST100012 | G20: KPDIST | H20: Nairobi East | I20: Mombasa Road | J20: June Chesire | K20: finance@adamji.co.ke | L20: =IF(AND(TRIM(LOWER(E20))=TRIM(LOWER(J20)),TRIM(LOWER(C20))=TRIM(LOWER(K20))),"Match",IF(AND(NOT(TRIM(LOWER(E20))=TRIM(LOWER(J20))),TRIM(LOWER(C20))=TRIM(LOWER(K20))),"Different owner",IF(AND(TRIM(LOWER(E20))=TRIM(LOWER(J20)),NOT(TRIM(LOWER(C20))=TRIM(LOWER(K20)))),"Different contact","Different owner & contact"))) -> Different contact
A21: Winnie | B21: Adams Brown & Company Ltd | C21: info@abc-place.com | D21: 0721619018 | E21: Doreen Mugwika | F21: CUST100013 | G21: KPPMGR | H21: Nairobi West | I21: Waiyaki Way | J21: Doreen Mugwika | K21: info@abc-place.com | L21: =IF(AND(TRIM(LOWER(E21))=TRIM(LOWER(J21)),TRIM(LOWER(C21))=TRIM(LOWER(K21))),"Match",IF(AND(NOT(TRIM(LOWER(E21))=TRIM(LOWER(J21))),TRIM(LOWER(C21))=TRIM(LOWER(K21))),"Different owner",IF(AND(TRIM(LOWER(E21))=TRIM(LOWER(J21)),NOT(TRIM(LOWER(C21))=TRIM(LOWER(K21)))),"Different contact","Different owner & contact"))) -> Match
A22: Emma and Tyrus | B22: Adlife Management Company Ltd | E22: Berna Piwang | F22: CUST100014 | G22: KPPMGR | H22: Nairobi West | I22: Hurlingham | J22: Berna Piwang | K22: wenceslaus@adlifeplaza.com | L22: =IF(AND(TRIM(LOWER(E22))=TRIM(LOWER(J22)),TRIM(LOWER(C22))=TRIM(LOWER(K22))),"Match",IF(AND(NOT(TRIM(LOWER(E22))=TRIM(LOWER(J22))),TRIM(LOWER(C22))=TRIM(LOWER(K22))),"Different owner",IF(AND(TRIM(LOWER(E22))=TRIM(LOWER(J22)),NOT(TRIM(LOWER(C22))=TRIM(LOWER(K22)))),"Different contact","Different owner & contact"))) -> Different contact
A23: Ann Wanjira | B23: Adrian Kenya Ltd | C23: ann.wanjira@adriankenya.com | D23: 0726339919 | E23: Yvonne Otieno | F23: CUST100015 | G23: KPINDUSTRY | H23: Nairobi West | I23: Waiyaki Way | J23: Yvonne Achieng | K23: adrianpayables@adriankenya.com | L23: =IF(AND(TRIM(LOWER(E23))=TRIM(LOWER(J23)),TRIM(LOWER(C23))=TRIM(LOWER(K23))),"Match",IF(AND(NOT(TRIM(LOWER(E23))=TRIM(LOWER(J23))),TRIM(LOWER(C23))=TRIM(LOWER(K23))),"Different owner",IF(AND(TRIM(LOWER(E23))=TRIM(LOWER(J23)),NOT(TRIM(LOWER(C23))=TRIM(LOWER(K23)))),"Different contact","Different owner & contact"))) -> Different owner & contact
A24: Veronica Wanjema | B24: Adrian Kenya Ltd | C24: v.wanjema@adriankenya.com | D24: 0726339919 | E24: Yvonne Otieno | F24: CUST100015 | G24: KPINDUSTRY | H24: Nairobi West | I24: Waiyaki Way | J24: Yvonne Achieng | K24: adrianpayables@adriankenya.com | L24: =IF(AND(TRIM(LOWER(E24))=TRIM(LOWER(J24)),TRIM(LOWER(C24))=TRIM(LOWER(K24))),"Match",IF(AND(NOT(TRIM(LOWER(E24))=TRIM(LOWER(J24))),TRIM(LOWER(C24))=TRIM(LOWER(K24))),"Different owner",IF(AND(TRIM(LOWER(E24))=TRIM(LOWER(J24)),NOT(TRIM(LOWER(C24))=TRIM(LOWER(K24)))),"Different contact","Different owner & contact"))) -> Different owner & contact
A25: Mercy Njane | B25: Aero Club East Africa Ltd | C25: admin@aeroclubea.com | E25: Mercy Irungu | F25: CUST100017 | G25: KPAIRLINE | H25: Nairobi East | I25: Wilson Airport | J25: Berna Piwang | K25: purchasing@aeroclubea.com | L25: =IF(AND(TRIM(LOWER(E25))=TRIM(LOWER(J25)),TRIM(LOWER(C25))=TRIM(LOWER(K25))),"Match",IF(AND(NOT(TRIM(LOWER(E25))=TRIM(LOWER(J25))),TRIM(LOWER(C25))=TRIM(LOWER(K25))),"Different owner",IF(AND(TRIM(LOWER(E25))=TRIM(LOWER(J25)),NOT(TRIM(LOWER(C25))=TRIM(LOWER(K25)))),"Different contact","Different owner & contact"))) -> Different owner & contact
A26: Ruth Ndege | B26: Afex Kenya Ltd | C26: ruth.ndege@afexgroup.com | E26: June Chesire | F26: CUST100018 | G26: KPHOTEL | H26: Nairobi West | I26: Waiyaki Way | J26: June Chesire | K26: ruth.ndege@afexgroup.com | L26: =IF(AND(TRIM(LOWER(E26))=TRIM(LOWER(J26)),TRIM(LOWER(C26))=TRIM(LOWER(K26))),"Match",IF(AND(NOT(TRIM(LOWER(E26))=TRIM(LOWER(J26))),TRIM(LOWER(C26))=TRIM(LOWER(K26))),"Different owner",IF(AND(TRIM(LOWER(E26))=TRIM(LOWER(J26)),NOT(TRIM(LOWER(C26))=TRIM(LOWER(K26)))),"Different contact","Different owner & contact"))) -> Match
A27: Joseph Leorso | B27: Afri-Sine Limited T/A Nyali Golf View Residence | E27: Lucy Gakii | F27: CUST101487 | G27: KPHOTEL | H27: Coast | I27: Mombasa | J27: Lucy Rimberia | K27: afrisineltd@gmail.com | L27: =IF(AND(TRIM(LOWER(E27))=TRIM(LOWER(J27)),TRIM(LOWER(C27))=TRIM(LOWER(K27))),"Match",IF(AND(NOT(TRIM(LOWER(E27))=TRIM(LOWER(J27))),TRIM(LOWER(C27))=TRIM(LOWER(K27))),"Different owner",IF(AND(TRIM(LOWER(E27))=TRIM(LOWER(J27)),NOT(TRIM(LOWER(C27))=TRIM(LOWER(K27)))),"Different contact","Different owner & contact"))) -> Different owner & contact
A28: Laban Zewe | B28: Afri-Sine Limited T/A Nyali Golf View Residence | C28: laban@afrisine.co.ke | D28: 0714423826 | E28: Lucy Gakii | F28: CUST101487 | G28: KPHOTEL | H28: Coast | I28: Mombasa | J28: Lucy Rimberia | K28: afrisineltd@gmail.com | L28: =IF(AND(TRIM(LOWER(E28))=TRIM(LOWER(J28)),TRIM(LOWER(C28))=TRIM(LOWER(K28))),"Match",IF(AND(NOT(TRIM(LOWER(E28))=TRIM(LOWER(J28))),TRIM(LOWER(C28))=TRIM(LOWER(K28))),"Different owner",IF(AND(TRIM(LOWER(E28))=TRIM(LOWER(J28)),NOT(TRIM(LOWER(C28))=TRIM(LOWER(K28)))),"Different contact","Different owner & contact"))) -> Different owner & contact
A29: Grace A | B29: Afri-Trail Ventures Ltd | C29: gracem@gmail.com | D29: 0722773443 | E29: June Chesire | F29: CUST100030 | G29: KPDIST | H29: Nairobi Central | I29: CBD | J29: Berna Piwang | K29: afritrail@gmail.com | L29: =IF(AND(TRIM(LOWER(E29))=TRIM(LOWER(J29)),TRIM(LOWER(C29))=TRIM(LOWER(K29))),"Match",IF(AND(NOT(TRIM(LOWER(E29))=TRIM(LOWER(J29))),TRIM(LOWER(C29))=TRIM(LOWER(K29))),"Different owner",IF(AND(TRIM(LOWER(E29))=TRIM(LOWER(J29)),NOT(TRIM(LOWER(C29))=TRIM(LOWER(K29)))),"Different contact","Different owner & contact"))) -> Different owner & contact
A30: Davina Ngina | B30: Africa Reit | C30: info@africareit.com | E30: Mercy Irungu | F30: CUST100019 | G30: KPSERVICE | H30: Nairobi West | I30: Karen | J30: Shirleen Chebet | K30: accounts@africareit.com | L30: =IF(AND(TRIM(LOWER(E30))=TRIM(LOWER(J30)),TRIM(LOWER(C30))=TRIM(LOWER(K30))),"Match",IF(AND(NOT(TRIM(LOWER(E30))=TRIM(LOWER(J30))),TRIM(LOWER(C30))=TRIM(LOWER(K30))),"Different owner",IF(AND(TRIM(LOWER(E30))=TRIM(LOWER(J30)),NOT(TRIM(LOWER(C30))=TRIM(LOWER(K30)))),"Different contact","Different owner & contact"))) -> Different owner & contact
A31: Eric Njenga | B31: African Forest Lodges Ltd | C31: procurement@theforest.co.ke | E31: Mercy Irungu | F31: CUST100023 | G31: KPHOTEL | H31: Nairobi West | I31: Naivasha | J31: Diana Wendy | K31: njengaeric1@gmail.com | L31: =IF(AND(TRIM(LOWER(E31))=TRIM(LOWER(J31)),TRIM(LOWER(C31))=TRIM(LOWER(K31))),"Match",IF(AND(NOT(TRIM(LOWER(E31))=TRIM(LOWER(J31))),TRIM(LOWER(C31))=TRIM(LOWER(K31))),"Different owner",IF(AND(TRIM(LOWER(E31))=TRIM(LOWER(J31)),NOT(TRIM(LOWER(C31))=TRIM(LOWER(K31)))),"Different contact","Different owner & contact"))) -> Different owner & contact
A32: Christine | B32: African Fund For Endagered Wildlife Afew | C32: admin@giraffecentre.org | D32: 0723934980 | E32: Doreen Mugwika | F32: CUST100024 | G32: KPPMGR | H32: Nairobi West | I32: Karen | J32: Doreen Mugwika | K32: solomon@giraffecentre.org | L32: =IF(AND(TRIM(LOWER(E32))=TRIM(LOWER(J32)),TRIM(LOWER(C32))=TRIM(LOWER(K32))),"Match",IF(AND(NOT(TRIM(LOWER(E32))=TRIM(LOWER(J32))),TRIM(LOWER(C32))=TRIM(LOWER(K32))),"Different owner",IF(AND(TRIM(LOWER(E32))=TRIM(LOWER(J32)),NOT(TRIM(LOWER(C32))=TRIM(LOWER(K32)))),"Different contact","Different owner & contact"))) -> Different contact
A33: Bethsheba Getanda | B33: African Population & Health Research Centre | C33: bgetanda@aphrc.org | D33: 0720359978 | E33: Doreen Mugwika | F33: CUST100026 | G33: KPNGO | H33: Nairobi West | I33: Lower Kabete | J33: Doreen Mugwika | K33: guest234@aphrc.org | L33: =IF(AND(TRIM(LOWER(E33))=TRIM(LOWER(J33)),TRIM(LOWER(C33))=TRIM(LOWER(K33))),"Match",IF(AND(NOT(TRIM(LOWER(E33))=TRIM(LOWER(J33))),TRIM(LOWER(C33))=TRIM(LOWER(K33))),"Different owner",IF(AND(TRIM(LOWER(E33))=TRIM(LOWER(J33)),NOT(TRIM(LOWER(C33))=TRIM(LOWER(K33)))),"Different contact","Different owner & contact"))) -> Different contact
A34: Sophie Muoni | B34: African Tulip Ltd C/O Knight Frank | C34: Sophie.Muoni@ke.knightfrank.com | E34: Irene Luketelo | F34: CUST100028 | G34: KPPMGR | H34: Nairobi West | I34: Waiyaki Way | J34: Irene Luketelo | K34: Sophie.Muoni@ke.knightfrank.com | L34: =IF(AND(TRIM(LOWER(E34))=TRIM(LOWER(J34)),TRIM(LOWER(C34))=TRIM(LOWER(K34))),"Match",IF(AND(NOT(TRIM(LOWER(E34))=TRIM(LOWER(J34))),TRIM(LOWER(C34))=TRIM(LOWER(K34))),"Different owner",IF(AND(TRIM(LOWER(E34))=TRIM(LOWER(J34)),NOT(TRIM(LOWER(C34))=TRIM(LOWER(K34)))),"Different contact","Different owner & contact"))) -> Match
A35: Peter Belo | B35: Aga Khan Academy Mombasa | C35: belo@agakhanacademies.org | D35: 0780505044 | E35: Lucy Gakii | F35: CUST100032 | G35: KPEDU | H35: Coast | I35: Mombasa | J35: Lucy Rimberia | K35: sameer.hanif@agakhanacademies.org; vincent.kwendo@oshwalacademy.sc.ke | L35: =IF(AND(TRIM(LOWER(E35))=TRIM(LOWER(J35)),TRIM(LOWER(C35))=TRIM(LOWER(K35))),"Match",IF(AND(NOT(TRIM(LOWER(E35))=TRIM(LOWER(J35))),TRIM(LOWER(C35))=TRIM(LOWER(K35))),"Different owner",IF(AND(TRIM(LOWER(E35))=TRIM(LOWER(J35)),NOT(TRIM(LOWER(C35))=TRIM(LOWER(K35)))),"Different contact","Different owner & contact"))) -> Different owner & contact
A36: Sameer Hanif | B36: Aga Khan Academy Mombasa | C36: sameer.hanif@agakhanacademies.org | E36: Lucy Gakii | F36: CUST100032 | G36: KPEDU | H36: Coast | I36: Mombasa | J36: Lucy Rimberia | K36: sameer.hanif@agakhanacademies.org; vincent.kwendo@oshwalacademy.sc.ke | L36: =IF(AND(TRIM(LOWER(E36))=TRIM(LOWER(J36)),TRIM(LOWER(C36))=TRIM(LOWER(K36))),"Match",IF(AND(NOT(TRIM(LOWER(E36))=TRIM(LOWER(J36))),TRIM(LOWER(C36))=TRIM(LOWER(K36))),"Different owner",IF(AND(TRIM(LOWER(E36))=TRIM(LOWER(J36)),NOT(TRIM(LOWER(C36))=TRIM(LOWER(K36)))),"Different contact","Different owner & contact"))) -> Different owner & contact
A37: shamim damji | B37: Aga Khan Academy Senior School Nairobi | C37: shamim.damji@akesk.org | E37: Yvonne Otieno | F37: CUST100033 | G37: KPEDU | H37: Nairobi West | I37: Parklands | J37: Diana Wendy | K37: sismail@akesk.org | L37: =IF(AND(TRIM(LOWER(E37))=TRIM(LOWER(J37)),TRIM(LOWER(C37))=TRIM(LOWER(K37))),"Match",IF(AND(NOT(TRIM(LOWER(E37))=TRIM(LOWER(J37))),TRIM(LOWER(C37))=TRIM(LOWER(K37))),"Different owner",IF(AND(TRIM(LOWER(E37))=TRIM(LOWER(J37)),NOT(TRIM(LOWER(C37))=TRIM(LOWER(K37)))),"Different contact","Different owner & contact"))) -> Different owner & contact
A38: Gulzar Suleiman | B38: Aga Khan Development Network - Kenya | C38: gulzar.suleman@akdn.org | E38: June Chesire | F38: CUST100034 | G38: KPHEALTH | H38: Nairobi Central | I38: CBD | J38: June Chesire | K38: gulzar.suleman@akdnkenya.org | L38: =IF(AND(TRIM(LOWER(E38))=TRIM(LOWER(J38)),TRIM(LOWER(C38))=TRIM(LOWER(K38))),"Match",IF(AND(NOT(TRIM(LOWER(E38))=TRIM(LOWER(J38))),TRIM(LOWER(C38))=TRIM(LOWER(K38))),"Different owner",IF(AND(TRIM(LOWER(E38))=TRIM(LOWER(J38)),NOT(TRIM(LOWER(C38))=TRIM(LOWER(K38)))),"Different contact","Different owner & contact"))) -> Different contact
A39: Gulzar Suleman | B39: Aga Khan Development Network - Kenya | C39: gulzar.suleman@akdnkenya.org | E39: June Chesire | F39: CUST100034 | G39: KPHEALTH | H39: Nairobi Central | I39: CBD | J39: June Chesire | K39: gulzar.suleman@akdnkenya.org | L39: =IF(AND(TRIM(LOWER(E39))=TRIM(LOWER(J39)),TRIM(LOWER(C39))=TRIM(LOWER(K39))),"Match",IF(AND(NOT(TRIM(LOWER(E39))=TRIM(LOWER(J39))),TRIM(LOWER(C39))=TRIM(LOWER(K39))),"Different owner",IF(AND(TRIM(LOWER(E39))=TRIM(LOWER(J39)),NOT(TRIM(LOWER(C39))=TRIM(LOWER(K39)))),"Different contact","Different owner & contact"))) -> Match
A40: Alice Kariuki | B40: Aga Khan Health Service Kenya | C40: alice.kariuki@aku.edu | E40: June Chesire | F40: CUST100035 | G40: KPHEALTH | H40: Nairobi West | I40: Parklands | J40: June Chesire | K40: anne.nyambura@aku.edu | L40: =IF(AND(TRIM(LOWER(E40))=TRIM(LOWER(J40)),TRIM(LOWER(C40))=TRIM(LOWER(K40))),"Match",IF(AND(NOT(TRIM(LOWER(E40))=TRIM(LOWER(J40))),TRIM(LOWER(C40))=TRIM(LOWER(K40))),"Different owner",IF(AND(TRIM(LOWER(E40))=TRIM(LOWER(J40)),NOT(TRIM(LOWER(C40))=TRIM(LOWER(K40)))),"Different contact","Different owner & contact"))) -> Different contact
...
