Workbook

Sheet Summary
A1: Back order position — audit-trail basis
A2: Every figure is a formula over Episode Detail. Nothing here is hardcoded. Grain = episode (one order x one item x one occurrence); an order with 3 short items counts as 3 episodes but 1 order.
A3: Period (opened_at): | B3: 20 – 25 Jul 2026 | D3: Duration basis: | E3: Working days (Mon–Sat, Sundays & Kenyan holidays excluded)
A5: Metric | B5: Value | C5: Note
A6: Open backorder episodes (order x item) | B6: =COUNTIFS('Episode Detail'!$AT$5:$AT$25,"Open",'Episode Detail'!$AP$5:$AP$25,"No") -> 14 | C6: Base grain of the audit trail
A7: Open back orders (unique) | B7: =SUM('Episode Detail'!$AU$5:$AU$25) -> 14 | C7: DISTINCT order_nbr — comparable to the Acumatica order count
A8: Open items (unique SKUs) | B8: =SUM('Episode Detail'!$AV$5:$AV$25) -> 8 | C8: DISTINCT inventory_id
A9: Total order value on back order (KES) | B9: =SUMIFS('Episode Detail'!$AC$5:$AC$25,'Episode Detail'!$AP$5:$AP$25,"No") -> 3643902.3 | C9: Value of the SHORT LINES only — see note below
A10: Open / at-risk value (KES) | B10: =SUMIFS('Episode Detail'!$AD$5:$AD$25,'Episode Detail'!$AT$5:$AT$25,"Open",'Episode Detail'!$AP$5:$AP$25,"No") -> 2322851.6 | C10: backorder_qty x net price. Recoverable — NOT a loss
A11: Value already fulfilled (KES) | B11: =SUMIFS('Episode Detail'!$AE$5:$AE$25,'Episode Detail'!$AP$5:$AP$25,"No") -> 1315553.2 | C11: shipped_qty x net price
A12: Overall value fill rate | B12: =IFERROR(B11/B9,"") -> 0.36102867 | C12: Fulfilled / total line value
A13: Episodes with ZERO qty shipped | B13: =COUNTIFS('Episode Detail'!$X$5:$X$25,0,'Episode Detail'!$AT$5:$AT$25,"Open",'Episode Detail'!$AP$5:$AP$25,"No") -> 11 | C13: Nothing has left the warehouse on these at all
A14: Open value on those episodes (KES) | B14: =SUMIFS('Episode Detail'!$AD$5:$AD$25,'Episode Detail'!$X$5:$X$25,0,'Episode Detail'!$AT$5:$AT$25,"Open",'Episode Detail'!$AP$5:$AP$25,"No") -> 2154793.7 | C14: Hard stockouts
A15: Episodes older than 7 working days | B15: =COUNTIFS('Episode Detail'!$R$5:$R$25,">"&Lookups!$B$18,'Episode Detail'!$AT$5:$AT$25,"Open",'Episode Detail'!$AP$5:$AP$25,"No") -> 7 | C15: Threshold on Lookups
A16: Open value older than 7 working days (KES) | B16: =SUMIFS('Episode Detail'!$AD$5:$AD$25,'Episode Detail'!$R$5:$R$25,">"&Lookups!$B$18,'Episode Detail'!$AT$5:$AT$25,"Open",'Episode Detail'!$AP$5:$AP$25,"No") -> 251151.06 | C16: Past the channel write-off point
A17: Flagged ESCALATE | B17: =COUNTIFS('Episode Detail'!$AO$5:$AO$25,"ESCALATE",'Episode Detail'!$AP$5:$AP$25,"No") -> 4 | C17: Aged AND above the value floor
A19: Audit-trail measures — what the Acumatica screen cannot tell you
A20: Metric | B20: Value | C20: Note
A21: Resolved episodes in period | B21: =COUNTIFS('Episode Detail'!$AT$5:$AT$25,"Resolved",'Episode Detail'!$AP$5:$AP$25,"No") -> 6 | C21: Closed out — Acumatica loses these entirely
A22: Avg time to resolve | B22: =IFERROR(AVERAGEIFS('Episode Detail'!$R$5:$R$25,'Episode Detail'!$AT$5:$AT$25,"Resolved",'Episode Detail'!$T$5:$T$25,"Yes",'Episode Detail'!$AP$5:$AP$25,"No"),"") -> 5.1666667 | C22: Verified start dates only; backfilled excluded
A23: Avg time to resolve (label) | B23: =IF(B22=0,"Same Day",ROUND(B22,0)&IF(ROUND(B22,0)=1," Day Delay"," Days Delay")) -> 5 Days Delay | C23: Display form, e.g. 5 Days Delay
A24: Longest still open (working days) | B24: =_xlfn.MAXIFS('Episode Detail'!$R$5:$R$25,'Episode Detail'!$AT$5:$AT$25,"Open",'Episode Detail'!$AP$5:$AP$25,"No") -> 15 | C24: Worst live case
A25: Delayed revenue — shipped late (KES) | B25: =SUMIFS('Episode Detail'!$AF$5:$AF$25,'Episode Detail'!$AP$5:$AP$25,"No") -> 320811.34 | C25: Sale HAPPENED, just late. Not a loss
A26: Revenue-days delayed (KES-days) | B26: =SUMIFS('Episode Detail'!$AG$5:$AG$25,'Episode Detail'!$AP$5:$AP$25,"No") -> 524947.6 | C26: Weighted service cost — use this to rank causes
A27: Lost revenue (KES) | B27: =SUMIFS('Episode Detail'!$AH$5:$AH$25,'Episode Detail'!$AP$5:$AP$25,"No") -> 256648.56 | C27: Cancelled, or open past write-off. THIS is loss of sales
A28: of which PRODUCTION family (KES) | B28: =SUMIFS('Episode Detail'!$AH$5:$AH$25,'Episode Detail'!$AK$5:$AK$25,"PRODUCTION",'Episode Detail'!$AP$5:$AP$25,"No") -> 226138.2 | C28: "Loss of sales due to delayed production"
A29: Reason coverage | B29: =IFERROR(COUNTIFS('Episode Detail'!$AJ$5:$AJ$25,"<>(unreasoned)",'Episode Detail'!$AP$5:$AP$25,"No")/COUNTIFS('Episode Detail'!$AP$5:$AP$25,"No"),"") -> 0.95 | C29: Every family split is a sample of this size
A30: Verified start dates | B30: =IFERROR(COUNTIFS('Episode Detail'!$T$5:$T$25,"Yes",'Episode Detail'!$AP$5:$AP$25,"No")/COUNTIFS('Episode Detail'!$AP$5:$AP$25,"No"),"") -> 0.9 | C30: Backfilled durations are minimums
A33: By category
A34: Category | B34: Episodes (all) | C34: Open orders | D34: Order value (KES) | E34: Open value (KES) | F34: Fill rate
A35: Modern Trade T2 | B35: =COUNTIFS('Episode Detail'!$F$5:$F$25,$A35,'Episode Detail'!$AP$5:$AP$25,"No") -> 7 | C35: =SUMPRODUCT(('Episode Detail'!$F$5:$F$25=$A35)*'Episode Detail'!$AU$5:$AU$25) -> 3 | D35: =SUMIFS('Episode Detail'!$AC$5:$AC$25,'Episode Detail'!$F$5:$F$25,$A35,'Episode Detail'!$AP$5:$AP$25,"No") -> 645497 | E35: =SUMIFS('Episode Detail'!$AD$5:$AD$25,'Episode Detail'!$F$5:$F$25,$A35,'Episode Detail'!$AT$5:$AT$25,"Open",'Episode Detail'!$AP$5:$AP$25,"No") -> 168057.9 | F35: =IFERROR((D35-E35)/D35,"") -> 0.73964573
A36: Modern Trade T1 | B36: =COUNTIFS('Episode Detail'!$F$5:$F$25,$A36,'Episode Detail'!$AP$5:$AP$25,"No") -> 5 | C36: =SUMPRODUCT(('Episode Detail'!$F$5:$F$25=$A36)*'Episode Detail'!$AU$5:$AU$25) -> 5 | D36: =SUMIFS('Episode Detail'!$AC$5:$AC$25,'Episode Detail'!$F$5:$F$25,$A36,'Episode Detail'!$AP$5:$AP$25,"No") -> 154298.4 | E36: =SUMIFS('Episode Detail'!$AD$5:$AD$25,'Episode Detail'!$F$5:$F$25,$A36,'Episode Detail'!$AT$5:$AT$25,"Open",'Episode Detail'!$AP$5:$AP$25,"No") -> 154298.4 | F36: =IFERROR((D36-E36)/D36,"") -> 0
A37: Pharmacy | B37: =COUNTIFS('Episode Detail'!$F$5:$F$25,$A37,'Episode Detail'!$AP$5:$AP$25,"No") -> 2 | C37: =SUMPRODUCT(('Episode Detail'!$F$5:$F$25=$A37)*'Episode Detail'!$AU$5:$AU$25) -> 2 | D37: =SUMIFS('Episode Detail'!$AC$5:$AC$25,'Episode Detail'!$F$5:$F$25,$A37,'Episode Detail'!$AP$5:$AP$25,"No") -> 1937402.8 | E37: =SUMIFS('Episode Detail'!$AD$5:$AD$25,'Episode Detail'!$F$5:$F$25,$A37,'Episode Detail'!$AT$5:$AT$25,"Open",'Episode Detail'!$AP$5:$AP$25,"No") -> 1937402.8 | F37: =IFERROR((D37-E37)/D37,"") -> 0
A38: General Trade | B38: =COUNTIFS('Episode Detail'!$F$5:$F$25,$A38,'Episode Detail'!$AP$5:$AP$25,"No") -> 2 | C38: =SUMPRODUCT(('Episode Detail'!$F$5:$F$25=$A38)*'Episode Detail'!$AU$5:$AU$25) -> 1 | D38: =SUMIFS('Episode Detail'!$AC$5:$AC$25,'Episode Detail'!$F$5:$F$25,$A38,'Episode Detail'!$AP$5:$AP$25,"No") -> 880226.6 | E38: =SUMIFS('Episode Detail'!$AD$5:$AD$25,'Episode Detail'!$F$5:$F$25,$A38,'Episode Detail'!$AT$5:$AT$25,"Open",'Episode Detail'!$AP$5:$AP$25,"No") -> 37260 | F38: =IFERROR((D38-E38)/D38,"") -> 0.95766999
A39: Direct To Consumer (Cash Sale) | B39: =COUNTIFS('Episode Detail'!$F$5:$F$25,$A39,'Episode Detail'!$AP$5:$AP$25,"No") -> 1 | C39: =SUMPRODUCT(('Episode Detail'!$F$5:$F$25=$A39)*'Episode Detail'!$AU$5:$AU$25) -> 0 | D39: =SUMIFS('Episode Detail'!$AC$5:$AC$25,'Episode Detail'!$F$5:$F$25,$A39,'Episode Detail'!$AP$5:$AP$25,"No") -> 645 | E39: =SUMIFS('Episode Detail'!$AD$5:$AD$25,'Episode Detail'!$F$5:$F$25,$A39,'Episode Detail'!$AT$5:$AT$25,"Open",'Episode Detail'!$AP$5:$AP$25,"No") -> 0 | F39: =IFERROR((D39-E39)/D39,"") -> 1
A40: Non Traditional Channels | B40: =COUNTIFS('Episode Detail'!$F$5:$F$25,$A40,'Episode Detail'!$AP$5:$AP$25,"No") -> 1 | C40: =SUMPRODUCT(('Episode Detail'!$F$5:$F$25=$A40)*'Episode Detail'!$AU$5:$AU$25) -> 1 | D40: =SUMIFS('Episode Detail'!$AC$5:$AC$25,'Episode Detail'!$F$5:$F$25,$A40,'Episode Detail'!$AP$5:$AP$25,"No") -> 3397.44 | E40: =SUMIFS('Episode Detail'!$AD$5:$AD$25,'Episode Detail'!$F$5:$F$25,$A40,'Episode Detail'!$AT$5:$AT$25,"Open",'Episode Detail'!$AP$5:$AP$25,"No") -> 3397.44 | F40: =IFERROR((D40-E40)/D40,"") -> 0
A41: (not classified) | B41: =COUNTIFS('Episode Detail'!$F$5:$F$25,$A41,'Episode Detail'!$AP$5:$AP$25,"No") -> 2 | C41: =SUMPRODUCT(('Episode Detail'!$F$5:$F$25=$A41)*'Episode Detail'!$AU$5:$AU$25) -> 2 | D41: =SUMIFS('Episode Detail'!$AC$5:$AC$25,'Episode Detail'!$F$5:$F$25,$A41,'Episode Detail'!$AP$5:$AP$25,"No") -> 22435 | E41: =SUMIFS('Episode Detail'!$AD$5:$AD$25,'Episode Detail'!$F$5:$F$25,$A41,'Episode Detail'!$AT$5:$AT$25,"Open",'Episode Detail'!$AP$5:$AP$25,"No") -> 22435 | F41: =IFERROR((D41-E41)/D41,"") -> 0
A42: Total | B42: =SUM(B35:B41) -> 20 | C42: =SUM(C35:C41) -> 14 | D42: =SUM(D35:D41) -> 3643902.3 | E42: =SUM(E35:E41) -> 2322851.6 | F42: =IFERROR((D42-E42)/D42,"") -> 0.36253736
A45: By age bucket | D45: Open episodes only. Lower/Upper are editable (blue).
A46: Age bucket | B46: Lower | C46: Upper | D46: Open episodes | E46: Open orders | F46: Open value (KES)
...

Sheet Filters & Definitions
A1: Filters, provenance & definitions
A2: TEMPLATE / STRUCTURE DEMO. Sample rows use real order numbers, customers and SKUs from the 23 Jul 2026 extract; quantities and dates are illustrative. In production this sheet is written from the resolved API filter payload.
A4: PROVENANCE
A5: Generated at | B5: 2026-07-26 09:15 EAT
A6: Generated by | B6: ipay.user@kim-fay.com
A7: Source | B7: Acumatica REST API -> backorder_episodes / backorder_line_events
A8: Sync run id | B8: 48213
A9: Grain | B9: One row per (order_nbr, inventory_id, episode_no)
A11: FILTERS APPLIED — echoed verbatim from the API payload, do not edit
A12: Filter | B12: Value
A13: Period basis | B13: Backorders that STARTED in the period (opened_at)
A14: Period | B14: 20 – 25 Jul 2026
A15: State | B15: Open + Resolved (All)
A16: Duration basis | B16: Working days (Mon–Sat; Sundays & Kenyan gazetted holidays excluded)
A17: Order type | B17: SO only
A18: Reason family | B18: All
A19: Category / channel | B19: All
A20: Brand | B20: All
A21: Warehouse | B21: All (FGS, TPFGS)
A22: Include excluded-from-KPI episodes | B22: Shown in Episode Detail, outside every KPI
A23: Include backfilled start dates in durations | B23: No
... A25: Include internal / cash-sale accounts | B25: No
A27: CANONICAL FORMULAS — the agreed definitions
A28: Measure | B28: Formula | C28: Note
A29: net_order_qty | B29: order_qty - cancelled_qty | C29: Cancelled qty never counts against fill rate.
A30: open_qty | B30: net_order_qty - shipped_qty | C30: Owed to the customer, including goods already picked.
A31: backorder_qty | B31: GREATEST(0, open_qty - qty_on_shipments) | C31: THE shortage. Excludes goods already on a shipment.
A32: fill_rate | B32: shipped_qty / net_order_qty | C32: Denominator excludes cancelled qty.
A33: revenue_at_risk | B33: backorder_qty x net_unit_price | C33: Still recoverable. NOT a loss.
A34: days (working) | B34: Mon–Sat between opened_at and resolved_at (or as-at date) | C34: Sundays and gazetted holidays excluded.
A35: days_late | B35: GREATEST(0, working_days - promised_lead_time) | C35: Lead time is a Lookups parameter.
A36: delayed_revenue | B36: shipped_late_qty x net_unit_price | C36: Sale HAPPENED, just late. Not a loss.
A37: revenue_days_delayed | B37: delayed_revenue x days_late (KES-days) | C37: Ranks causes by weighted impact.
A38: lost_revenue | B38: cancelled_qty x price, or open value past the write-off threshold | C38: THIS is loss of sales.
A39: brand | B39: Inventory ID prefix -> Lookups brand map | C39: In production, read from the item master instead.
A41: Never add Revenue at Risk + Delayed Revenue + Lost Revenue together — they measure different things and overlap.

Sheet Loss by Reason
A1: Loss by reason family and code
A2: All 33 Acumatica reason codes map to exactly one family. Family rows are shaded; code rows sit beneath them.
A4: Family | B4: Reason code | C4: True supply shortage? | D4: Episodes | E4: Peak qty short | F4: Open value (KES) | G4: Delayed revenue (KES) | H4: Revenue-days delayed | I4: Lost revenue (KES) | J4: Avg days delay
A5: PRODUCTION | B5: — family total — | C5: Yes | D5: =COUNTIFS('Episode Detail'!$AK$5:$AK$25,$A5,'Episode Detail'!$AP$5:$AP$25,"No") -> 8 | E5: =SUMIFS('Episode Detail'!$V$5:$V$25,'Episode Detail'!$AK$5:$AK$25,$A5,'Episode Detail'!$AP$5:$AP$25,"No") -> 3080 | F5: =SUMIFS('Episode Detail'!$AD$5:$AD$25,'Episode Detail'!$AK$5:$AK$25,$A5,'Episode Detail'!$AT$5:$AT$25,"Open",'Episode Detail'!$AP$5:$AP$25,"No") -> 220640.7 | G5: =SUMIFS('Episode Detail'!$AF$5:$AF$25,'Episode Detail'!$AK$5:$AK$25,$A5,'Episode Detail'!$AP$5:$AP$25,"No") -> 68216.1 | H5: =SUMIFS('Episode Detail'!$AG$5:$AG$25,'Episode Detail'!$AK$5:$AK$25,$A5,'Episode Detail'!$AP$5:$AP$25,"No") -> 475654 | I5: =SUMIFS('Episode Detail'!$AH$5:$AH$25,'Episode Detail'!$AK$5:$AK$25,$A5,'Episode Detail'!$AP$5:$AP$25,"No") -> 226138.2 | J5: =IFERROR(AVERAGEIFS('Episode Detail'!$R$5:$R$25,'Episode Detail'!$AK$5:$AK$25,$A5,'Episode Detail'!$T$5:$T$25,"Yes",'Episode Detail'!$AP$5:$AP$25,"No"),"") -> 10.714286
B6: out_of_stock_production | D6: =COUNTIFS('Episode Detail'!$AJ$5:$AJ$25,$B6,'Episode Detail'!$AP$5:$AP$25,"No") -> 4 | E6: =SUMIFS('Episode Detail'!$V$5:$V$25,'Episode Detail'!$AJ$5:$AJ$25,$B6,'Episode Detail'!$AP$5:$AP$25,"No") -> 2266 | F6: =SUMIFS('Episode Detail'!$AD$5:$AD$25,'Episode Detail'!$AJ$5:$AJ$25,$B6,'Episode Detail'!$AT$5:$AT$25,"Open",'Episode Detail'!$AP$5:$AP$25,"No") -> 135137.4 | G6: =SUMIFS('Episode Detail'!$AF$5:$AF$25,'Episode Detail'!$AJ$5:$AJ$25,$B6,'Episode Detail'!$AP$5:$AP$25,"No") -> 68216.1 | H6: =SUMIFS('Episode Detail'!$AG$5:$AG$25,'Episode Detail'!$AJ$5:$AJ$25,$B6,'Episode Detail'!$AP$5:$AP$25,"No") -> 475654 | I6: =SUMIFS('Episode Detail'!$AH$5:$AH$25,'Episode Detail'!$AJ$5:$AJ$25,$B6,'Episode Detail'!$AP$5:$AP$25,"No") -> 140634.9 | J6: =IFERROR(AVERAGEIFS('Episode Detail'!$R$5:$R$25,'Episode Detail'!$AJ$5:$AJ$25,$B6,'Episode Detail'!$T$5:$T$25,"Yes",'Episode Detail'!$AP$5:$AP$25,"No"),"") -> 11
B7: production_stockout | D7: =COUNTIFS('Episode Detail'!$AJ$5:$AJ$25,$B7,'Episode Detail'!$AP$5:$AP$25,"No") -> 0 | E7: =SUMIFS('Episode Detail'!$V$5:$V$25,'Episode Detail'!$AJ$5:$AJ$25,$B7,'Episode Detail'!$AP$5:$AP$25,"No") -> 0 | F7: =SUMIFS('Episode Detail'!$AD$5:$AD$25,'Episode Detail'!$AJ$5:$AJ$25,$B7,'Episode Detail'!$AT$5:$AT$25,"Open",'Episode Detail'!$AP$5:$AP$25,"No") -> 0 | G7: =SUMIFS('Episode Detail'!$AF$5:$AF$25,'Episode Detail'!$AJ$5:$AJ$25,$B7,'Episode Detail'!$AP$5:$AP$25,"No") -> 0 | H7: =SUMIFS('Episode Detail'!$AG$5:$AG$25,'Episode Detail'!$AJ$5:$AJ$25,$B7,'Episode Detail'!$AP$5:$AP$25,"No") -> 0 | I7: =SUMIFS('Episode Detail'!$AH$5:$AH$25,'Episode Detail'!$AJ$5:$AJ$25,$B7,'Episode Detail'!$AP$5:$AP$25,"No") -> 0 | J7: =IFERROR(AVERAGEIFS('Episode Detail'!$R$5:$R$25,'Episode Detail'!$AJ$5:$AJ$25,$B7,'Episode Detail'!$T$5:$T$25,"Yes",'Episode Detail'!$AP$5:$AP$25,"No"),"")
B8: raw_material_stockout | D8: =COUNTIFS('Episode Detail'!$AJ$5:$AJ$25,$B8,'Episode Detail'!$AP$5:$AP$25,"No") -> 1 | E8: =SUMIFS('Episode Detail'!$V$5:$V$25,'Episode Detail'!$AJ$5:$AJ$25,$B8,'Episode Detail'!$AP$5:$AP$25,"No") -> 542 | F8: =SUMIFS('Episode Detail'!$AD$5:$AD$25,'Episode Detail'!$AJ$5:$AJ$25,$B8,'Episode Detail'!$AT$5:$AT$25,"Open",'Episode Detail'!$AP$5:$AP$25,"No") -> 32920.5 | G8: =SUMIFS('Episode Detail'!$AF$5:$AF$25,'Episode Detail'!$AJ$5:$AJ$25,$B8,'Episode Detail'!$AP$5:$AP$25,"No") -> 0 | H8: =SUMIFS('Episode Detail'!$AG$5:$AG$25,'Episode Detail'!$AJ$5:$AJ$25,$B8,'Episode Detail'!$AP$5:$AP$25,"No") -> 0 | I8: =SUMIFS('Episode Detail'!$AH$5:$AH$25,'Episode Detail'!$AJ$5:$AJ$25,$B8,'Episode Detail'!$AP$5:$AP$25,"No") -> 32920.5 | J8: =IFERROR(AVERAGEIFS('Episode Detail'!$R$5:$R$25,'Episode Detail'!$AJ$5:$AJ$25,$B8,'Episode Detail'!$T$5:$T$25,"Yes",'Episode Detail'!$AP$5:$AP$25,"No"),"") -> 13
B9: order_to_make | D9: =COUNTIFS('Episode Detail'!$AJ$5:$AJ$25,$B9,'Episode Detail'!$AP$5:$AP$25,"No") -> 1 | E9: =SUMIFS('Episode Detail'!$V$5:$V$25,'Episode Detail'!$AJ$5:$AJ$25,$B9,'Episode Detail'!$AP$5:$AP$25,"No") -> 260 | F9: =SUMIFS('Episode Detail'!$AD$5:$AD$25,'Episode Detail'!$AJ$5:$AJ$25,$B9,'Episode Detail'!$AT$5:$AT$25,"Open",'Episode Detail'!$AP$5:$AP$25,"No") -> 19500 | G9: =SUMIFS('Episode Detail'!$AF$5:$AF$25,'Episode Detail'!$AJ$5:$AJ$25,$B9,'Episode Detail'!$AP$5:$AP$25,"No") -> 0 | H9: =SUMIFS('Episode Detail'!$AG$5:$AG$25,'Episode Detail'!$AJ$5:$AJ$25,$B9,'Episode Detail'!$AP$5:$AP$25,"No") -> 0 | I9: =SUMIFS('Episode Detail'!$AH$5:$AH$25,'Episode Detail'!$AJ$5:$AJ$25,$B9,'Episode Detail'!$AP$5:$AP$25,"No") -> 19500 | J9: =IFERROR(AVERAGEIFS('Episode Detail'!$R$5:$R$25,'Episode Detail'!$AJ$5:$AJ$25,$B9,'Episode Detail'!$T$5:$T$25,"Yes",'Episode Detail'!$AP$5:$AP$25,"No"),"")
B10: conversion_delays | D10: =COUNTIFS('Episode Detail'!$AJ$5:$AJ$25,$B10,'Episode Detail'!$AP$5:$AP$25,"No") -> 2 | E10: =SUMIFS('Episode Detail'!$V$5:$V$25,'Episode Detail'!$AJ$5:$AJ$25,$B10,'Episode Detail'!$AP$5:$AP$25,"No") -> 12 | F10: =SUMIFS('Episode Detail'!$AD$5:$AD$25,'Episode Detail'!$AJ$5:$AJ$25,$B10,'Episode Detail'!$AT$5:$AT$25,"Open",'Episode Detail'!$AP$5:$AP$25,"No") -> 33082.8 | G10: =SUMIFS('Episode Detail'!$AF$5:$AF$25,'Episode Detail'!$AJ$5:$AJ$25,$B10,'Episode Detail'!$AP$5:$AP$25,"No") -> 0 | H10: =SUMIFS('Episode Detail'!$AG$5:$AG$25,'Episode Detail'!$AJ$5:$AJ$25,$B10,'Episode Detail'!$AP$5:$AP$25,"No") -> 0 | I10: =SUMIFS('Episode Detail'!$AH$5:$AH$25,'Episode Detail'!$AJ$5:$AJ$25,$B10,'Episode Detail'!$AP$5:$AP$25,"No") -> 33082.8 | J10: =IFERROR(AVERAGEIFS('Episode Detail'!$R$5:$R$25,'Episode Detail'!$AJ$5:$AJ$25,$B10,'Episode Detail'!$T$5:$T$25,"Yes",'Episode Detail'!$AP$5:$AP$25,"No"),"") -> 9
B11: conversion_issues | D11: =COUNTIFS('Episode Detail'!$AJ$5:$AJ$25,$B11,'Episode Detail'!$AP$5:$AP$25,"No") -> 0 | E11: =SUMIFS('Episode Detail'!$V$5:$V$25,'Episode Detail'!$AJ$5:$AJ$25,$B11,'Episode Detail'!$AP$5:$AP$25,"No") -> 0 | F11: =SUMIFS('Episode Detail'!$AD$5:$AD$25,'Episode Detail'!$AJ$5:$AJ$25,$B11,'Episode Detail'!$AT$5:$AT$25,"Open",'Episode Detail'!$AP$5:$AP$25,"No") -> 0 | G11: =SUMIFS('Episode Detail'!$AF$5:$AF$25,'Episode Detail'!$AJ$5:$AJ$25,$B11,'Episode Detail'!$AP$5:$AP$25,"No") -> 0 | H11: =SUMIFS('Episode Detail'!$AG$5:$AG$25,'Episode Detail'!$AJ$5:$AJ$25,$B11,'Episode Detail'!$AP$5:$AP$25,"No") -> 0 | I11: =SUMIFS('Episode Detail'!$AH$5:$AH$25,'Episode Detail'!$AJ$5:$AJ$25,$B11,'Episode Detail'!$AP$5:$AP$25,"No") -> 0 | J11: =IFERROR(AVERAGEIFS('Episode Detail'!$R$5:$R$25,'Episode Detail'!$AJ$5:$AJ$25,$B11,'Episode Detail'!$T$5:$T$25,"Yes",'Episode Detail'!$AP$5:$AP$25,"No"),"")
B12: batch_sequence | D12: =COUNTIFS('Episode Detail'!$AJ$5:$AJ$25,$B12,'Episode Detail'!$AP$5:$AP$25,"No") -> 0 | E12: =SUMIFS('Episode Detail'!$V$5:$V$25,'Episode Detail'!$AJ$5:$AJ$25,$B12,'Episode Detail'!$AP$5:$AP$25,"No") -> 0 | F12: =SUMIFS('Episode Detail'!$AD$5:$AD$25,'Episode Detail'!$AJ$5:$AJ$25,$B12,'Episode Detail'!$AT$5:$AT$25,"Open",'Episode Detail'!$AP$5:$AP$25,"No") -> 0 | G12: =SUMIFS('Episode Detail'!$AF$5:$AF$25,'Episode Detail'!$AJ$5:$AJ$25,$B12,'Episode Detail'!$AP$5:$AP$25,"No") -> 0 | H12: =SUMIFS('Episode Detail'!$AG$5:$AG$25,'Episode Detail'!$AJ$5:$AJ$25,$B12,'Episode Detail'!$AP$5:$AP$25,"No") -> 0 | I12: =SUMIFS('Episode Detail'!$AH$5:$AH$25,'Episode Detail'!$AJ$5:$AJ$25,$B12,'Episode Detail'!$AP$5:$AP$25,"No") -> 0 | J12: =IFERROR(AVERAGEIFS('Episode Detail'!$R$5:$R$25,'Episode Detail'!$AJ$5:$AJ$25,$B12,'Episode Detail'!$T$5:$T$25,"Yes",'Episode Detail'!$AP$5:$AP$25,"No"),"")
B13: wrong_moq | D13: =COUNTIFS('Episode Detail'!$AJ$5:$AJ$25,$B13,'Episode Detail'!$AP$5:$AP$25,"No") -> 0 | E13: =SUMIFS('Episode Detail'!$V$5:$V$25,'Episode Detail'!$AJ$5:$AJ$25,$B13,'Episode Detail'!$AP$5:$AP$25,"No") -> 0 | F13: =SUMIFS('Episode Detail'!$AD$5:$AD$25,'Episode Detail'!$AJ$5:$AJ$25,$B13,'Episode Detail'!$AT$5:$AT$25,"Open",'Episode Detail'!$AP$5:$AP$25,"No") -> 0 | G13: =SUMIFS('Episode Detail'!$AF$5:$AF$25,'Episode Detail'!$AJ$5:$AJ$25,$B13,'Episode Detail'!$AP$5:$AP$25,"No") -> 0 | H13: =SUMIFS('Episode Detail'!$AG$5:$AG$25,'Episode Detail'!$AJ$5:$AJ$25,$B13,'Episode Detail'!$AP$5:$AP$25,"No") -> 0 | I13: =SUMIFS('Episode Detail'!$AH$5:$AH$25,'Episode Detail'!$AJ$5:$AJ$25,$B13,'Episode Detail'!$AP$5:$AP$25,"No") -> 0 | J13: =IFERROR(AVERAGEIFS('Episode Detail'!$R$5:$R$25,'Episode Detail'!$AJ$5:$AJ$25,$B13,'Episode Detail'!$T$5:$T$25,"Yes",'Episode Detail'!$AP$5:$AP$25,"No"),"")
A14: PROCUREMENT | B14: — family total — | C14: Yes | D14: =COUNTIFS('Episode Detail'!$AK$5:$AK$25,$A14,'Episode Detail'!$AP$5:$AP$25,"No") -> 5 | E14: =SUMIFS('Episode Detail'!$V$5:$V$25,'Episode Detail'!$AK$5:$AK$25,$A14,'Episode Detail'!$AP$5:$AP$25,"No") -> 108 | F14: =SUMIFS('Episode Detail'!$AD$5:$AD$25,'Episode Detail'!$AK$5:$AK$25,$A14,'Episode Detail'!$AT$5:$AT$25,"Open",'Episode Detail'!$AP$5:$AP$25,"No") -> 203346.9 | G14: =SUMIFS('Episode Detail'!$AF$5:$AF$25,'Episode Detail'!$AK$5:$AK$25,$A14,'Episode Detail'!$AP$5:$AP$25,"No") -> 0 | H14: =SUMIFS('Episode Detail'!$AG$5:$AG$25,'Episode Detail'!$AK$5:$AK$25,$A14,'Episode Detail'!$AP$5:$AP$25,"No") -> 0 | I14: =SUMIFS('Episode Detail'!$AH$5:$AH$25,'Episode Detail'!$AK$5:$AK$25,$A14,'Episode Detail'!$AP$5:$AP$25,"No") -> 30510.36 | J14: =IFERROR(AVERAGEIFS('Episode Detail'!$R$5:$R$25,'Episode Detail'!$AK$5:$AK$25,$A14,'Episode Detail'!$T$5:$T$25,"Yes",'Episode Detail'!$AP$5:$AP$25,"No"),"") -> 3.5
B15: out_of_stock_procurement | D15: =COUNTIFS('Episode Detail'!$AJ$5:$AJ$25,$B15,'Episode Detail'!$AP$5:$AP$25,"No") -> 3 | E15: =SUMIFS('Episode Detail'!$V$5:$V$25,'Episode Detail'!$AJ$5:$AJ$25,$B15,'Episode Detail'!$AP$5:$AP$25,"No") -> 54 | F15: =SUMIFS('Episode Detail'!$AD$5:$AD$25,'Episode Detail'!$AJ$5:$AJ$25,$B15,'Episode Detail'!$AT$5:$AT$25,"Open",'Episode Detail'!$AP$5:$AP$25,"No") -> 121215.6 | G15: =SUMIFS('Episode Detail'!$AF$5:$AF$25,'Episode Detail'!$AJ$5:$AJ$25,$B15,'Episode Detail'!$AP$5:$AP$25,"No") -> 0 | H15: =SUMIFS('Episode Detail'!$AG$5:$AG$25,'Episode Detail'!$AJ$5:$AJ$25,$B15,'Episode Detail'!$AP$5:$AP$25,"No") -> 0 | I15: =SUMIFS('Episode Detail'!$AH$5:$AH$25,'Episode Detail'!$AJ$5:$AJ$25,$B15,'Episode Detail'!$AP$5:$AP$25,"No") -> 30510.36 | J15: =IFERROR(AVERAGEIFS('Episode Detail'!$R$5:$R$25,'Episode Detail'!$AJ$5:$AJ$25,$B15,'Episode Detail'!$T$5:$T$25,"Yes",'Episode Detail'!$AP$5:$AP$25,"No"),"") -> 4
B16: out_of_stock_msa | D16: =COUNTIFS('Episode Detail'!$AJ$5:$AJ$25,$B16,'Episode Detail'!$AP$5:$AP$25,"No") -> 2 | E16: =SUMIFS('Episode Detail'!$V$5:$V$25,'Episode Detail'!$AJ$5:$AJ$25,$B16,'Episode Detail'!$AP$5:$AP$25,"No") -> 54 | F16: =SUMIFS('Episode Detail'!$AD$5:$AD$25,'Episode Detail'!$AJ$5:$AJ$25,$B16,'Episode Detail'!$AT$5:$AT$25,"Open",'Episode Detail'!$AP$5:$AP$25,"No") -> 82131.3 | G16: =SUMIFS('Episode Detail'!$AF$5:$AF$25,'Episode Detail'!$AJ$5:$AJ$25,$B16,'Episode Detail'!$AP$5:$AP$25,"No") -> 0 | H16: =SUMIFS('Episode Detail'!$AG$5:$AG$25,'Episode Detail'!$AJ$5:$AJ$25,$B16,'Episode Detail'!$AP$5:$AP$25,"No") -> 0 | I16: =SUMIFS('Episode Detail'!$AH$5:$AH$25,'Episode Detail'!$AJ$5:$AJ$25,$B16,'Episode Detail'!$AP$5:$AP$25,"No") -> 0 | J16: =IFERROR(AVERAGEIFS('Episode Detail'!$R$5:$R$25,'Episode Detail'!$AJ$5:$AJ$25,$B16,'Episode Detail'!$T$5:$T$25,"Yes",'Episode Detail'!$AP$5:$AP$25,"No"),"") -> 2
B17: delayed_supplier_payment | D17: =COUNTIFS('Episode Detail'!$AJ$5:$AJ$25,$B17,'Episode Detail'!$AP$5:$AP$25,"No") -> 0 | E17: =SUMIFS('Episode Detail'!$V$5:$V$25,'Episode Detail'!$AJ$5:$AJ$25,$B17,'Episode Detail'!$AP$5:$AP$25,"No") -> 0 | F17: =SUMIFS('Episode Detail'!$AD$5:$AD$25,'Episode Detail'!$AJ$5:$AJ$25,$B17,'Episode Detail'!$AT$5:$AT$25,"Open",'Episode Detail'!$AP$5:$AP$25,"No") -> 0 | G17: =SUMIFS('Episode Detail'!$AF$5:$AF$25,'Episode Detail'!$AJ$5:$AJ$25,$B17,'Episode Detail'!$AP$5:$AP$25,"No") -> 0 | H17: =SUMIFS('Episode Detail'!$AG$5:$AG$25,'Episode Detail'!$AJ$5:$AJ$25,$B17,'Episode Detail'!$AP$5:$AP$25,"No") -> 0 | I17: =SUMIFS('Episode Detail'!$AH$5:$AH$25,'Episode Detail'!$AJ$5:$AJ$25,$B17,'Episode Detail'!$AP$5:$AP$25,"No") -> 0 | J17: =IFERROR(AVERAGEIFS('Episode Detail'!$R$5:$R$25,'Episode Detail'!$AJ$5:$AJ$25,$B17,'Episode Detail'!$T$5:$T$25,"Yes",'Episode Detail'!$AP$5:$AP$25,"No"),"")
B18: kebs_stickers | D18: =COUNTIFS('Episode Detail'!$AJ$5:$AJ$25,$B18,'Episode Detail'!$AP$5:$AP$25,"No") -> 0 | E18: =SUMIFS('Episode Detail'!$V$5:$V$25,'Episode Detail'!$AJ$5:$AJ$25,$B18,'Episode Detail'!$AP$5:$AP$25,"No") -> 0 | F18: =SUMIFS('Episode Detail'!$AD$5:$AD$25,'Episode Detail'!$AJ$5:$AJ$25,$B18,'Episode Detail'!$AT$5:$AT$25,"Open",'Episode Detail'!$AP$5:$AP$25,"No") -> 0 | G18: =SUMIFS('Episode Detail'!$AF$5:$AF$25,'Episode Detail'!$AJ$5:$AJ$25,$B18,'Episode Detail'!$AP$5:$AP$25,"No") -> 0 | H18: =SUMIFS('Episode Detail'!$AG$5:$AG$25,'Episode Detail'!$AJ$5:$AJ$25,$B18,'Episode Detail'!$AP$5:$AP$25,"No") -> 0 | I18: =SUMIFS('Episode Detail'!$AH$5:$AH$25,'Episode Detail'!$AJ$5:$AJ$25,$B18,'Episode Detail'!$AP$5:$AP$25,"No") -> 0 | J18: =IFERROR(AVERAGEIFS('Episode Detail'!$R$5:$R$25,'Episode Detail'!$AJ$5:$AJ$25,$B18,'Episode Detail'!$T$5:$T$25,"Yes",'Episode Detail'!$AP$5:$AP$25,"No"),"")
A19: LOGISTICS | B19: — family total — | C19: No | D19: =COUNTIFS('Episode Detail'!$AK$5:$AK$25,$A19,'Episode Detail'!$AP$5:$AP$25,"No") -> 4 | E19: =SUMIFS('Episode Detail'!$V$5:$V$25,'Episode Detail'!$AK$5:$AK$25,$A19,'Episode Detail'!$AP$5:$AP$25,"No") -> 570 | F19: =SUMIFS('Episode Detail'!$AD$5:$AD$25,'Episode Detail'!$AK$5:$AK$25,$A19,'Episode Detail'!$AT$5:$AT$25,"Open",'Episode Detail'!$AP$5:$AP$25,"No") -> 0 | G19: =SUMIFS('Episode Detail'!$AF$5:$AF$25,'Episode Detail'!$AK$5:$AK$25,$A19,'Episode Detail'!$AP$5:$AP$25,"No") -> 252595.24 | H19: =SUMIFS('Episode Detail'!$AG$5:$AG$25,'Episode Detail'!$AK$5:$AK$25,$A19,'Episode Detail'!$AP$5:$AP$25,"No") -> 49293.6 | I19: =SUMIFS('Episode Detail'!$AH$5:$AH$25,'Episode Detail'!$AK$5:$AK$25,$A19,'Episode Detail'!$AP$5:$AP$25,"No") -> 0 | J19: =IFERROR(AVERAGEIFS('Episode Detail'!$R$5:$R$25,'Episode Detail'!$AK$5:$AK$25,$A19,'Episode Detail'!$T$5:$T$25,"Yes",'Episode Detail'!$AP$5:$AP$25,"No"),"") -> 3.25
B20: delay_in_delivery | D20: =COUNTIFS('Episode Detail'!$AJ$5:$AJ$25,$B20,'Episode Detail'!$AP$5:$AP$25,"No") -> 0 | E20: =SUMIFS('Episode Detail'!$V$5:$V$25,'Episode Detail'!$AJ$5:$AJ$25,$B20,'Episode Detail'!$AP$5:$AP$25,"No") -> 0 | F20: =SUMIFS('Episode Detail'!$AD$5:$AD$25,'Episode Detail'!$AJ$5:$AJ$25,$B20,'Episode Detail'!$AT$5:$AT$25,"Open",'Episode Detail'!$AP$5:$AP$25,"No") -> 0 | G20: =SUMIFS('Episode Detail'!$AF$5:$AF$25,'Episode Detail'!$AJ$5:$AJ$25,$B20,'Episode Detail'!$AP$5:$AP$25,"No") -> 0 | H20: =SUMIFS('Episode Detail'!$AG$5:$AG$25,'Episode Detail'!$AJ$5:$AJ$25,$B20,'Episode Detail'!$AP$5:$AP$25,"No") -> 0 | I20: =SUMIFS('Episode Detail'!$AH$5:$AH$25,'Episode Detail'!$AJ$5:$AJ$25,$B20,'Episode Detail'!$AP$5:$AP$25,"No") -> 0 | J20: =IFERROR(AVERAGEIFS('Episode Detail'!$R$5:$R$25,'Episode Detail'!$AJ$5:$AJ$25,$B20,'Episode Detail'!$T$5:$T$25,"Yes",'Episode Detail'!$AP$5:$AP$25,"No"),"")
B21: transfer_delays | D21: =COUNTIFS('Episode Detail'!$AJ$5:$AJ$25,$B21,'Episode Detail'!$AP$5:$AP$25,"No") -> 1 | E21: =SUMIFS('Episode Detail'!$V$5:$V$25,'Episode Detail'!$AJ$5:$AJ$25,$B21,'Episode Detail'!$AP$5:$AP$25,"No") -> 262 | F21: =SUMIFS('Episode Detail'!$AD$5:$AD$25,'Episode Detail'!$AJ$5:$AJ$25,$B21,'Episode Detail'!$AT$5:$AT$25,"Open",'Episode Detail'!$AP$5:$AP$25,"No") -> 0 | G21: =SUMIFS('Episode Detail'!$AF$5:$AF$25,'Episode Detail'!$AJ$5:$AJ$25,$B21,'Episode Detail'!$AP$5:$AP$25,"No") -> 225364.54 | H21: =SUMIFS('Episode Detail'!$AG$5:$AG$25,'Episode Detail'!$AJ$5:$AJ$25,$B21,'Episode Detail'!$AP$5:$AP$25,"No") -> 0 | I21: =SUMIFS('Episode Detail'!$AH$5:$AH$25,'Episode Detail'!$AJ$5:$AJ$25,$B21,'Episode Detail'!$AP$5:$AP$25,"No") -> 0 | J21: =IFERROR(AVERAGEIFS('Episode Detail'!$R$5:$R$25,'Episode Detail'!$AJ$5:$AJ$25,$B21,'Episode Detail'!$T$5:$T$25,"Yes",'Episode Detail'!$AP$5:$AP$25,"No"),"") -> 2
B22: truck_full | D22: =COUNTIFS('Episode Detail'!$AJ$5:$AJ$25,$B22,'Episode Detail'!$AP$5:$AP$25,"No") -> 1 | E22: =SUMIFS('Episode Detail'!$V$5:$V$25,'Episode Detail'!$AJ$5:$AJ$25,$B22,'Episode Detail'!$AP$5:$AP$25,"No") -> 6 | F22: =SUMIFS('Episode Detail'!$AD$5:$AD$25,'Episode Detail'!$AJ$5:$AJ$25,$B22,'Episode Detail'!$AT$5:$AT$25,"Open",'Episode Detail'!$AP$5:$AP$25,"No") -> 0 | G22: =SUMIFS('Episode Detail'!$AF$5:$AF$25,'Episode Detail'!$AJ$5:$AJ$25,$B22,'Episode Detail'!$AP$5:$AP$25,"No") -> 322.5 | H22: =SUMIFS('Episode Detail'!$AG$5:$AG$25,'Episode Detail'!$AJ$5:$AJ$25,$B22,'Episode Detail'!$AP$5:$AP$25,"No") -> 645 | I22: =SUMIFS('Episode Detail'!$AH$5:$AH$25,'Episode Detail'!$AJ$5:$AJ$25,$B22,'Episode Detail'!$AP$5:$AP$25,"No") -> 0 | J22: =IFERROR(AVERAGEIFS('Episode Detail'!$R$5:$R$25,'Episode Detail'!$AJ$5:$AJ$25,$B22,'Episode Detail'!$T$5:$T$25,"Yes",'Episode Detail'!$AP$5:$AP$25,"No"),"") -> 4
B23: did_not_pick_on_shipment | D23: =COUNTIFS('Episode Detail'!$AJ$5:$AJ$25,$B23,'Episode Detail'!$AP$5:$AP$25,"No") -> 2 | E23: =SUMIFS('Episode Detail'!$V$5:$V$25,'Episode Detail'!$AJ$5:$AJ$25,$B23,'Episode Detail'!$AP$5:$AP$25,"No") -> 302 | F23: =SUMIFS('Episode Detail'!$AD$5:$AD$25,'Episode Detail'!$AJ$5:$AJ$25,$B23,'Episode Detail'!$AT$5:$AT$25,"Open",'Episode Detail'!$AP$5:$AP$25,"No") -> 0 | G23: =SUMIFS('Episode Detail'!$AF$5:$AF$25,'Episode Detail'!$AJ$5:$AJ$25,$B23,'Episode Detail'!$AP$5:$AP$25,"No") -> 26908.2 | H23: =SUMIFS('Episode Detail'!$AG$5:$AG$25,'Episode Detail'!$AJ$5:$AJ$25,$B23,'Episode Detail'!$AP$5:$AP$25,"No") -> 48648.6 | I23: =SUMIFS('Episode Detail'!$AH$5:$AH$25,'Episode Detail'!$AJ$5:$AJ$25,$B23,'Episode Detail'!$AP$5:$AP$25,"No") -> 0 | J23: =IFERROR(AVERAGEIFS('Episode Detail'!$R$5:$R$25,'Episode Detail'!$AJ$5:$AJ$25,$B23,'Episode Detail'!$T$5:$T$25,"Yes",'Episode Detail'!$AP$5:$AP$25,"No"),"") -> 3.5
A24: COMMERCIAL | B24: — family total — | C24: No | D24: =COUNTIFS('Episode Detail'!$AK$5:$AK$25,$A24,'Episode Detail'!$AP$5:$AP$25,"No") -> 1 | E24: =SUMIFS('Episode Detail'!$V$5:$V$25,'Episode Detail'!$AK$5:$AK$25,$A24,'Episode Detail'!$AP$5:$AP$25,"No") -> 12 | F24: =SUMIFS('Episode Detail'!$AD$5:$AD$25,'Episode Detail'!$AK$5:$AK$25,$A24,'Episode Detail'!$AT$5:$AT$25,"Open",'Episode Detail'!$AP$5:$AP$25,"No") -> 3397.44 | G24: =SUMIFS('Episode Detail'!$AF$5:$AF$25,'Episode Detail'!$AK$5:$AK$25,$A24,'Episode Detail'!$AP$5:$AP$25,"No") -> 0 | H24: =SUMIFS('Episode Detail'!$AG$5:$AG$25,'Episode Detail'!$AK$5:$AK$25,$A24,'Episode Detail'!$AP$5:$AP$25,"No") -> 0 | I24: =SUMIFS('Episode Detail'!$AH$5:$AH$25,'Episode Detail'!$AK$5:$AK$25,$A24,'Episode Detail'!$AP$5:$AP$25,"No") -> 0 | J24: =IFERROR(AVERAGEIFS('Episode Detail'!$R$5:$R$25,'Episode Detail'!$AK$5:$AK$25,$A24,'Episode Detail'!$T$5:$T$25,"Yes",'Episode Detail'!$AP$5:$AP$25,"No"),"") -> 2
B25: discontinued | D25: =COUNTIFS('Episode Detail'!$AJ$5:$AJ$25,$B25,'Episode Detail'!$AP$5:$AP$25,"No") -> 0 | E25: =SUMIFS('Episode Detail'!$V$5:$V$25,'Episode Detail'!$AJ$5:$AJ$25,$B25,'Episode Detail'!$AP$5:$AP$25,"No") -> 0 | F25: =SUMIFS('Episode Detail'!$AD$5:$AD$25,'Episode Detail'!$AJ$5:$AJ$25,$B25,'Episode Detail'!$AT$5:$AT$25,"Open",'Episode Detail'!$AP$5:$AP$25,"No") -> 0 | G25: =SUMIFS('Episode Detail'!$AF$5:$AF$25,'Episode Detail'!$AJ$5:$AJ$25,$B25,'Episode Detail'!$AP$5:$AP$25,"No") -> 0 | H25: =SUMIFS('Episode Detail'!$AG$5:$AG$25,'Episode Detail'!$AJ$5:$AJ$25,$B25,'Episode Detail'!$AP$5:$AP$25,"No") -> 0 | I25: =SUMIFS('Episode Detail'!$AH$5:$AH$25,'Episode Detail'!$AJ$5:$AJ$25,$B25,'Episode Detail'!$AP$5:$AP$25,"No") -> 0 | J25: =IFERROR(AVERAGEIFS('Episode Detail'!$R$5:$R$25,'Episode Detail'!$AJ$5:$AJ$25,$B25,'Episode Detail'!$T$5:$T$25,"Yes",'Episode Detail'!$AP$5:$AP$25,"No"),"")
B26: pb_discontinued | D26: =COUNTIFS('Episode Detail'!$AJ$5:$AJ$25,$B26,'Episode Detail'!$AP$5:$AP$25,"No") -> 0 | E26: =SUMIFS('Episode Detail'!$V$5:$V$25,'Episode Detail'!$AJ$5:$AJ$25,$B26,'Episode Detail'!$AP$5:$AP$25,"No") -> 0 | F26: =SUMIFS('Episode Detail'!$AD$5:$AD$25,'Episode Detail'!$AJ$5:$AJ$25,$B26,'Episode Detail'!$AT$5:$AT$25,"Open",'Episode Detail'!$AP$5:$AP$25,"No") -> 0 | G26: =SUMIFS('Episode Detail'!$AF$5:$AF$25,'Episode Detail'!$AJ$5:$AJ$25,$B26,'Episode Detail'!$AP$5:$AP$25,"No") -> 0 | H26: =SUMIFS('Episode Detail'!$AG$5:$AG$25,'Episode Detail'!$AJ$5:$AJ$25,$B26,'Episode Detail'!$AP$5:$AP$25,"No") -> 0 | I26: =SUMIFS('Episode Detail'!$AH$5:$AH$25,'Episode Detail'!$AJ$5:$AJ$25,$B26,'Episode Detail'!$AP$5:$AP$25,"No") -> 0 | J26: =IFERROR(AVERAGEIFS('Episode Detail'!$R$5:$R$25,'Episode Detail'!$AJ$5:$AJ$25,$B26,'Episode Detail'!$T$5:$T$25,"Yes",'Episode Detail'!$AP$5:$AP$25,"No"),"")
B27: non_focus | D27: =COUNTIFS('Episode Detail'!$AJ$5:$AJ$25,$B27,'Episode Detail'!$AP$5:$AP$25,"No") -> 1 | E27: =SUMIFS('Episode Detail'!$V$5:$V$25,'Episode Detail'!$AJ$5:$AJ$25,$B27,'Episode Detail'!$AP$5:$AP$25,"No") -> 12 | F27: =SUMIFS('Episode Detail'!$AD$5:$AD$25,'Episode Detail'!$AJ$5:$AJ$25,$B27,'Episode Detail'!$AT$5:$AT$25,"Open",'Episode Detail'!$AP$5:$AP$25,"No") -> 3397.44 | G27: =SUMIFS('Episode Detail'!$AF$5:$AF$25,'Episode Detail'!$AJ$5:$AJ$25,$B27,'Episode Detail'!$AP$5:$AP$25,"No") -> 0 | H27: =SUMIFS('Episode Detail'!$AG$5:$AG$25,'Episode Detail'!$AJ$5:$AJ$25,$B27,'Episode Detail'!$AP$5:$AP$25,"No") -> 0 | I27: =SUMIFS('Episode Detail'!$AH$5:$AH$25,'Episode Detail'!$AJ$5:$AJ$25,$B27,'Episode Detail'!$AP$5:$AP$25,"No") -> 0 | J27: =IFERROR(AVERAGEIFS('Episode Detail'!$R$5:$R$25,'Episode Detail'!$AJ$5:$AJ$25,$B27,'Episode Detail'!$T$5:$T$25,"Yes",'Episode Detail'!$AP$5:$AP$25,"No"),"") -> 2
B28: promo_product | D28: =COUNTIFS('Episode Detail'!$AJ$5:$AJ$25,$B28,'Episode Detail'!$AP$5:$AP$25,"No") -> 0 | E28: =SUMIFS('Episode Detail'!$V$5:$V$25,'Episode Detail'!$AJ$5:$AJ$25,$B28,'Episode Detail'!$AP$5:$AP$25,"No") -> 0 | F28: =SUMIFS('Episode Detail'!$AD$5:$AD$25,'Episode Detail'!$AJ$5:$AJ$25,$B28,'Episode Detail'!$AT$5:$AT$25,"Open",'Episode Detail'!$AP$5:$AP$25,"No") -> 0 | G28: =SUMIFS('Episode Detail'!$AF$5:$AF$25,'Episode Detail'!$AJ$5:$AJ$25,$B28,'Episode Detail'!$AP$5:$AP$25,"No") -> 0 | H28: =SUMIFS('Episode Detail'!$AG$5:$AG$25,'Episode Detail'!$AJ$5:$AJ$25,$B28,'Episode Detail'!$AP$5:$AP$25,"No") -> 0 | I28: =SUMIFS('Episode Detail'!$AH$5:$AH$25,'Episode Detail'!$AJ$5:$AJ$25,$B28,'Episode Detail'!$AP$5:$AP$25,"No") -> 0 | J28: =IFERROR(AVERAGEIFS('Episode Detail'!$R$5:$R$25,'Episode Detail'!$AJ$5:$AJ$25,$B28,'Episode Detail'!$T$5:$T$25,"Yes",'Episode Detail'!$AP$5:$AP$25,"No"),"")
B29: short_expiry | D29: =COUNTIFS('Episode Detail'!$AJ$5:$AJ$25,$B29,'Episode Detail'!$AP$5:$AP$25,"No") -> 0 | E29: =SUMIFS('Episode Detail'!$V$5:$V$25,'Episode Detail'!$AJ$5:$AJ$25,$B29,'Episode Detail'!$AP$5:$AP$25,"No") -> 0 | F29: =SUMIFS('Episode Detail'!$AD$5:$AD$25,'Episode Detail'!$AJ$5:$AJ$25,$B29,'Episode Detail'!$AT$5:$AT$25,"Open",'Episode Detail'!$AP$5:$AP$25,"No") -> 0 | G29: =SUMIFS('Episode Detail'!$AF$5:$AF$25,'Episode Detail'!$AJ$5:$AJ$25,$B29,'Episode Detail'!$AP$5:$AP$25,"No") -> 0 | H29: =SUMIFS('Episode Detail'!$AG$5:$AG$25,'Episode Detail'!$AJ$5:$AJ$25,$B29,'Episode Detail'!$AP$5:$AP$25,"No") -> 0 | I29: =SUMIFS('Episode Detail'!$AH$5:$AH$25,'Episode Detail'!$AJ$5:$AJ$25,$B29,'Episode Detail'!$AP$5:$AP$25,"No") -> 0 | J29: =IFERROR(AVERAGEIFS('Episode Detail'!$R$5:$R$25,'Episode Detail'!$AJ$5:$AJ$25,$B29,'Episode Detail'!$T$5:$T$25,"Yes",'Episode Detail'!$AP$5:$AP$25,"No"),"")
B30: npd | D30: =COUNTIFS('Episode Detail'!$AJ$5:$AJ$25,$B30,'Episode Detail'!$AP$5:$AP$25,"No") -> 0 | E30: =SUMIFS('Episode Detail'!$V$5:$V$25,'Episode Detail'!$AJ$5:$AJ$25,$B30,'Episode Detail'!$AP$5:$AP$25,"No") -> 0 | F30: =SUMIFS('Episode Detail'!$AD$5:$AD$25,'Episode Detail'!$AJ$5:$AJ$25,$B30,'Episode Detail'!$AT$5:$AT$25,"Open",'Episode Detail'!$AP$5:$AP$25,"No") -> 0 | G30: =SUMIFS('Episode Detail'!$AF$5:$AF$25,'Episode Detail'!$AJ$5:$AJ$25,$B30,'Episode Detail'!$AP$5:$AP$25,"No") -> 0 | H30: =SUMIFS('Episode Detail'!$AG$5:$AG$25,'Episode Detail'!$AJ$5:$AJ$25,$B30,'Episode Detail'!$AP$5:$AP$25,"No") -> 0 | I30: =SUMIFS('Episode Detail'!$AH$5:$AH$25,'Episode Detail'!$AJ$5:$AJ$25,$B30,'Episode Detail'!$AP$5:$AP$25,"No") -> 0 | J30: =IFERROR(AVERAGEIFS('Episode Detail'!$R$5:$R$25,'Episode Detail'!$AJ$5:$AJ$25,$B30,'Episode Detail'!$T$5:$T$25,"Yes",'Episode Detail'!$AP$5:$AP$25,"No"),"")
A31: DATA_PROCESS | B31: — family total — | C31: No | D31: =COUNTIFS('Episode Detail'!$AK$5:$AK$25,$A31,'Episode Detail'!$AP$5:$AP$25,"No") -> 1 | E31: =SUMIFS('Episode Detail'!$V$5:$V$25,'Episode Detail'!$AK$5:$AK$25,$A31,'Episode Detail'!$AP$5:$AP$25,"No") -> 1 | F31: =SUMIFS('Episode Detail'!$AD$5:$AD$25,'Episode Detail'!$AK$5:$AK$25,$A31,'Episode Detail'!$AT$5:$AT$25,"Open",'Episode Detail'!$AP$5:$AP$25,"No") -> 2935 | G31: =SUMIFS('Episode Detail'!$AF$5:$AF$25,'Episode Detail'!$AK$5:$AK$25,$A31,'Episode Detail'!$AP$5:$AP$25,"No") -> 0 | H31: =SUMIFS('Episode Detail'!$AG$5:$AG$25,'Episode Detail'!$AK$5:$AK$25,$A31,'Episode Detail'!$AP$5:$AP$25,"No") -> 0 | I31: =SUMIFS('Episode Detail'!$AH$5:$AH$25,'Episode Detail'!$AK$5:$AK$25,$A31,'Episode Detail'!$AP$5:$AP$25,"No") -> 0 | J31: =IFERROR(AVERAGEIFS('Episode Detail'!$R$5:$R$25,'Episode Detail'!$AK$5:$AK$25,$A31,'Episode Detail'!$T$5:$T$25,"Yes",'Episode Detail'!$AP$5:$AP$25,"No"),"") -> 4
B32: delayed_communication | D32: =COUNTIFS('Episode Detail'!$AJ$5:$AJ$25,$B32,'Episode Detail'!$AP$5:$AP$25,"No") -> 0 | E32: =SUMIFS('Episode Detail'!$V$5:$V$25,'Episode Detail'!$AJ$5:$AJ$25,$B32,'Episode Detail'!$AP$5:$AP$25,"No") -> 0 | F32: =SUMIFS('Episode Detail'!$AD$5:$AD$25,'Episode Detail'!$AJ$5:$AJ$25,$B32,'Episode Detail'!$AT$5:$AT$25,"Open",'Episode Detail'!$AP$5:$AP$25,"No") -> 0 | G32: =SUMIFS('Episode Detail'!$AF$5:$AF$25,'Episode Detail'!$AJ$5:$AJ$25,$B32,'Episode Detail'!$AP$5:$AP$25,"No") -> 0 | H32: =SUMIFS('Episode Detail'!$AG$5:$AG$25,'Episode Detail'!$AJ$5:$AJ$25,$B32,'Episode Detail'!$AP$5:$AP$25,"No") -> 0 | I32: =SUMIFS('Episode Detail'!$AH$5:$AH$25,'Episode Detail'!$AJ$5:$AJ$25,$B32,'Episode Detail'!$AP$5:$AP$25,"No") -> 0 | J32: =IFERROR(AVERAGEIFS('Episode Detail'!$R$5:$R$25,'Episode Detail'!$AJ$5:$AJ$25,$B32,'Episode Detail'!$T$5:$T$25,"Yes",'Episode Detail'!$AP$5:$AP$25,"No"),"")
B33: price_difference | D33: =COUNTIFS('Episode Detail'!$AJ$5:$AJ$25,$B33,'Episode Detail'!$AP$5:$AP$25,"No") -> 0 | E33: =SUMIFS('Episode Detail'!$V$5:$V$25,'Episode Detail'!$AJ$5:$AJ$25,$B33,'Episode Detail'!$AP$5:$AP$25,"No") -> 0 | F33: =SUMIFS('Episode Detail'!$AD$5:$AD$25,'Episode Detail'!$AJ$5:$AJ$25,$B33,'Episode Detail'!$AT$5:$AT$25,"Open",'Episode Detail'!$AP$5:$AP$25,"No") -> 0 | G33: =SUMIFS('Episode Detail'!$AF$5:$AF$25,'Episode Detail'!$AJ$5:$AJ$25,$B33,'Episode Detail'!$AP$5:$AP$25,"No") -> 0 | H33: =SUMIFS('Episode Detail'!$AG$5:$AG$25,'Episode Detail'!$AJ$5:$AJ$25,$B33,'Episode Detail'!$AP$5:$AP$25,"No") -> 0 | I33: =SUMIFS('Episode Detail'!$AH$5:$AH$25,'Episode Detail'!$AJ$5:$AJ$25,$B33,'Episode Detail'!$AP$5:$AP$25,"No") -> 0 | J33: =IFERROR(AVERAGEIFS('Episode Detail'!$R$5:$R$25,'Episode Detail'!$AJ$5:$AJ$25,$B33,'Episode Detail'!$T$5:$T$25,"Yes",'Episode Detail'!$AP$5:$AP$25,"No"),"")
B34: price_variance | D34: =COUNTIFS('Episode Detail'!$AJ$5:$AJ$25,$B34,'Episode Detail'!$AP$5:$AP$25,"No") -> 0 | E34: =SUMIFS('Episode Detail'!$V$5:$V$25,'Episode Detail'!$AJ$5:$AJ$25,$B34,'Episode Detail'!$AP$5:$AP$25,"No") -> 0 | F34: =SUMIFS('Episode Detail'!$AD$5:$AD$25,'Episode Detail'!$AJ$5:$AJ$25,$B34,'Episode Detail'!$AT$5:$AT$25,"Open",'Episode Detail'!$AP$5:$AP$25,"No") -> 0 | G34: =SUMIFS('Episode Detail'!$AF$5:$AF$25,'Episode Detail'!$AJ$5:$AJ$25,$B34,'Episode Detail'!$AP$5:$AP$25,"No") -> 0 | H34: =SUMIFS('Episode Detail'!$AG$5:$AG$25,'Episode Detail'!$AJ$5:$AJ$25,$B34,'Episode Detail'!$AP$5:$AP$25,"No") -> 0 | I34: =SUMIFS('Episode Detail'!$AH$5:$AH$25,'Episode Detail'!$AJ$5:$AJ$25,$B34,'Episode Detail'!$AP$5:$AP$25,"No") -> 0 | J34: =IFERROR(AVERAGEIFS('Episode Detail'!$R$5:$R$25,'Episode Detail'!$AJ$5:$AJ$25,$B34,'Episode Detail'!$T$5:$T$25,"Yes",'Episode Detail'!$AP$5:$AP$25,"No"),"")
B35: price_overcharge | D35: =COUNTIFS('Episode Detail'!$AJ$5:$AJ$25,$B35,'Episode Detail'!$AP$5:$AP$25,"No") -> 0 | E35: =SUMIFS('Episode Detail'!$V$5:$V$25,'Episode Detail'!$AJ$5:$AJ$25,$B35,'Episode Detail'!$AP$5:$AP$25,"No") -> 0 | F35: =SUMIFS('Episode Detail'!$AD$5:$AD$25,'Episode Detail'!$AJ$5:$AJ$25,$B35,'Episode Detail'!$AT$5:$AT$25,"Open",'Episode Detail'!$AP$5:$AP$25,"No") -> 0 | G35: =SUMIFS('Episode Detail'!$AF$5:$AF$25,'Episode Detail'!$AJ$5:$AJ$25,$B35,'Episode Detail'!$AP$5:$AP$25,"No") -> 0 | H35: =SUMIFS('Episode Detail'!$AG$5:$AG$25,'Episode Detail'!$AJ$5:$AJ$25,$B35,'Episode Detail'!$AP$5:$AP$25,"No") -> 0 | I35: =SUMIFS('Episode Detail'!$AH$5:$AH$25,'Episode Detail'!$AJ$5:$AJ$25,$B35,'Episode Detail'!$AP$5:$AP$25,"No") -> 0 | J35: =IFERROR(AVERAGEIFS('Episode Detail'!$R$5:$R$25,'Episode Detail'!$AJ$5:$AJ$25,$B35,'Episode Detail'!$T$5:$T$25,"Yes",'Episode Detail'!$AP$5:$AP$25,"No"),"")
B36: invoicing_error | D36: =COUNTIFS('Episode Detail'!$AJ$5:$AJ$25,$B36,'Episode Detail'!$AP$5:$AP$25,"No") -> 0 | E36: =SUMIFS('Episode Detail'!$V$5:$V$25,'Episode Detail'!$AJ$5:$AJ$25,$B36,'Episode Detail'!$AP$5:$AP$25,"No") -> 0 | F36: =SUMIFS('Episode Detail'!$AD$5:$AD$25,'Episode Detail'!$AJ$5:$AJ$25,$B36,'Episode Detail'!$AT$5:$AT$25,"Open",'Episode Detail'!$AP$5:$AP$25,"No") -> 0 | G36: =SUMIFS('Episode Detail'!$AF$5:$AF$25,'Episode Detail'!$AJ$5:$AJ$25,$B36,'Episode Detail'!$AP$5:$AP$25,"No") -> 0 | H36: =SUMIFS('Episode Detail'!$AG$5:$AG$25,'Episode Detail'!$AJ$5:$AJ$25,$B36,'Episode Detail'!$AP$5:$AP$25,"No") -> 0 | I36: =SUMIFS('Episode Detail'!$AH$5:$AH$25,'Episode Detail'!$AJ$5:$AJ$25,$B36,'Episode Detail'!$AP$5:$AP$25,"No") -> 0 | J36: =IFERROR(AVERAGEIFS('Episode Detail'!$R$5:$R$25,'Episode Detail'!$AJ$5:$AJ$25,$B36,'Episode Detail'!$T$5:$T$25,"Yes",'Episode Detail'!$AP$5:$AP$25,"No"),"")
B37: stock_variance | D37: =COUNTIFS('Episode Detail'!$AJ$5:$AJ$25,$B37,'Episode Detail'!$AP$5:$AP$25,"No") -> 0 | E37: =SUMIFS('Episode Detail'!$V$5:$V$25,'Episode Detail'!$AJ$5:$AJ$25,$B37,'Episode Detail'!$AP$5:$AP$25,"No") -> 0 | F37: =SUMIFS('Episode Detail'!$AD$5:$AD$25,'Episode Detail'!$AJ$5:$AJ$25,$B37,'Episode Detail'!$AT$5:$AT$25,"Open",'Episode Detail'!$AP$5:$AP$25,"No") -> 0 | G37: =SUMIFS('Episode Detail'!$AF$5:$AF$25,'Episode Detail'!$AJ$5:$AJ$25,$B37,'Episode Detail'!$AP$5:$AP$25,"No") -> 0 | H37: =SUMIFS('Episode Detail'!$AG$5:$AG$25,'Episode Detail'!$AJ$5:$AJ$25,$B37,'Episode Detail'!$AP$5:$AP$25,"No") -> 0 | I37: =SUMIFS('Episode Detail'!$AH$5:$AH$25,'Episode Detail'!$AJ$5:$AJ$25,$B37,'Episode Detail'!$AP$5:$AP$25,"No") -> 0 | J37: =IFERROR(AVERAGEIFS('Episode Detail'!$R$5:$R$25,'Episode Detail'!$AJ$5:$AJ$25,$B37,'Episode Detail'!$T$5:$T$25,"Yes",'Episode Detail'!$AP$5:$AP$25,"No"),"")
B38: isolation_error | D38: =COUNTIFS('Episode Detail'!$AJ$5:$AJ$25,$B38,'Episode Detail'!$AP$5:$AP$25,"No") -> 0 | E38: =SUMIFS('Episode Detail'!$V$5:$V$25,'Episode Detail'!$AJ$5:$AJ$25,$B38,'Episode Detail'!$AP$5:$AP$25,"No") -> 0 | F38: =SUMIFS('Episode Detail'!$AD$5:$AD$25,'Episode Detail'!$AJ$5:$AJ$25,$B38,'Episode Detail'!$AT$5:$AT$25,"Open",'Episode Detail'!$AP$5:$AP$25,"No") -> 0 | G38: =SUMIFS('Episode Detail'!$AF$5:$AF$25,'Episode Detail'!$AJ$5:$AJ$25,$B38,'Episode Detail'!$AP$5:$AP$25,"No") -> 0 | H38: =SUMIFS('Episode Detail'!$AG$5:$AG$25,'Episode Detail'!$AJ$5:$AJ$25,$B38,'Episode Detail'!$AP$5:$AP$25,"No") -> 0 | I38: =SUMIFS('Episode Detail'!$AH$5:$AH$25,'Episode Detail'!$AJ$5:$AJ$25,$B38,'Episode Detail'!$AP$5:$AP$25,"No") -> 0 | J38: =IFERROR(AVERAGEIFS('Episode Detail'!$R$5:$R$25,'Episode Detail'!$AJ$5:$AJ$25,$B38,'Episode Detail'!$T$5:$T$25,"Yes",'Episode Detail'!$AP$5:$AP$25,"No"),"")
B39: wrong_product_description | D39: =COUNTIFS('Episode Detail'!$AJ$5:$AJ$25,$B39,'Episode Detail'!$AP$5:$AP$25,"No") -> 0 | E39: =SUMIFS('Episode Detail'!$V$5:$V$25,'Episode Detail'!$AJ$5:$AJ$25,$B39,'Episode Detail'!$AP$5:$AP$25,"No") -> 0 | F39: =SUMIFS('Episode Detail'!$AD$5:$AD$25,'Episode Detail'!$AJ$5:$AJ$25,$B39,'Episode Detail'!$AT$5:$AT$25,"Open",'Episode Detail'!$AP$5:$AP$25,"No") -> 0 | G39: =SUMIFS('Episode Detail'!$AF$5:$AF$25,'Episode Detail'!$AJ$5:$AJ$25,$B39,'Episode Detail'!$AP$5:$AP$25,"No") -> 0 | H39: =SUMIFS('Episode Detail'!$AG$5:$AG$25,'Episode Detail'!$AJ$5:$AJ$25,$B39,'Episode Detail'!$AP$5:$AP$25,"No") -> 0 | I39: =SUMIFS('Episode Detail'!$AH$5:$AH$25,'Episode Detail'!$AJ$5:$AJ$25,$B39,'Episode Detail'!$AP$5:$AP$25,"No") -> 0 | J39: =IFERROR(AVERAGEIFS('Episode Detail'!$R$5:$R$25,'Episode Detail'!$AJ$5:$AJ$25,$B39,'Episode Detail'!$T$5:$T$25,"Yes",'Episode Detail'!$AP$5:$AP$25,"No"),"")
B40: wrong_code | D40: =COUNTIFS('Episode Detail'!$AJ$5:$AJ$25,$B40,'Episode Detail'!$AP$5:$AP$25,"No") -> 1 | E40: =SUMIFS('Episode Detail'!$V$5:$V$25,'Episode Detail'!$AJ$5:$AJ$25,$B40,'Episode Detail'!$AP$5:$AP$25,"No") -> 1 | F40: =SUMIFS('Episode Detail'!$AD$5:$AD$25,'Episode Detail'!$AJ$5:$AJ$25,$B40,'Episode Detail'!$AT$5:$AT$25,"Open",'Episode Detail'!$AP$5:$AP$25,"No") -> 2935 | G40: =SUMIFS('Episode Detail'!$AF$5:$AF$25,'Episode Detail'!$AJ$5:$AJ$25,$B40,'Episode Detail'!$AP$5:$AP$25,"No") -> 0 | H40: =SUMIFS('Episode Detail'!$AG$5:$AG$25,'Episode Detail'!$AJ$5:$AJ$25,$B40,'Episode Detail'!$AP$5:$AP$25,"No") -> 0 | I40: =SUMIFS('Episode Detail'!$AH$5:$AH$25,'Episode Detail'!$AJ$5:$AJ$25,$B40,'Episode Detail'!$AP$5:$AP$25,"No") -> 0 | J40: =IFERROR(AVERAGEIFS('Episode Detail'!$R$5:$R$25,'Episode Detail'!$AJ$5:$AJ$25,$B40,'Episode Detail'!$T$5:$T$25,"Yes",'Episode Detail'!$AP$5:$AP$25,"No"),"") -> 4
B41: system_error | D41: =COUNTIFS('Episode Detail'!$AJ$5:$AJ$25,$B41,'Episode Detail'!$AP$5:$AP$25,"No") -> 0 | E41: =SUMIFS('Episode Detail'!$V$5:$V$25,'Episode Detail'!$AJ$5:$AJ$25,$B41,'Episode Detail'!$AP$5:$AP$25,"No") -> 0 | F41: =SUMIFS('Episode Detail'!$AD$5:$AD$25,'Episode Detail'!$AJ$5:$AJ$25,$B41,'Episode Detail'!$AT$5:$AT$25,"Open",'Episode Detail'!$AP$5:$AP$25,"No") -> 0 | G41: =SUMIFS('Episode Detail'!$AF$5:$AF$25,'Episode Detail'!$AJ$5:$AJ$25,$B41,'Episode Detail'!$AP$5:$AP$25,"No") -> 0 | H41: =SUMIFS('Episode Detail'!$AG$5:$AG$25,'Episode Detail'!$AJ$5:$AJ$25,$B41,'Episode Detail'!$AP$5:$AP$25,"No") -> 0 | I41: =SUMIFS('Episode Detail'!$AH$5:$AH$25,'Episode Detail'!$AJ$5:$AJ$25,$B41,'Episode Detail'!$AP$5:$AP$25,"No") -> 0 | J41: =IFERROR(AVERAGEIFS('Episode Detail'!$R$5:$R$25,'Episode Detail'!$AJ$5:$AJ$25,$B41,'Episode Detail'!$T$5:$T$25,"Yes",'Episode Detail'!$AP$5:$AP$25,"No"),"")
...

Sheet Episode Detail
A1: Episode Detail — one row per (order, item, occurrence)
A2: Columns A–M mirror the Acumatica export so the two can sit side by side. Amber columns are live formulas — do not paste over them. Parameters live on Lookups.
A4: Order Nbr. | B4: Order Type | C4: Order Date | D4: Customer | E4: Main Account | F4: Category | G4: Warehouse | H4: Inventory ID | I4: Brand | J4: Item Description | K4: UOM | L4: Order Qty | M4: Unit Price (net) | N4: Backordered On | O4: Resolved On | P4: Window | Q4: Days (calendar) | R4: Days (working) | S4: Delay Label | T4: Start Date Verified? | U4: Episode No. | V4: Peak Backorder Qty | W4: Current Backorder Qty | X4: Shipped Qty | Y4: Shipped Late Qty | Z4: Cancelled Qty | AA4: Partial Fills | AB4: Fill Rate % | AC4: Line Order Value (KES) | AD4: Revenue at Risk (KES) | AE4: Value Fulfilled (KES) | AF4: Delayed Revenue (KES) | AG4: Revenue-Days Delayed | AH4: Lost Revenue (KES) | AI4: Resolution Type | AJ4: Reason Code | AK4: Reason Family | AL4: Reason Notes | AM4: Reason Set By | AN4: Reason Set At | AO4: Escalation Flag | AP4: Excluded from KPI? | AQ4: Exclusion Reason | AR4: Sync Run (opened) | AS4: Sync Run (resolved) | AT4: State | AU4: Order 1st open row | AV4: Item 1st open row
A5: SO363506 | B5: SO | C5: 46213 | D5: Khetia Drapers Ltd - Plus | E5: Khetia Drapers Ltd | F5: Modern Trade T2 | G5: FGS | H5: SIFTP0015 | I5: =IFERROR(INDEX(Lookups!$B$6:$B$10,MATCH(LEFT(H5,3),Lookups!$A$6:$A$10,0)),"(unmapped)") -> Sifa | J5: Sifa TP Emb. Unwrap. Twinpack 20x2s White | K5: CASE | L5: 1356 | M5: 142.55 | N5: 46213 | P5: =IF(ISBLANK(O5),TEXT(N5,"d mmm yyyy")&" – ongoing",IF(TEXT(N5,"mmmyyyy")=TEXT(O5,"mmmyyyy"),TEXT(N5,"d")&" – "&TEXT(O5,"d mmm yyyy"),IF(TEXT(N5,"yyyy")=TEXT(O5,"yyyy"),TEXT(N5,"d mmm")&" – "&TEXT(O5,"d mmm yyyy"),TEXT(N5,"d mmm yyyy")&" – "&TEXT(O5,"d mmm yyyy")))) -> 10 Jul 2026 – ongoing | Q5: =IF(ISBLANK(O5),Lookups!$B$16-N5,O5-N5) -> 16 | R5: =IF(ISBLANK(O5),NETWORKDAYS.INTL(N5,Lookups!$B$16,"0000001")-1,NETWORKDAYS.INTL(N5,O5,"0000001")-1) -> 13 | S5: =IF(R5=0,"Same Day",R5&IF(R5=1," Day Delay"," Days Delay")&IF(T5="Yes",""," (min.)")) -> 13 Days Delay | T5: Yes | U5: 1 | V5: 680 | W5: 420 | X5: 936 | Y5: 0 | Z5: 0 | AA5: 2 | AB5: =IFERROR(X5/(L5-Z5),"") -> 0.69026549 | AC5: =L5*M5 -> 193297.8 | AD5: =W5*M5 -> 59871 | AE5: =X5*M5 -> 133426.8 | AF5: =Y5*M5 -> 0 | AG5: =AF5*MAX(0,R5-Lookups!$B$17) -> 0 | AH5: =IF(ISBLANK(O5),IF(R5>Lookups!$B$18,W5*M5,0),Z5*M5) -> 59871 | AJ5: out_of_stock_production | AK5: PRODUCTION | AL5: Mill line 2 down 11-14 Jul | AM5: j.mwangi | AN5: 46214 | AO5: =IF(AND(R5>Lookups!$B$18,AD5>Lookups!$B$19),"ESCALATE",IF(AD5>Lookups!$B$20,"High value",IF(R5>Lookups!$B$18,"Aged","Monitor"))) -> ESCALATE | AP5: No | AR5: 48100 | AT5: =IF(ISBLANK(O5),"Open","Resolved") -> Open | AU5: =IF(AND($AT5="Open",$AP5="No",COUNTIFS($A$5:$A5,$A5,$AT$5:$AT5,"Open",$AP$5:$AP5,"No")=1),1,0) -> 1 | AV5: =IF(AND($AT5="Open",$AP5="No",COUNTIFS($H$5:$H5,$H5,$AT$5:$AT5,"Open",$AP$5:$AP5,"No")=1),1,0) -> 1
A6: SO363491 | B6: SO | C6: 46213 | D6: Khetia Drapers Ltd - Gigamart | E6: Khetia Drapers Ltd | F6: Modern Trade T2 | G6: FGS | H6: SIFTP0015 | I6: =IFERROR(INDEX(Lookups!$B$6:$B$10,MATCH(LEFT(H6,3),Lookups!$A$6:$A$10,0)),"(unmapped)") -> Sifa | J6: Sifa TP Emb. Unwrap. Twinpack 20x2s White | K6: CASE | L6: 1086 | M6: 142.55 | N6: 46213 | P6: =IF(ISBLANK(O6),TEXT(N6,"d mmm yyyy")&" – ongoing",IF(TEXT(N6,"mmmyyyy")=TEXT(O6,"mmmyyyy"),TEXT(N6,"d")&" – "&TEXT(O6,"d mmm yyyy"),IF(TEXT(N6,"yyyy")=TEXT(O6,"yyyy"),TEXT(N6,"d mmm")&" – "&TEXT(O6,"d mmm yyyy"),TEXT(N6,"d mmm yyyy")&" – "&TEXT(O6,"d mmm yyyy")))) -> 10 Jul 2026 – ongoing | Q6: =IF(ISBLANK(O6),Lookups!$B$16-N6,O6-N6) -> 16 | R6: =IF(ISBLANK(O6),NETWORKDAYS.INTL(N6,Lookups!$B$16,"0000001")-1,NETWORKDAYS.INTL(N6,O6,"0000001")-1) -> 13 | S6: =IF(R6=0,"Same Day",R6&IF(R6=1," Day Delay"," Days Delay")&IF(T6="Yes",""," (min.)")) -> 13 Days Delay | T6: Yes | U6: 1 | V6: 594 | W6: 528 | X6: 558 | Y6: 0 | Z6: 0 | AA6: 1 | AB6: =IFERROR(X6/(L6-Z6),"") -> 0.51381215 | AC6: =L6*M6 -> 154809.3 | AD6: =W6*M6 -> 75266.4 | AE6: =X6*M6 -> 79542.9 | AF6: =Y6*M6 -> 0 | AG6: =AF6*MAX(0,R6-Lookups!$B$17) -> 0 | AH6: =IF(ISBLANK(O6),IF(R6>Lookups!$B$18,W6*M6,0),Z6*M6) -> 75266.4 | AJ6: out_of_stock_production | AK6: PRODUCTION | AL6: Same mill event | AM6: j.mwangi | AN6: 46214 | AO6: =IF(AND(R6>Lookups!$B$18,AD6>Lookups!$B$19),"ESCALATE",IF(AD6>Lookups!$B$20,"High value",IF(R6>Lookups!$B$18,"Aged","Monitor"))) -> ESCALATE | AP6: No | AR6: 48103 | AT6: =IF(ISBLANK(O6),"Open","Resolved") -> Open | AU6: =IF(AND($AT6="Open",$AP6="No",COUNTIFS($A$5:$A6,$A6,$AT$5:$AT6,"Open",$AP$5:$AP6,"No")=1),1,0) -> 1 | AV6: =IF(AND($AT6="Open",$AP6="No",COUNTIFS($H$5:$H6,$H6,$AT$5:$AT6,"Open",$AP$5:$AP6,"No")=1),1,0) -> 0
A7: SO363495 | B7: SO | C7: 46213 | D7: Khetia Drapers Ltd - Eldoret CBD | E7: Khetia Drapers Ltd | F7: Modern Trade T2 | G7: FGS | H7: COSTP0004 | I7: =IFERROR(INDEX(Lookups!$B$6:$B$10,MATCH(LEFT(H7,3),Lookups!$A$6:$A$10,0)),"(unmapped)") -> Cosy | J7: Cosy TP Emb. Wrap. 40s Singles White | K7: CASE | L7: 1128 | M7: 64.55 | N7: 46213 | P7: =IF(ISBLANK(O7),TEXT(N7,"d mmm yyyy")&" – ongoing",IF(TEXT(N7,"mmmyyyy")=TEXT(O7,"mmmyyyy"),TEXT(N7,"d")&" – "&TEXT(O7,"d mmm yyyy"),IF(TEXT(N7,"yyyy")=TEXT(O7,"yyyy"),TEXT(N7,"d mmm")&" – "&TEXT(O7,"d mmm yyyy"),TEXT(N7,"d mmm yyyy")&" – "&TEXT(O7,"d mmm yyyy")))) -> 10 Jul 2026 – ongoing | Q7: =IF(ISBLANK(O7),Lookups!$B$16-N7,O7-N7) -> 16 | R7: =IF(ISBLANK(O7),NETWORKDAYS.INTL(N7,Lookups!$B$16,"0000001")-1,NETWORKDAYS.INTL(N7,O7,"0000001")-1) -> 13 | S7: =IF(R7=0,"Same Day",R7&IF(R7=1," Day Delay"," Days Delay")&IF(T7="Yes",""," (min.)")) -> 13 Days Delay | T7: Yes | U7: 1 | V7: 542 | W7: 510 | X7: 618 | Y7: 0 | Z7: 0 | AA7: 1 | AB7: =IFERROR(X7/(L7-Z7),"") -> 0.54787234 | AC7: =L7*M7 -> 72812.4 | AD7: =W7*M7 -> 32920.5 | AE7: =X7*M7 -> 39891.9 | AF7: =Y7*M7 -> 0 | AG7: =AF7*MAX(0,R7-Lookups!$B$17) -> 0 | AH7: =IF(ISBLANK(O7),IF(R7>Lookups!$B$18,W7*M7,0),Z7*M7) -> 32920.5 | AJ7: raw_material_stockout | AK7: PRODUCTION | AL7: Parent reel short shipped | AM7: j.mwangi | AN7: 46215 | AO7: =IF(AND(R7>Lookups!$B$18,AD7>Lookups!$B$19),"ESCALATE",IF(AD7>Lookups!$B$20,"High value",IF(R7>Lookups!$B$18,"Aged","Monitor"))) -> ESCALATE | AP7: No | AR7: 48106 | AT7: =IF(ISBLANK(O7),"Open","Resolved") -> Open | AU7: =IF(AND($AT7="Open",$AP7="No",COUNTIFS($A$5:$A7,$A7,$AT$5:$AT7,"Open",$AP$5:$AP7,"No")=1),1,0) -> 1 | AV7: =IF(AND($AT7="Open",$AP7="No",COUNTIFS($H$5:$H7,$H7,$AT$5:$AT7,"Open",$AP$5:$AP7,"No")=1),1,0) -> 1
A8: SO363507 | B8: SO | C8: 46213 | D8: Khetia Drapers Ltd - Kakamega Poa | E8: Khetia Drapers Ltd | F8: Modern Trade T2 | G8: FGS | H8: COSTP0006 | I8: =IFERROR(INDEX(Lookups!$B$6:$B$10,MATCH(LEFT(H8,3),Lookups!$A$6:$A$10,0)),"(unmapped)") -> Cosy | J8: Cosy TP Emb. Unwrap. 4x10s White | K8: CASE | L8: 876 | M8: 64.55 | N8: 46213 | O8: 46225 | P8: =IF(ISBLANK(O8),TEXT(N8,"d mmm yyyy")&" – ongoing",IF(TEXT(N8,"mmmyyyy")=TEXT(O8,"mmmyyyy"),TEXT(N8,"d")&" – "&TEXT(O8,"d mmm yyyy"),IF(TEXT(N8,"yyyy")=TEXT(O8,"yyyy"),TEXT(N8,"d mmm")&" – "&TEXT(O8,"d mmm yyyy"),TEXT(N8,"d mmm yyyy")&" – "&TEXT(O8,"d mmm yyyy")))) -> 10 – 22 Jul 2026 | Q8: =IF(ISBLANK(O8),Lookups!$B$16-N8,O8-N8) -> 12 | R8: =IF(ISBLANK(O8),NETWORKDAYS.INTL(N8,Lookups!$B$16,"0000001")-1,NETWORKDAYS.INTL(N8,O8,"0000001")-1) -> 10 | S8: =IF(R8=0,"Same Day",R8&IF(R8=1," Day Delay"," Days Delay")&IF(T8="Yes",""," (min.)")) -> 10 Days Delay | T8: Yes | U8: 1 | V8: 514 | W8: 0 | X8: 876 | Y8: 514 | Z8: 0 | AA8: 3 | AB8: =IFERROR(X8/(L8-Z8),"") -> 1 | AC8: =L8*M8 -> 56545.8 | AD8: =W8*M8 -> 0 | AE8: =X8*M8 -> 56545.8 | AF8: =Y8*M8 -> 33178.7 | AG8: =AF8*MAX(0,R8-Lookups!$B$17) -> 265429.6 | AH8: =IF(ISBLANK(O8),IF(R8>Lookups!$B$18,W8*M8,0),Z8*M8) -> 0 | AI8: shipped_full | AJ8: out_of_stock_production | AK8: PRODUCTION | AL8: Cleared on 22 Jul run | AM8: j.mwangi | AN8: 46215 | AO8: =IF(AND(R8>Lookups!$B$18,AD8>Lookups!$B$19),"ESCALATE",IF(AD8>Lookups!$B$20,"High value",IF(R8>Lookups!$B$18,"Aged","Monitor"))) -> Aged | AP8: No | AR8: 48109 | AS8: 48189 | AT8: =IF(ISBLANK(O8),"Open","Resolved") -> Resolved | AU8: =IF(AND($AT8="Open",$AP8="No",COUNTIFS($A$5:$A8,$A8,$AT$5:$AT8,"Open",$AP$5:$AP8,"No")=1),1,0) -> 0 | AV8: =IF(AND($AT8="Open",$AP8="No",COUNTIFS($H$5:$H8,$H8,$AT$5:$AT8,"Open",$AP$5:$AP8,"No")=1),1,0) -> 0
A9: SO363603 | B9: SO | C9: 46213 | D9: Khetia Drapers Ltd - Thika | E9: Khetia Drapers Ltd | F9: Modern Trade T2 | G9: FGS | H9: FAYTP0013 | I9: =IFERROR(INDEX(Lookups!$B$6:$B$10,MATCH(LEFT(H9,3),Lookups!$A$6:$A$10,0)),"(unmapped)") -> Fay | J9: Fay TP Emb. Wrap. 40s Singles White | K9: CASE | L9: 965 | M9: 73.3 | N9: 46213 | O9: 46223 | P9: =IF(ISBLANK(O9),TEXT(N9,"d mmm yyyy")&" – ongoing",IF(TEXT(N9,"mmmyyyy")=TEXT(O9,"mmmyyyy"),TEXT(N9,"d")&" – "&TEXT(O9,"d mmm yyyy"),IF(TEXT(N9,"yyyy")=TEXT(O9,"yyyy"),TEXT(N9,"d mmm")&" – "&TEXT(O9,"d mmm yyyy"),TEXT(N9,"d mmm yyyy")&" – "&TEXT(O9,"d mmm yyyy")))) -> 10 – 20 Jul 2026 | Q9: =IF(ISBLANK(O9),Lookups!$B$16-N9,O9-N9) -> 10 | R9: =IF(ISBLANK(O9),NETWORKDAYS.INTL(N9,Lookups!$B$16,"0000001")-1,NETWORKDAYS.INTL(N9,O9,"0000001")-1) -> 8 | S9: =IF(R9=0,"Same Day",R9&IF(R9=1," Day Delay"," Days Delay")&IF(T9="Yes",""," (min.)")) -> 8 Days Delay | T9: Yes | U9: 1 | V9: 478 | W9: 0 | X9: 890 | Y9: 478 | Z9: 75 | AA9: 2 | AB9: =IFERROR(X9/(L9-Z9),"") -> 1 | AC9: =L9*M9 -> 70734.5 | AD9: =W9*M9 -> 0 | AE9: =X9*M9 -> 65237 | AF9: =Y9*M9 -> 35037.4 | AG9: =AF9*MAX(0,R9-Lookups!$B$17) -> 210224.4 | AH9: =IF(ISBLANK(O9),IF(R9>Lookups!$B$18,W9*M9,0),Z9*M9) -> 5497.5 | AI9: shipped_partial | AJ9: out_of_stock_production | AK9: PRODUCTION | AL9: 75 CASE cancelled by buyer | AM9: j.mwangi | AN9: 46215 | AO9: =IF(AND(R9>Lookups!$B$18,AD9>Lookups!$B$19),"ESCALATE",IF(AD9>Lookups!$B$20,"High value",IF(R9>Lookups!$B$18,"Aged","Monitor"))) -> Aged | AP9: No | AR9: 48112 | AS9: 48192 | AT9: =IF(ISBLANK(O9),"Open","Resolved") -> Resolved | AU9: =IF(AND($AT9="Open",$AP9="No",COUNTIFS($A$5:$A9,$A9,$AT$5:$AT9,"Open",$AP$5:$AP9,"No")=1),1,0) -> 0 | AV9: =IF(AND($AT9="Open",$AP9="No",COUNTIFS($H$5:$H9,$H9,$AT$5:$AT9,"Open",$AP$5:$AP9,"No")=1),1,0) -> 0
A10: SO367035 | B10: SO | C10: 46226 | D10: Majid Al Futtaim Hypermarkets Ltd - Business Bay Square | E10: Majid Al Futtaim Hypermarkets Ltd | F10: Modern Trade T1 | G10: FGS | H10: FAYFL0010 | I10: =IFERROR(INDEX(Lookups!$B$6:$B$10,MATCH(LEFT(H10,3),Lookups!$A$6:$A$10,0)),"(unmapped)") -> Fay | J10: Fay Aluminium Foil Catering (45x50m) | K10: ROLL | L10: 24 | M10: 2542.53 | N10: 46226 | P10: =IF(ISBLANK(O10),TEXT(N10,"d mmm yyyy")&" – ongoing",IF(TEXT(N10,"mmmyyyy")=TEXT(O10,"mmmyyyy"),TEXT(N10,"d")&" – "&TEXT(O10,"d mmm yyyy"),IF(TEXT(N10,"yyyy")=TEXT(O10,"yyyy"),TEXT(N10,"d mmm")&" – "&TEXT(O10,"d mmm yyyy"),TEXT(N10,"d mmm yyyy")&" – "&TEXT(O10,"d mmm yyyy")))) -> 23 Jul 2026 – ongoing | Q10: =IF(ISBLANK(O10),Lookups!$B$16-N10,O10-N10) -> 3 | R10: =IF(ISBLANK(O10),NETWORKDAYS.INTL(N10,Lookups!$B$16,"0000001")-1,NETWORKDAYS.INTL(N10,O10,"0000001")-1) -> 2 | S10: =IF(R10=0,"Same Day",R10&IF(R10=1," Day Delay"," Days Delay")&IF(T10="Yes",""," (min.)")) -> 2 Days Delay | T10: Yes | U10: 1 | V10: 24 | W10: 24 | X10: 0 | Y10: 0 | Z10: 0 | AA10: 0 | AB10: =IFERROR(X10/(L10-Z10),"") -> 0 | AC10: =L10*M10 -> 61020.72 | AD10: =W10*M10 -> 61020.72 | AE10: =X10*M10 -> 0 | AF10: =Y10*M10 -> 0 | AG10: =AF10*MAX(0,R10-Lookups!$B$17) -> 0 | AH10: =IF(ISBLANK(O10),IF(R10>Lookups!$B$18,W10*M10,0),Z10*M10) -> 0 | AJ10: out_of_stock_procurement | AK10: PROCUREMENT | AL10: Import ETA 29 Jul | AM10: a.otieno | AN10: 46226 | AO10: =IF(AND(R10>Lookups!$B$18,AD10>Lookups!$B$19),"ESCALATE",IF(AD10>Lookups!$B$20,"High value",IF(R10>Lookups!$B$18,"Aged","Monitor"))) -> Monitor | AP10: No | AR10: 48115 | AT10: =IF(ISBLANK(O10),"Open","Resolved") -> Open | AU10: =IF(AND($AT10="Open",$AP10="No",COUNTIFS($A$5:$A10,$A10,$AT$5:$AT10,"Open",$AP$5:$AP10,"No")=1),1,0) -> 1 | AV10: =IF(AND($AT10="Open",$AP10="No",COUNTIFS($H$5:$H10,$H10,$AT$5:$AT10,"Open",$AP$5:$AP10,"No")=1),1,0) -> 1
