Workbook

Sheet Filters & Definitions
A1: Backorder Audit Trail — Export
A2: TEMPLATE / STRUCTURE DEMO. Sample rows use real order numbers, customers and SKUs from the 23 Jul 2026 extract; quantities and dates are illustrative. Replace with output of BackorderQueryBuilder.
A4: REPORT PROVENANCE
A5: Generated at | B5: 2026-07-26 09:15 EAT
A6: Generated by | B6: ipay.user@kim-fay.com
A7: Source | B7: Acumatica REST API via backorder_episodes / backorder_line_events
A8: Sync run id | B8: 48213
A9: Snapshot basis | B9: Live (episodes as at generation time)
A11: FILTERS APPLIED (echoed verbatim from the API payload — do not edit)
A12: Filter | B12: Value
A13: Period basis | B13: Backorders that STARTED in the period (opened_at)
A14: Period | B14: 20 – 25 Jul 2026
A15: State | B15: Open + Resolved (All)
A16: Duration basis | B16: Working days (Mon–Sat, Sundays & Kenyan gazetted holidays excluded)
A17: Order type | B17: SO only
A18: Reason family | B18: All
A19: Channel | B19: All
A20: Warehouse | B20: All (FGS, TPFGS)
A21: Include excluded-from-KPI episodes | B21: Yes — shown, but not in KPI totals
A22: Include backfilled start dates in durations | B22: No
A23: Include zero-value / free lines | B23: No
A24: Include internal / cash-sale accounts | B24: No
A26: DATA QUALITY — read before quoting any figure
A27: Measure | B27: Value | C27: Meaning
A28: Reason coverage | B28: 64.2% | C28: Share of episodes carrying a reason_code. Every family split is a sample of this size.
A29: Backfilled start dates | B29: 16.2% | C29: Episodes open before the ledger went live. Their durations are MINIMUMS, labelled "(min.)".
A30: Episodes excluded from KPIs | B30: 19 | C30: Free lines, zero-value lines, rejected/on-hold headers, internal accounts.
A31: Reconciled to Acumatica | B31: Yes — variance 0.31% | C31: Gate is 0.5%. See the Acumatica Bridge sheet.
A33: CANONICAL FORMULAS — these are the agreed definitions
A34: Measure | B34: Formula | C34: Note
A35: net_order_qty | B35: order_qty - cancelled_qty | C35: Cancelled qty never counts against fill rate.
A36: open_qty | B36: net_order_qty - shipped_qty | C36: Owed to the customer, including goods already picked.
A37: backorder_qty | B37: GREATEST(0, open_qty - qty_on_shipments) | C37: THE shortage. Excludes goods already on a shipment.
A38: line_fill_rate_pct | B38: shipped_qty / net_order_qty | C38: Denominator excludes cancelled qty.
A39: revenue_at_risk | B39: backorder_qty x net_unit_price | C39: Still recoverable. NOT a loss.
A40: days_to_resolve | B40: resolved_at - opened_at (calendar days) | C40: Blank while open; ageing uses NOW().
A41: working_days_to_resolve | B41: As above, excluding Sundays + gazetted holidays | C41: Default basis for service KPIs.
A42: days_late | B42: GREATEST(0, working_days - promised_lead_time_days) | C42: Promised lead time is per channel.
A43: delayed_revenue | B43: shipped_late_qty x net_unit_price | C43: Sale HAPPENED, just late. Not a loss.
A44: revenue_days_delayed | B44: delayed_revenue x days_late (KES-days) | C44: Ranks causes by weighted impact.
...

Sheet Summary
A1: Summary — 20 – 25 Jul 2026
A2: All values are formulas referencing Episode Detail. Nothing on this sheet is hardcoded.
A4: KPI | B4: Value | C4: Basis / caveat
A5: Open episodes | B5: =COUNTIFS('Episode Detail'!$AP$5:$AP$22,"Open",'Episode Detail'!$AL$5:$AL$22,"No") -> 12 | C5: Excludes free / zero-value lines
A6: Open orders (distinct) | B6: =SUM('Episode Detail'!$AQ$5:$AQ$22) -> 12 | C6: DISTINCT order_nbr via helper column AQ — never a row count
A7: Open items (distinct SKUs) | B7: =SUM('Episode Detail'!$AR$5:$AR$22) -> 8 | C7: DISTINCT inventory_id via helper column AR
A8: Revenue at Risk (KES) | B8: =SUMIFS('Episode Detail'!$AB$5:$AB$22,'Episode Detail'!$AP$5:$AP$22,"Open",'Episode Detail'!$AL$5:$AL$22,"No") -> 2274582.8 | C8: Open only. Recoverable — NOT a loss
A9: Resolved episodes | B9: =COUNTIFS('Episode Detail'!$AP$5:$AP$22,"Resolved",'Episode Detail'!$AL$5:$AL$22,"No") -> 5 | C9: In-period resolutions
A10: Avg Time to Resolve (working days) | B10: =IFERROR(AVERAGEIFS('Episode Detail'!$Q$5:$Q$22,'Episode Detail'!$AP$5:$AP$22,"Resolved",'Episode Detail'!$S$5:$S$22,"Yes",'Episode Detail'!$AL$5:$AL$22,"No"),"") -> 5.6 | C10: Verified start dates only — backfilled excluded
A11: Longest open (working days) | B11: =_xlfn.MAXIFS('Episode Detail'!$Q$5:$Q$22,'Episode Detail'!$AP$5:$AP$22,"Open",'Episode Detail'!$AL$5:$AL$22,"No") -> 15 | C11: Ageing against as-at date
A12: Delayed Revenue (KES) | B12: =SUMIFS('Episode Detail'!$AC$5:$AC$22,'Episode Detail'!$AL$5:$AL$22,"No") -> 320488.84 | C12: Shipped late. Sale happened
A13: Revenue-Days Delayed (KES-days) | B13: =SUMIFS('Episode Detail'!$AD$5:$AD$22,'Episode Detail'!$AL$5:$AL$22,"No") -> 534994.6 | C13: Weighted service cost — use to rank causes
A14: Lost Revenue (KES) | B14: =SUMIFS('Episode Detail'!$AE$5:$AE$22,'Episode Detail'!$AL$5:$AL$22,"No") -> 256648.56 | C14: THIS is loss of sales
A15: Reason coverage | B15: =IFERROR(COUNTIFS('Episode Detail'!$AG$5:$AG$22,"<>(unreasoned)",'Episode Detail'!$AL$5:$AL$22,"No")/COUNTIFS('Episode Detail'!$AL$5:$AL$22,"No"),"") -> 0.94117647 | C15: Every family split is a sample of this size
A16: Verified start dates | B16: =IFERROR(COUNTIFS('Episode Detail'!$S$5:$S$22,"Yes",'Episode Detail'!$AL$5:$AL$22,"No")/COUNTIFS('Episode Detail'!$AL$5:$AL$22,"No"),"") -> 0.88235294 | C16: Backfilled durations are minimums
A19: Loss of sales due to delayed production — the headline the business asked for
A20: Measure (PRODUCTION family only) | B20: Value | C20: Read as
A21: Lost Revenue — PRODUCTION (KES) | B21: =SUMIFS('Episode Detail'!$AE$5:$AE$22,'Episode Detail'!$AH$5:$AH$22,"PRODUCTION",'Episode Detail'!$AL$5:$AL$22,"No") -> 226138.2 | C21: Revenue we will never invoice
A22: Revenue at Risk — PRODUCTION (KES) | B22: =SUMIFS('Episode Detail'!$AB$5:$AB$22,'Episode Detail'!$AH$5:$AH$22,"PRODUCTION",'Episode Detail'!$AP$5:$AP$22,"Open",'Episode Detail'!$AL$5:$AL$22,"No") -> 220640.7 | C22: Still recoverable if stock lands
A23: Revenue-Days Delayed — PRODUCTION | B23: =SUMIFS('Episode Detail'!$AD$5:$AD$22,'Episode Detail'!$AH$5:$AH$22,"PRODUCTION",'Episode Detail'!$AL$5:$AL$22,"No") -> 475654 | C23: How long we made customers wait
A24: Episodes — PRODUCTION | B24: =COUNTIFS('Episode Detail'!$AH$5:$AH$22,"PRODUCTION",'Episode Detail'!$AL$5:$AL$22,"No") -> 8 | C24: Count of order-item shortages
A25: Avg delay — PRODUCTION (working days) | B25: =IFERROR(AVERAGEIFS('Episode Detail'!$Q$5:$Q$22,'Episode Detail'!$AH$5:$AH$22,"PRODUCTION",'Episode Detail'!$S$5:$S$22,"Yes",'Episode Detail'!$AL$5:$AL$22,"No"),"") -> 10.714286 | C25: Verified starts only

Sheet Loss by Reason
A1: Loss by reason family and code
A2: Family totals are SUMIFS over Episode Detail. All 33 Acumatica reason codes map to exactly one family.
A4: Family | B4: Reason code | C4: True supply shortage? | D4: Episodes | E4: Peak Qty | F4: Revenue at Risk | G4: Delayed Revenue | H4: Revenue-Days Delayed | I4: Lost Revenue | J4: Avg Days Delay
A5: PRODUCTION | B5: — family total — | C5: Yes | D5: =COUNTIFS('Episode Detail'!$AH$5:$AH$22,$A5,'Episode Detail'!$AL$5:$AL$22,"No") -> 8 | E5: =SUMIFS('Episode Detail'!$U$5:$U$22,'Episode Detail'!$AH$5:$AH$22,$A5,'Episode Detail'!$AL$5:$AL$22,"No") -> 3080 | F5: =SUMIFS('Episode Detail'!$AB$5:$AB$22,'Episode Detail'!$AH$5:$AH$22,$A5,'Episode Detail'!$AP$5:$AP$22,"Open",'Episode Detail'!$AL$5:$AL$22,"No") -> 220640.7 | G5: =SUMIFS('Episode Detail'!$AC$5:$AC$22,'Episode Detail'!$AH$5:$AH$22,$A5,'Episode Detail'!$AL$5:$AL$22,"No") -> 68216.1 | H5: =SUMIFS('Episode Detail'!$AD$5:$AD$22,'Episode Detail'!$AH$5:$AH$22,$A5,'Episode Detail'!$AL$5:$AL$22,"No") -> 475654 | I5: =SUMIFS('Episode Detail'!$AE$5:$AE$22,'Episode Detail'!$AH$5:$AH$22,$A5,'Episode Detail'!$AL$5:$AL$22,"No") -> 226138.2 | J5: =IFERROR(AVERAGEIFS('Episode Detail'!$Q$5:$Q$22,'Episode Detail'!$AH$5:$AH$22,$A5,'Episode Detail'!$S$5:$S$22,"Yes",'Episode Detail'!$AL$5:$AL$22,"No"),"") -> 10.714286
B6: out_of_stock_production | D6: =COUNTIFS('Episode Detail'!$AG$5:$AG$22,$B6,'Episode Detail'!$AL$5:$AL$22,"No") -> 4 | E6: =SUMIFS('Episode Detail'!$U$5:$U$22,'Episode Detail'!$AG$5:$AG$22,$B6,'Episode Detail'!$AL$5:$AL$22,"No") -> 2266 | F6: =SUMIFS('Episode Detail'!$AB$5:$AB$22,'Episode Detail'!$AG$5:$AG$22,$B6,'Episode Detail'!$AP$5:$AP$22,"Open",'Episode Detail'!$AL$5:$AL$22,"No") -> 135137.4 | G6: =SUMIFS('Episode Detail'!$AC$5:$AC$22,'Episode Detail'!$AG$5:$AG$22,$B6,'Episode Detail'!$AL$5:$AL$22,"No") -> 68216.1 | H6: =SUMIFS('Episode Detail'!$AD$5:$AD$22,'Episode Detail'!$AG$5:$AG$22,$B6,'Episode Detail'!$AL$5:$AL$22,"No") -> 475654 | I6: =SUMIFS('Episode Detail'!$AE$5:$AE$22,'Episode Detail'!$AG$5:$AG$22,$B6,'Episode Detail'!$AL$5:$AL$22,"No") -> 140634.9 | J6: =IFERROR(AVERAGEIFS('Episode Detail'!$Q$5:$Q$22,'Episode Detail'!$AG$5:$AG$22,$B6,'Episode Detail'!$S$5:$S$22,"Yes",'Episode Detail'!$AL$5:$AL$22,"No"),"") -> 11
B7: production_stockout | D7: =COUNTIFS('Episode Detail'!$AG$5:$AG$22,$B7,'Episode Detail'!$AL$5:$AL$22,"No") -> 0 | E7: =SUMIFS('Episode Detail'!$U$5:$U$22,'Episode Detail'!$AG$5:$AG$22,$B7,'Episode Detail'!$AL$5:$AL$22,"No") -> 0 | F7: =SUMIFS('Episode Detail'!$AB$5:$AB$22,'Episode Detail'!$AG$5:$AG$22,$B7,'Episode Detail'!$AP$5:$AP$22,"Open",'Episode Detail'!$AL$5:$AL$22,"No") -> 0 | G7: =SUMIFS('Episode Detail'!$AC$5:$AC$22,'Episode Detail'!$AG$5:$AG$22,$B7,'Episode Detail'!$AL$5:$AL$22,"No") -> 0 | H7: =SUMIFS('Episode Detail'!$AD$5:$AD$22,'Episode Detail'!$AG$5:$AG$22,$B7,'Episode Detail'!$AL$5:$AL$22,"No") -> 0 | I7: =SUMIFS('Episode Detail'!$AE$5:$AE$22,'Episode Detail'!$AG$5:$AG$22,$B7,'Episode Detail'!$AL$5:$AL$22,"No") -> 0 | J7: =IFERROR(AVERAGEIFS('Episode Detail'!$Q$5:$Q$22,'Episode Detail'!$AG$5:$AG$22,$B7,'Episode Detail'!$S$5:$S$22,"Yes",'Episode Detail'!$AL$5:$AL$22,"No"),"")
B8: raw_material_stockout | D8: =COUNTIFS('Episode Detail'!$AG$5:$AG$22,$B8,'Episode Detail'!$AL$5:$AL$22,"No") -> 1 | E8: =SUMIFS('Episode Detail'!$U$5:$U$22,'Episode Detail'!$AG$5:$AG$22,$B8,'Episode Detail'!$AL$5:$AL$22,"No") -> 542 | F8: =SUMIFS('Episode Detail'!$AB$5:$AB$22,'Episode Detail'!$AG$5:$AG$22,$B8,'Episode Detail'!$AP$5:$AP$22,"Open",'Episode Detail'!$AL$5:$AL$22,"No") -> 32920.5 | G8: =SUMIFS('Episode Detail'!$AC$5:$AC$22,'Episode Detail'!$AG$5:$AG$22,$B8,'Episode Detail'!$AL$5:$AL$22,"No") -> 0 | H8: =SUMIFS('Episode Detail'!$AD$5:$AD$22,'Episode Detail'!$AG$5:$AG$22,$B8,'Episode Detail'!$AL$5:$AL$22,"No") -> 0 | I8: =SUMIFS('Episode Detail'!$AE$5:$AE$22,'Episode Detail'!$AG$5:$AG$22,$B8,'Episode Detail'!$AL$5:$AL$22,"No") -> 32920.5 | J8: =IFERROR(AVERAGEIFS('Episode Detail'!$Q$5:$Q$22,'Episode Detail'!$AG$5:$AG$22,$B8,'Episode Detail'!$S$5:$S$22,"Yes",'Episode Detail'!$AL$5:$AL$22,"No"),"") -> 13
B9: order_to_make | D9: =COUNTIFS('Episode Detail'!$AG$5:$AG$22,$B9,'Episode Detail'!$AL$5:$AL$22,"No") -> 1 | E9: =SUMIFS('Episode Detail'!$U$5:$U$22,'Episode Detail'!$AG$5:$AG$22,$B9,'Episode Detail'!$AL$5:$AL$22,"No") -> 260 | F9: =SUMIFS('Episode Detail'!$AB$5:$AB$22,'Episode Detail'!$AG$5:$AG$22,$B9,'Episode Detail'!$AP$5:$AP$22,"Open",'Episode Detail'!$AL$5:$AL$22,"No") -> 19500 | G9: =SUMIFS('Episode Detail'!$AC$5:$AC$22,'Episode Detail'!$AG$5:$AG$22,$B9,'Episode Detail'!$AL$5:$AL$22,"No") -> 0 | H9: =SUMIFS('Episode Detail'!$AD$5:$AD$22,'Episode Detail'!$AG$5:$AG$22,$B9,'Episode Detail'!$AL$5:$AL$22,"No") -> 0 | I9: =SUMIFS('Episode Detail'!$AE$5:$AE$22,'Episode Detail'!$AG$5:$AG$22,$B9,'Episode Detail'!$AL$5:$AL$22,"No") -> 19500 | J9: =IFERROR(AVERAGEIFS('Episode Detail'!$Q$5:$Q$22,'Episode Detail'!$AG$5:$AG$22,$B9,'Episode Detail'!$S$5:$S$22,"Yes",'Episode Detail'!$AL$5:$AL$22,"No"),"")
B10: conversion_delays | D10: =COUNTIFS('Episode Detail'!$AG$5:$AG$22,$B10,'Episode Detail'!$AL$5:$AL$22,"No") -> 2 | E10: =SUMIFS('Episode Detail'!$U$5:$U$22,'Episode Detail'!$AG$5:$AG$22,$B10,'Episode Detail'!$AL$5:$AL$22,"No") -> 12 | F10: =SUMIFS('Episode Detail'!$AB$5:$AB$22,'Episode Detail'!$AG$5:$AG$22,$B10,'Episode Detail'!$AP$5:$AP$22,"Open",'Episode Detail'!$AL$5:$AL$22,"No") -> 33082.8 | G10: =SUMIFS('Episode Detail'!$AC$5:$AC$22,'Episode Detail'!$AG$5:$AG$22,$B10,'Episode Detail'!$AL$5:$AL$22,"No") -> 0 | H10: =SUMIFS('Episode Detail'!$AD$5:$AD$22,'Episode Detail'!$AG$5:$AG$22,$B10,'Episode Detail'!$AL$5:$AL$22,"No") -> 0 | I10: =SUMIFS('Episode Detail'!$AE$5:$AE$22,'Episode Detail'!$AG$5:$AG$22,$B10,'Episode Detail'!$AL$5:$AL$22,"No") -> 33082.8 | J10: =IFERROR(AVERAGEIFS('Episode Detail'!$Q$5:$Q$22,'Episode Detail'!$AG$5:$AG$22,$B10,'Episode Detail'!$S$5:$S$22,"Yes",'Episode Detail'!$AL$5:$AL$22,"No"),"") -> 9
B11: conversion_issues | D11: =COUNTIFS('Episode Detail'!$AG$5:$AG$22,$B11,'Episode Detail'!$AL$5:$AL$22,"No") -> 0 | E11: =SUMIFS('Episode Detail'!$U$5:$U$22,'Episode Detail'!$AG$5:$AG$22,$B11,'Episode Detail'!$AL$5:$AL$22,"No") -> 0 | F11: =SUMIFS('Episode Detail'!$AB$5:$AB$22,'Episode Detail'!$AG$5:$AG$22,$B11,'Episode Detail'!$AP$5:$AP$22,"Open",'Episode Detail'!$AL$5:$AL$22,"No") -> 0 | G11: =SUMIFS('Episode Detail'!$AC$5:$AC$22,'Episode Detail'!$AG$5:$AG$22,$B11,'Episode Detail'!$AL$5:$AL$22,"No") -> 0 | H11: =SUMIFS('Episode Detail'!$AD$5:$AD$22,'Episode Detail'!$AG$5:$AG$22,$B11,'Episode Detail'!$AL$5:$AL$22,"No") -> 0 | I11: =SUMIFS('Episode Detail'!$AE$5:$AE$22,'Episode Detail'!$AG$5:$AG$22,$B11,'Episode Detail'!$AL$5:$AL$22,"No") -> 0 | J11: =IFERROR(AVERAGEIFS('Episode Detail'!$Q$5:$Q$22,'Episode Detail'!$AG$5:$AG$22,$B11,'Episode Detail'!$S$5:$S$22,"Yes",'Episode Detail'!$AL$5:$AL$22,"No"),"")
B12: batch_sequence | D12: =COUNTIFS('Episode Detail'!$AG$5:$AG$22,$B12,'Episode Detail'!$AL$5:$AL$22,"No") -> 0 | E12: =SUMIFS('Episode Detail'!$U$5:$U$22,'Episode Detail'!$AG$5:$AG$22,$B12,'Episode Detail'!$AL$5:$AL$22,"No") -> 0 | F12: =SUMIFS('Episode Detail'!$AB$5:$AB$22,'Episode Detail'!$AG$5:$AG$22,$B12,'Episode Detail'!$AP$5:$AP$22,"Open",'Episode Detail'!$AL$5:$AL$22,"No") -> 0 | G12: =SUMIFS('Episode Detail'!$AC$5:$AC$22,'Episode Detail'!$AG$5:$AG$22,$B12,'Episode Detail'!$AL$5:$AL$22,"No") -> 0 | H12: =SUMIFS('Episode Detail'!$AD$5:$AD$22,'Episode Detail'!$AG$5:$AG$22,$B12,'Episode Detail'!$AL$5:$AL$22,"No") -> 0 | I12: =SUMIFS('Episode Detail'!$AE$5:$AE$22,'Episode Detail'!$AG$5:$AG$22,$B12,'Episode Detail'!$AL$5:$AL$22,"No") -> 0 | J12: =IFERROR(AVERAGEIFS('Episode Detail'!$Q$5:$Q$22,'Episode Detail'!$AG$5:$AG$22,$B12,'Episode Detail'!$S$5:$S$22,"Yes",'Episode Detail'!$AL$5:$AL$22,"No"),"")
B13: wrong_moq | D13: =COUNTIFS('Episode Detail'!$AG$5:$AG$22,$B13,'Episode Detail'!$AL$5:$AL$22,"No") -> 0 | E13: =SUMIFS('Episode Detail'!$U$5:$U$22,'Episode Detail'!$AG$5:$AG$22,$B13,'Episode Detail'!$AL$5:$AL$22,"No") -> 0 | F13: =SUMIFS('Episode Detail'!$AB$5:$AB$22,'Episode Detail'!$AG$5:$AG$22,$B13,'Episode Detail'!$AP$5:$AP$22,"Open",'Episode Detail'!$AL$5:$AL$22,"No") -> 0 | G13: =SUMIFS('Episode Detail'!$AC$5:$AC$22,'Episode Detail'!$AG$5:$AG$22,$B13,'Episode Detail'!$AL$5:$AL$22,"No") -> 0 | H13: =SUMIFS('Episode Detail'!$AD$5:$AD$22,'Episode Detail'!$AG$5:$AG$22,$B13,'Episode Detail'!$AL$5:$AL$22,"No") -> 0 | I13: =SUMIFS('Episode Detail'!$AE$5:$AE$22,'Episode Detail'!$AG$5:$AG$22,$B13,'Episode Detail'!$AL$5:$AL$22,"No") -> 0 | J13: =IFERROR(AVERAGEIFS('Episode Detail'!$Q$5:$Q$22,'Episode Detail'!$AG$5:$AG$22,$B13,'Episode Detail'!$S$5:$S$22,"Yes",'Episode Detail'!$AL$5:$AL$22,"No"),"")
A14: PROCUREMENT | B14: — family total — | C14: Yes | D14: =COUNTIFS('Episode Detail'!$AH$5:$AH$22,$A14,'Episode Detail'!$AL$5:$AL$22,"No") -> 4 | E14: =SUMIFS('Episode Detail'!$U$5:$U$22,'Episode Detail'!$AH$5:$AH$22,$A14,'Episode Detail'!$AL$5:$AL$22,"No") -> 90 | F14: =SUMIFS('Episode Detail'!$AB$5:$AB$22,'Episode Detail'!$AH$5:$AH$22,$A14,'Episode Detail'!$AP$5:$AP$22,"Open",'Episode Detail'!$AL$5:$AL$22,"No") -> 158475.6 | G14: =SUMIFS('Episode Detail'!$AC$5:$AC$22,'Episode Detail'!$AH$5:$AH$22,$A14,'Episode Detail'!$AL$5:$AL$22,"No") -> 0 | H14: =SUMIFS('Episode Detail'!$AD$5:$AD$22,'Episode Detail'!$AH$5:$AH$22,$A14,'Episode Detail'!$AL$5:$AL$22,"No") -> 0 | I14: =SUMIFS('Episode Detail'!$AE$5:$AE$22,'Episode Detail'!$AH$5:$AH$22,$A14,'Episode Detail'!$AL$5:$AL$22,"No") -> 30510.36 | J14: =IFERROR(AVERAGEIFS('Episode Detail'!$Q$5:$Q$22,'Episode Detail'!$AH$5:$AH$22,$A14,'Episode Detail'!$S$5:$S$22,"Yes",'Episode Detail'!$AL$5:$AL$22,"No"),"") -> 4
B15: out_of_stock_procurement | D15: =COUNTIFS('Episode Detail'!$AG$5:$AG$22,$B15,'Episode Detail'!$AL$5:$AL$22,"No") -> 3 | E15: =SUMIFS('Episode Detail'!$U$5:$U$22,'Episode Detail'!$AG$5:$AG$22,$B15,'Episode Detail'!$AL$5:$AL$22,"No") -> 54 | F15: =SUMIFS('Episode Detail'!$AB$5:$AB$22,'Episode Detail'!$AG$5:$AG$22,$B15,'Episode Detail'!$AP$5:$AP$22,"Open",'Episode Detail'!$AL$5:$AL$22,"No") -> 121215.6 | G15: =SUMIFS('Episode Detail'!$AC$5:$AC$22,'Episode Detail'!$AG$5:$AG$22,$B15,'Episode Detail'!$AL$5:$AL$22,"No") -> 0 | H15: =SUMIFS('Episode Detail'!$AD$5:$AD$22,'Episode Detail'!$AG$5:$AG$22,$B15,'Episode Detail'!$AL$5:$AL$22,"No") -> 0 | I15: =SUMIFS('Episode Detail'!$AE$5:$AE$22,'Episode Detail'!$AG$5:$AG$22,$B15,'Episode Detail'!$AL$5:$AL$22,"No") -> 30510.36 | J15: =IFERROR(AVERAGEIFS('Episode Detail'!$Q$5:$Q$22,'Episode Detail'!$AG$5:$AG$22,$B15,'Episode Detail'!$S$5:$S$22,"Yes",'Episode Detail'!$AL$5:$AL$22,"No"),"") -> 4
B16: out_of_stock_msa | D16: =COUNTIFS('Episode Detail'!$AG$5:$AG$22,$B16,'Episode Detail'!$AL$5:$AL$22,"No") -> 1 | E16: =SUMIFS('Episode Detail'!$U$5:$U$22,'Episode Detail'!$AG$5:$AG$22,$B16,'Episode Detail'!$AL$5:$AL$22,"No") -> 36 | F16: =SUMIFS('Episode Detail'!$AB$5:$AB$22,'Episode Detail'!$AG$5:$AG$22,$B16,'Episode Detail'!$AP$5:$AP$22,"Open",'Episode Detail'!$AL$5:$AL$22,"No") -> 37260 | G16: =SUMIFS('Episode Detail'!$AC$5:$AC$22,'Episode Detail'!$AG$5:$AG$22,$B16,'Episode Detail'!$AL$5:$AL$22,"No") -> 0 | H16: =SUMIFS('Episode Detail'!$AD$5:$AD$22,'Episode Detail'!$AG$5:$AG$22,$B16,'Episode Detail'!$AL$5:$AL$22,"No") -> 0 | I16: =SUMIFS('Episode Detail'!$AE$5:$AE$22,'Episode Detail'!$AG$5:$AG$22,$B16,'Episode Detail'!$AL$5:$AL$22,"No") -> 0 | J16: =IFERROR(AVERAGEIFS('Episode Detail'!$Q$5:$Q$22,'Episode Detail'!$AG$5:$AG$22,$B16,'Episode Detail'!$S$5:$S$22,"Yes",'Episode Detail'!$AL$5:$AL$22,"No"),"")
B17: delayed_supplier_payment | D17: =COUNTIFS('Episode Detail'!$AG$5:$AG$22,$B17,'Episode Detail'!$AL$5:$AL$22,"No") -> 0 | E17: =SUMIFS('Episode Detail'!$U$5:$U$22,'Episode Detail'!$AG$5:$AG$22,$B17,'Episode Detail'!$AL$5:$AL$22,"No") -> 0 | F17: =SUMIFS('Episode Detail'!$AB$5:$AB$22,'Episode Detail'!$AG$5:$AG$22,$B17,'Episode Detail'!$AP$5:$AP$22,"Open",'Episode Detail'!$AL$5:$AL$22,"No") -> 0 | G17: =SUMIFS('Episode Detail'!$AC$5:$AC$22,'Episode Detail'!$AG$5:$AG$22,$B17,'Episode Detail'!$AL$5:$AL$22,"No") -> 0 | H17: =SUMIFS('Episode Detail'!$AD$5:$AD$22,'Episode Detail'!$AG$5:$AG$22,$B17,'Episode Detail'!$AL$5:$AL$22,"No") -> 0 | I17: =SUMIFS('Episode Detail'!$AE$5:$AE$22,'Episode Detail'!$AG$5:$AG$22,$B17,'Episode Detail'!$AL$5:$AL$22,"No") -> 0 | J17: =IFERROR(AVERAGEIFS('Episode Detail'!$Q$5:$Q$22,'Episode Detail'!$AG$5:$AG$22,$B17,'Episode Detail'!$S$5:$S$22,"Yes",'Episode Detail'!$AL$5:$AL$22,"No"),"")
B18: kebs_stickers | D18: =COUNTIFS('Episode Detail'!$AG$5:$AG$22,$B18,'Episode Detail'!$AL$5:$AL$22,"No") -> 0 | E18: =SUMIFS('Episode Detail'!$U$5:$U$22,'Episode Detail'!$AG$5:$AG$22,$B18,'Episode Detail'!$AL$5:$AL$22,"No") -> 0 | F18: =SUMIFS('Episode Detail'!$AB$5:$AB$22,'Episode Detail'!$AG$5:$AG$22,$B18,'Episode Detail'!$AP$5:$AP$22,"Open",'Episode Detail'!$AL$5:$AL$22,"No") -> 0 | G18: =SUMIFS('Episode Detail'!$AC$5:$AC$22,'Episode Detail'!$AG$5:$AG$22,$B18,'Episode Detail'!$AL$5:$AL$22,"No") -> 0 | H18: =SUMIFS('Episode Detail'!$AD$5:$AD$22,'Episode Detail'!$AG$5:$AG$22,$B18,'Episode Detail'!$AL$5:$AL$22,"No") -> 0 | I18: =SUMIFS('Episode Detail'!$AE$5:$AE$22,'Episode Detail'!$AG$5:$AG$22,$B18,'Episode Detail'!$AL$5:$AL$22,"No") -> 0 | J18: =IFERROR(AVERAGEIFS('Episode Detail'!$Q$5:$Q$22,'Episode Detail'!$AG$5:$AG$22,$B18,'Episode Detail'!$S$5:$S$22,"Yes",'Episode Detail'!$AL$5:$AL$22,"No"),"")
A19: LOGISTICS | B19: — family total — | C19: No | D19: =COUNTIFS('Episode Detail'!$AH$5:$AH$22,$A19,'Episode Detail'!$AL$5:$AL$22,"No") -> 3 | E19: =SUMIFS('Episode Detail'!$U$5:$U$22,'Episode Detail'!$AH$5:$AH$22,$A19,'Episode Detail'!$AL$5:$AL$22,"No") -> 564 | F19: =SUMIFS('Episode Detail'!$AB$5:$AB$22,'Episode Detail'!$AH$5:$AH$22,$A19,'Episode Detail'!$AP$5:$AP$22,"Open",'Episode Detail'!$AL$5:$AL$22,"No") -> 0 | G19: =SUMIFS('Episode Detail'!$AC$5:$AC$22,'Episode Detail'!$AH$5:$AH$22,$A19,'Episode Detail'!$AL$5:$AL$22,"No") -> 252272.74 | H19: =SUMIFS('Episode Detail'!$AD$5:$AD$22,'Episode Detail'!$AH$5:$AH$22,$A19,'Episode Detail'!$AL$5:$AL$22,"No") -> 59340.6 | I19: =SUMIFS('Episode Detail'!$AE$5:$AE$22,'Episode Detail'!$AH$5:$AH$22,$A19,'Episode Detail'!$AL$5:$AL$22,"No") -> 0 | J19: =IFERROR(AVERAGEIFS('Episode Detail'!$Q$5:$Q$22,'Episode Detail'!$AH$5:$AH$22,$A19,'Episode Detail'!$S$5:$S$22,"Yes",'Episode Detail'!$AL$5:$AL$22,"No"),"") -> 3.3333333
B20: delay_in_delivery | D20: =COUNTIFS('Episode Detail'!$AG$5:$AG$22,$B20,'Episode Detail'!$AL$5:$AL$22,"No") -> 0 | E20: =SUMIFS('Episode Detail'!$U$5:$U$22,'Episode Detail'!$AG$5:$AG$22,$B20,'Episode Detail'!$AL$5:$AL$22,"No") -> 0 | F20: =SUMIFS('Episode Detail'!$AB$5:$AB$22,'Episode Detail'!$AG$5:$AG$22,$B20,'Episode Detail'!$AP$5:$AP$22,"Open",'Episode Detail'!$AL$5:$AL$22,"No") -> 0 | G20: =SUMIFS('Episode Detail'!$AC$5:$AC$22,'Episode Detail'!$AG$5:$AG$22,$B20,'Episode Detail'!$AL$5:$AL$22,"No") -> 0 | H20: =SUMIFS('Episode Detail'!$AD$5:$AD$22,'Episode Detail'!$AG$5:$AG$22,$B20,'Episode Detail'!$AL$5:$AL$22,"No") -> 0 | I20: =SUMIFS('Episode Detail'!$AE$5:$AE$22,'Episode Detail'!$AG$5:$AG$22,$B20,'Episode Detail'!$AL$5:$AL$22,"No") -> 0 | J20: =IFERROR(AVERAGEIFS('Episode Detail'!$Q$5:$Q$22,'Episode Detail'!$AG$5:$AG$22,$B20,'Episode Detail'!$S$5:$S$22,"Yes",'Episode Detail'!$AL$5:$AL$22,"No"),"")
B21: transfer_delays | D21: =COUNTIFS('Episode Detail'!$AG$5:$AG$22,$B21,'Episode Detail'!$AL$5:$AL$22,"No") -> 1 | E21: =SUMIFS('Episode Detail'!$U$5:$U$22,'Episode Detail'!$AG$5:$AG$22,$B21,'Episode Detail'!$AL$5:$AL$22,"No") -> 262 | F21: =SUMIFS('Episode Detail'!$AB$5:$AB$22,'Episode Detail'!$AG$5:$AG$22,$B21,'Episode Detail'!$AP$5:$AP$22,"Open",'Episode Detail'!$AL$5:$AL$22,"No") -> 0 | G21: =SUMIFS('Episode Detail'!$AC$5:$AC$22,'Episode Detail'!$AG$5:$AG$22,$B21,'Episode Detail'!$AL$5:$AL$22,"No") -> 225364.54 | H21: =SUMIFS('Episode Detail'!$AD$5:$AD$22,'Episode Detail'!$AG$5:$AG$22,$B21,'Episode Detail'!$AL$5:$AL$22,"No") -> 0 | I21: =SUMIFS('Episode Detail'!$AE$5:$AE$22,'Episode Detail'!$AG$5:$AG$22,$B21,'Episode Detail'!$AL$5:$AL$22,"No") -> 0 | J21: =IFERROR(AVERAGEIFS('Episode Detail'!$Q$5:$Q$22,'Episode Detail'!$AG$5:$AG$22,$B21,'Episode Detail'!$S$5:$S$22,"Yes",'Episode Detail'!$AL$5:$AL$22,"No"),"") -> 2
B22: truck_full | D22: =COUNTIFS('Episode Detail'!$AG$5:$AG$22,$B22,'Episode Detail'!$AL$5:$AL$22,"No") -> 0 | E22: =SUMIFS('Episode Detail'!$U$5:$U$22,'Episode Detail'!$AG$5:$AG$22,$B22,'Episode Detail'!$AL$5:$AL$22,"No") -> 0 | F22: =SUMIFS('Episode Detail'!$AB$5:$AB$22,'Episode Detail'!$AG$5:$AG$22,$B22,'Episode Detail'!$AP$5:$AP$22,"Open",'Episode Detail'!$AL$5:$AL$22,"No") -> 0 | G22: =SUMIFS('Episode Detail'!$AC$5:$AC$22,'Episode Detail'!$AG$5:$AG$22,$B22,'Episode Detail'!$AL$5:$AL$22,"No") -> 0 | H22: =SUMIFS('Episode Detail'!$AD$5:$AD$22,'Episode Detail'!$AG$5:$AG$22,$B22,'Episode Detail'!$AL$5:$AL$22,"No") -> 0 | I22: =SUMIFS('Episode Detail'!$AE$5:$AE$22,'Episode Detail'!$AG$5:$AG$22,$B22,'Episode Detail'!$AL$5:$AL$22,"No") -> 0 | J22: =IFERROR(AVERAGEIFS('Episode Detail'!$Q$5:$Q$22,'Episode Detail'!$AG$5:$AG$22,$B22,'Episode Detail'!$S$5:$S$22,"Yes",'Episode Detail'!$AL$5:$AL$22,"No"),"")
B23: did_not_pick_on_shipment | D23: =COUNTIFS('Episode Detail'!$AG$5:$AG$22,$B23,'Episode Detail'!$AL$5:$AL$22,"No") -> 2 | E23: =SUMIFS('Episode Detail'!$U$5:$U$22,'Episode Detail'!$AG$5:$AG$22,$B23,'Episode Detail'!$AL$5:$AL$22,"No") -> 302 | F23: =SUMIFS('Episode Detail'!$AB$5:$AB$22,'Episode Detail'!$AG$5:$AG$22,$B23,'Episode Detail'!$AP$5:$AP$22,"Open",'Episode Detail'!$AL$5:$AL$22,"No") -> 0 | G23: =SUMIFS('Episode Detail'!$AC$5:$AC$22,'Episode Detail'!$AG$5:$AG$22,$B23,'Episode Detail'!$AL$5:$AL$22,"No") -> 26908.2 | H23: =SUMIFS('Episode Detail'!$AD$5:$AD$22,'Episode Detail'!$AG$5:$AG$22,$B23,'Episode Detail'!$AL$5:$AL$22,"No") -> 59340.6 | I23: =SUMIFS('Episode Detail'!$AE$5:$AE$22,'Episode Detail'!$AG$5:$AG$22,$B23,'Episode Detail'!$AL$5:$AL$22,"No") -> 0 | J23: =IFERROR(AVERAGEIFS('Episode Detail'!$Q$5:$Q$22,'Episode Detail'!$AG$5:$AG$22,$B23,'Episode Detail'!$S$5:$S$22,"Yes",'Episode Detail'!$AL$5:$AL$22,"No"),"") -> 4
A24: COMMERCIAL | B24: — family total — | C24: No | D24: =COUNTIFS('Episode Detail'!$AH$5:$AH$22,$A24,'Episode Detail'!$AL$5:$AL$22,"No") -> 0 | E24: =SUMIFS('Episode Detail'!$U$5:$U$22,'Episode Detail'!$AH$5:$AH$22,$A24,'Episode Detail'!$AL$5:$AL$22,"No") -> 0 | F24: =SUMIFS('Episode Detail'!$AB$5:$AB$22,'Episode Detail'!$AH$5:$AH$22,$A24,'Episode Detail'!$AP$5:$AP$22,"Open",'Episode Detail'!$AL$5:$AL$22,"No") -> 0 | G24: =SUMIFS('Episode Detail'!$AC$5:$AC$22,'Episode Detail'!$AH$5:$AH$22,$A24,'Episode Detail'!$AL$5:$AL$22,"No") -> 0 | H24: =SUMIFS('Episode Detail'!$AD$5:$AD$22,'Episode Detail'!$AH$5:$AH$22,$A24,'Episode Detail'!$AL$5:$AL$22,"No") -> 0 | I24: =SUMIFS('Episode Detail'!$AE$5:$AE$22,'Episode Detail'!$AH$5:$AH$22,$A24,'Episode Detail'!$AL$5:$AL$22,"No") -> 0 | J24: =IFERROR(AVERAGEIFS('Episode Detail'!$Q$5:$Q$22,'Episode Detail'!$AH$5:$AH$22,$A24,'Episode Detail'!$S$5:$S$22,"Yes",'Episode Detail'!$AL$5:$AL$22,"No"),"")
B25: discontinued | D25: =COUNTIFS('Episode Detail'!$AG$5:$AG$22,$B25,'Episode Detail'!$AL$5:$AL$22,"No") -> 0 | E25: =SUMIFS('Episode Detail'!$U$5:$U$22,'Episode Detail'!$AG$5:$AG$22,$B25,'Episode Detail'!$AL$5:$AL$22,"No") -> 0 | F25: =SUMIFS('Episode Detail'!$AB$5:$AB$22,'Episode Detail'!$AG$5:$AG$22,$B25,'Episode Detail'!$AP$5:$AP$22,"Open",'Episode Detail'!$AL$5:$AL$22,"No") -> 0 | G25: =SUMIFS('Episode Detail'!$AC$5:$AC$22,'Episode Detail'!$AG$5:$AG$22,$B25,'Episode Detail'!$AL$5:$AL$22,"No") -> 0 | H25: =SUMIFS('Episode Detail'!$AD$5:$AD$22,'Episode Detail'!$AG$5:$AG$22,$B25,'Episode Detail'!$AL$5:$AL$22,"No") -> 0 | I25: =SUMIFS('Episode Detail'!$AE$5:$AE$22,'Episode Detail'!$AG$5:$AG$22,$B25,'Episode Detail'!$AL$5:$AL$22,"No") -> 0 | J25: =IFERROR(AVERAGEIFS('Episode Detail'!$Q$5:$Q$22,'Episode Detail'!$AG$5:$AG$22,$B25,'Episode Detail'!$S$5:$S$22,"Yes",'Episode Detail'!$AL$5:$AL$22,"No"),"")
B26: pb_discontinued | D26: =COUNTIFS('Episode Detail'!$AG$5:$AG$22,$B26,'Episode Detail'!$AL$5:$AL$22,"No") -> 0 | E26: =SUMIFS('Episode Detail'!$U$5:$U$22,'Episode Detail'!$AG$5:$AG$22,$B26,'Episode Detail'!$AL$5:$AL$22,"No") -> 0 | F26: =SUMIFS('Episode Detail'!$AB$5:$AB$22,'Episode Detail'!$AG$5:$AG$22,$B26,'Episode Detail'!$AP$5:$AP$22,"Open",'Episode Detail'!$AL$5:$AL$22,"No") -> 0 | G26: =SUMIFS('Episode Detail'!$AC$5:$AC$22,'Episode Detail'!$AG$5:$AG$22,$B26,'Episode Detail'!$AL$5:$AL$22,"No") -> 0 | H26: =SUMIFS('Episode Detail'!$AD$5:$AD$22,'Episode Detail'!$AG$5:$AG$22,$B26,'Episode Detail'!$AL$5:$AL$22,"No") -> 0 | I26: =SUMIFS('Episode Detail'!$AE$5:$AE$22,'Episode Detail'!$AG$5:$AG$22,$B26,'Episode Detail'!$AL$5:$AL$22,"No") -> 0 | J26: =IFERROR(AVERAGEIFS('Episode Detail'!$Q$5:$Q$22,'Episode Detail'!$AG$5:$AG$22,$B26,'Episode Detail'!$S$5:$S$22,"Yes",'Episode Detail'!$AL$5:$AL$22,"No"),"")
B27: non_focus | D27: =COUNTIFS('Episode Detail'!$AG$5:$AG$22,$B27,'Episode Detail'!$AL$5:$AL$22,"No") -> 0 | E27: =SUMIFS('Episode Detail'!$U$5:$U$22,'Episode Detail'!$AG$5:$AG$22,$B27,'Episode Detail'!$AL$5:$AL$22,"No") -> 0 | F27: =SUMIFS('Episode Detail'!$AB$5:$AB$22,'Episode Detail'!$AG$5:$AG$22,$B27,'Episode Detail'!$AP$5:$AP$22,"Open",'Episode Detail'!$AL$5:$AL$22,"No") -> 0 | G27: =SUMIFS('Episode Detail'!$AC$5:$AC$22,'Episode Detail'!$AG$5:$AG$22,$B27,'Episode Detail'!$AL$5:$AL$22,"No") -> 0 | H27: =SUMIFS('Episode Detail'!$AD$5:$AD$22,'Episode Detail'!$AG$5:$AG$22,$B27,'Episode Detail'!$AL$5:$AL$22,"No") -> 0 | I27: =SUMIFS('Episode Detail'!$AE$5:$AE$22,'Episode Detail'!$AG$5:$AG$22,$B27,'Episode Detail'!$AL$5:$AL$22,"No") -> 0 | J27: =IFERROR(AVERAGEIFS('Episode Detail'!$Q$5:$Q$22,'Episode Detail'!$AG$5:$AG$22,$B27,'Episode Detail'!$S$5:$S$22,"Yes",'Episode Detail'!$AL$5:$AL$22,"No"),"")
B28: promo_product | D28: =COUNTIFS('Episode Detail'!$AG$5:$AG$22,$B28,'Episode Detail'!$AL$5:$AL$22,"No") -> 0 | E28: =SUMIFS('Episode Detail'!$U$5:$U$22,'Episode Detail'!$AG$5:$AG$22,$B28,'Episode Detail'!$AL$5:$AL$22,"No") -> 0 | F28: =SUMIFS('Episode Detail'!$AB$5:$AB$22,'Episode Detail'!$AG$5:$AG$22,$B28,'Episode Detail'!$AP$5:$AP$22,"Open",'Episode Detail'!$AL$5:$AL$22,"No") -> 0 | G28: =SUMIFS('Episode Detail'!$AC$5:$AC$22,'Episode Detail'!$AG$5:$AG$22,$B28,'Episode Detail'!$AL$5:$AL$22,"No") -> 0 | H28: =SUMIFS('Episode Detail'!$AD$5:$AD$22,'Episode Detail'!$AG$5:$AG$22,$B28,'Episode Detail'!$AL$5:$AL$22,"No") -> 0 | I28: =SUMIFS('Episode Detail'!$AE$5:$AE$22,'Episode Detail'!$AG$5:$AG$22,$B28,'Episode Detail'!$AL$5:$AL$22,"No") -> 0 | J28: =IFERROR(AVERAGEIFS('Episode Detail'!$Q$5:$Q$22,'Episode Detail'!$AG$5:$AG$22,$B28,'Episode Detail'!$S$5:$S$22,"Yes",'Episode Detail'!$AL$5:$AL$22,"No"),"")
B29: short_expiry | D29: =COUNTIFS('Episode Detail'!$AG$5:$AG$22,$B29,'Episode Detail'!$AL$5:$AL$22,"No") -> 0 | E29: =SUMIFS('Episode Detail'!$U$5:$U$22,'Episode Detail'!$AG$5:$AG$22,$B29,'Episode Detail'!$AL$5:$AL$22,"No") -> 0 | F29: =SUMIFS('Episode Detail'!$AB$5:$AB$22,'Episode Detail'!$AG$5:$AG$22,$B29,'Episode Detail'!$AP$5:$AP$22,"Open",'Episode Detail'!$AL$5:$AL$22,"No") -> 0 | G29: =SUMIFS('Episode Detail'!$AC$5:$AC$22,'Episode Detail'!$AG$5:$AG$22,$B29,'Episode Detail'!$AL$5:$AL$22,"No") -> 0 | H29: =SUMIFS('Episode Detail'!$AD$5:$AD$22,'Episode Detail'!$AG$5:$AG$22,$B29,'Episode Detail'!$AL$5:$AL$22,"No") -> 0 | I29: =SUMIFS('Episode Detail'!$AE$5:$AE$22,'Episode Detail'!$AG$5:$AG$22,$B29,'Episode Detail'!$AL$5:$AL$22,"No") -> 0 | J29: =IFERROR(AVERAGEIFS('Episode Detail'!$Q$5:$Q$22,'Episode Detail'!$AG$5:$AG$22,$B29,'Episode Detail'!$S$5:$S$22,"Yes",'Episode Detail'!$AL$5:$AL$22,"No"),"")
B30: npd | D30: =COUNTIFS('Episode Detail'!$AG$5:$AG$22,$B30,'Episode Detail'!$AL$5:$AL$22,"No") -> 0 | E30: =SUMIFS('Episode Detail'!$U$5:$U$22,'Episode Detail'!$AG$5:$AG$22,$B30,'Episode Detail'!$AL$5:$AL$22,"No") -> 0 | F30: =SUMIFS('Episode Detail'!$AB$5:$AB$22,'Episode Detail'!$AG$5:$AG$22,$B30,'Episode Detail'!$AP$5:$AP$22,"Open",'Episode Detail'!$AL$5:$AL$22,"No") -> 0 | G30: =SUMIFS('Episode Detail'!$AC$5:$AC$22,'Episode Detail'!$AG$5:$AG$22,$B30,'Episode Detail'!$AL$5:$AL$22,"No") -> 0 | H30: =SUMIFS('Episode Detail'!$AD$5:$AD$22,'Episode Detail'!$AG$5:$AG$22,$B30,'Episode Detail'!$AL$5:$AL$22,"No") -> 0 | I30: =SUMIFS('Episode Detail'!$AE$5:$AE$22,'Episode Detail'!$AG$5:$AG$22,$B30,'Episode Detail'!$AL$5:$AL$22,"No") -> 0 | J30: =IFERROR(AVERAGEIFS('Episode Detail'!$Q$5:$Q$22,'Episode Detail'!$AG$5:$AG$22,$B30,'Episode Detail'!$S$5:$S$22,"Yes",'Episode Detail'!$AL$5:$AL$22,"No"),"")
A31: DATA_PROCESS | B31: — family total — | C31: No | D31: =COUNTIFS('Episode Detail'!$AH$5:$AH$22,$A31,'Episode Detail'!$AL$5:$AL$22,"No") -> 1 | E31: =SUMIFS('Episode Detail'!$U$5:$U$22,'Episode Detail'!$AH$5:$AH$22,$A31,'Episode Detail'!$AL$5:$AL$22,"No") -> 1 | F31: =SUMIFS('Episode Detail'!$AB$5:$AB$22,'Episode Detail'!$AH$5:$AH$22,$A31,'Episode Detail'!$AP$5:$AP$22,"Open",'Episode Detail'!$AL$5:$AL$22,"No") -> 2935 | G31: =SUMIFS('Episode Detail'!$AC$5:$AC$22,'Episode Detail'!$AH$5:$AH$22,$A31,'Episode Detail'!$AL$5:$AL$22,"No") -> 0 | H31: =SUMIFS('Episode Detail'!$AD$5:$AD$22,'Episode Detail'!$AH$5:$AH$22,$A31,'Episode Detail'!$AL$5:$AL$22,"No") -> 0 | I31: =SUMIFS('Episode Detail'!$AE$5:$AE$22,'Episode Detail'!$AH$5:$AH$22,$A31,'Episode Detail'!$AL$5:$AL$22,"No") -> 0 | J31: =IFERROR(AVERAGEIFS('Episode Detail'!$Q$5:$Q$22,'Episode Detail'!$AH$5:$AH$22,$A31,'Episode Detail'!$S$5:$S$22,"Yes",'Episode Detail'!$AL$5:$AL$22,"No"),"") -> 4
B32: delayed_communication | D32: =COUNTIFS('Episode Detail'!$AG$5:$AG$22,$B32,'Episode Detail'!$AL$5:$AL$22,"No") -> 0 | E32: =SUMIFS('Episode Detail'!$U$5:$U$22,'Episode Detail'!$AG$5:$AG$22,$B32,'Episode Detail'!$AL$5:$AL$22,"No") -> 0 | F32: =SUMIFS('Episode Detail'!$AB$5:$AB$22,'Episode Detail'!$AG$5:$AG$22,$B32,'Episode Detail'!$AP$5:$AP$22,"Open",'Episode Detail'!$AL$5:$AL$22,"No") -> 0 | G32: =SUMIFS('Episode Detail'!$AC$5:$AC$22,'Episode Detail'!$AG$5:$AG$22,$B32,'Episode Detail'!$AL$5:$AL$22,"No") -> 0 | H32: =SUMIFS('Episode Detail'!$AD$5:$AD$22,'Episode Detail'!$AG$5:$AG$22,$B32,'Episode Detail'!$AL$5:$AL$22,"No") -> 0 | I32: =SUMIFS('Episode Detail'!$AE$5:$AE$22,'Episode Detail'!$AG$5:$AG$22,$B32,'Episode Detail'!$AL$5:$AL$22,"No") -> 0 | J32: =IFERROR(AVERAGEIFS('Episode Detail'!$Q$5:$Q$22,'Episode Detail'!$AG$5:$AG$22,$B32,'Episode Detail'!$S$5:$S$22,"Yes",'Episode Detail'!$AL$5:$AL$22,"No"),"")
B33: price_difference | D33: =COUNTIFS('Episode Detail'!$AG$5:$AG$22,$B33,'Episode Detail'!$AL$5:$AL$22,"No") -> 0 | E33: =SUMIFS('Episode Detail'!$U$5:$U$22,'Episode Detail'!$AG$5:$AG$22,$B33,'Episode Detail'!$AL$5:$AL$22,"No") -> 0 | F33: =SUMIFS('Episode Detail'!$AB$5:$AB$22,'Episode Detail'!$AG$5:$AG$22,$B33,'Episode Detail'!$AP$5:$AP$22,"Open",'Episode Detail'!$AL$5:$AL$22,"No") -> 0 | G33: =SUMIFS('Episode Detail'!$AC$5:$AC$22,'Episode Detail'!$AG$5:$AG$22,$B33,'Episode Detail'!$AL$5:$AL$22,"No") -> 0 | H33: =SUMIFS('Episode Detail'!$AD$5:$AD$22,'Episode Detail'!$AG$5:$AG$22,$B33,'Episode Detail'!$AL$5:$AL$22,"No") -> 0 | I33: =SUMIFS('Episode Detail'!$AE$5:$AE$22,'Episode Detail'!$AG$5:$AG$22,$B33,'Episode Detail'!$AL$5:$AL$22,"No") -> 0 | J33: =IFERROR(AVERAGEIFS('Episode Detail'!$Q$5:$Q$22,'Episode Detail'!$AG$5:$AG$22,$B33,'Episode Detail'!$S$5:$S$22,"Yes",'Episode Detail'!$AL$5:$AL$22,"No"),"")
B34: price_variance | D34: =COUNTIFS('Episode Detail'!$AG$5:$AG$22,$B34,'Episode Detail'!$AL$5:$AL$22,"No") -> 0 | E34: =SUMIFS('Episode Detail'!$U$5:$U$22,'Episode Detail'!$AG$5:$AG$22,$B34,'Episode Detail'!$AL$5:$AL$22,"No") -> 0 | F34: =SUMIFS('Episode Detail'!$AB$5:$AB$22,'Episode Detail'!$AG$5:$AG$22,$B34,'Episode Detail'!$AP$5:$AP$22,"Open",'Episode Detail'!$AL$5:$AL$22,"No") -> 0 | G34: =SUMIFS('Episode Detail'!$AC$5:$AC$22,'Episode Detail'!$AG$5:$AG$22,$B34,'Episode Detail'!$AL$5:$AL$22,"No") -> 0 | H34: =SUMIFS('Episode Detail'!$AD$5:$AD$22,'Episode Detail'!$AG$5:$AG$22,$B34,'Episode Detail'!$AL$5:$AL$22,"No") -> 0 | I34: =SUMIFS('Episode Detail'!$AE$5:$AE$22,'Episode Detail'!$AG$5:$AG$22,$B34,'Episode Detail'!$AL$5:$AL$22,"No") -> 0 | J34: =IFERROR(AVERAGEIFS('Episode Detail'!$Q$5:$Q$22,'Episode Detail'!$AG$5:$AG$22,$B34,'Episode Detail'!$S$5:$S$22,"Yes",'Episode Detail'!$AL$5:$AL$22,"No"),"")
B35: price_overcharge | D35: =COUNTIFS('Episode Detail'!$AG$5:$AG$22,$B35,'Episode Detail'!$AL$5:$AL$22,"No") -> 0 | E35: =SUMIFS('Episode Detail'!$U$5:$U$22,'Episode Detail'!$AG$5:$AG$22,$B35,'Episode Detail'!$AL$5:$AL$22,"No") -> 0 | F35: =SUMIFS('Episode Detail'!$AB$5:$AB$22,'Episode Detail'!$AG$5:$AG$22,$B35,'Episode Detail'!$AP$5:$AP$22,"Open",'Episode Detail'!$AL$5:$AL$22,"No") -> 0 | G35: =SUMIFS('Episode Detail'!$AC$5:$AC$22,'Episode Detail'!$AG$5:$AG$22,$B35,'Episode Detail'!$AL$5:$AL$22,"No") -> 0 | H35: =SUMIFS('Episode Detail'!$AD$5:$AD$22,'Episode Detail'!$AG$5:$AG$22,$B35,'Episode Detail'!$AL$5:$AL$22,"No") -> 0 | I35: =SUMIFS('Episode Detail'!$AE$5:$AE$22,'Episode Detail'!$AG$5:$AG$22,$B35,'Episode Detail'!$AL$5:$AL$22,"No") -> 0 | J35: =IFERROR(AVERAGEIFS('Episode Detail'!$Q$5:$Q$22,'Episode Detail'!$AG$5:$AG$22,$B35,'Episode Detail'!$S$5:$S$22,"Yes",'Episode Detail'!$AL$5:$AL$22,"No"),"")
B36: invoicing_error | D36: =COUNTIFS('Episode Detail'!$AG$5:$AG$22,$B36,'Episode Detail'!$AL$5:$AL$22,"No") -> 0 | E36: =SUMIFS('Episode Detail'!$U$5:$U$22,'Episode Detail'!$AG$5:$AG$22,$B36,'Episode Detail'!$AL$5:$AL$22,"No") -> 0 | F36: =SUMIFS('Episode Detail'!$AB$5:$AB$22,'Episode Detail'!$AG$5:$AG$22,$B36,'Episode Detail'!$AP$5:$AP$22,"Open",'Episode Detail'!$AL$5:$AL$22,"No") -> 0 | G36: =SUMIFS('Episode Detail'!$AC$5:$AC$22,'Episode Detail'!$AG$5:$AG$22,$B36,'Episode Detail'!$AL$5:$AL$22,"No") -> 0 | H36: =SUMIFS('Episode Detail'!$AD$5:$AD$22,'Episode Detail'!$AG$5:$AG$22,$B36,'Episode Detail'!$AL$5:$AL$22,"No") -> 0 | I36: =SUMIFS('Episode Detail'!$AE$5:$AE$22,'Episode Detail'!$AG$5:$AG$22,$B36,'Episode Detail'!$AL$5:$AL$22,"No") -> 0 | J36: =IFERROR(AVERAGEIFS('Episode Detail'!$Q$5:$Q$22,'Episode Detail'!$AG$5:$AG$22,$B36,'Episode Detail'!$S$5:$S$22,"Yes",'Episode Detail'!$AL$5:$AL$22,"No"),"")
B37: stock_variance | D37: =COUNTIFS('Episode Detail'!$AG$5:$AG$22,$B37,'Episode Detail'!$AL$5:$AL$22,"No") -> 0 | E37: =SUMIFS('Episode Detail'!$U$5:$U$22,'Episode Detail'!$AG$5:$AG$22,$B37,'Episode Detail'!$AL$5:$AL$22,"No") -> 0 | F37: =SUMIFS('Episode Detail'!$AB$5:$AB$22,'Episode Detail'!$AG$5:$AG$22,$B37,'Episode Detail'!$AP$5:$AP$22,"Open",'Episode Detail'!$AL$5:$AL$22,"No") -> 0 | G37: =SUMIFS('Episode Detail'!$AC$5:$AC$22,'Episode Detail'!$AG$5:$AG$22,$B37,'Episode Detail'!$AL$5:$AL$22,"No") -> 0 | H37: =SUMIFS('Episode Detail'!$AD$5:$AD$22,'Episode Detail'!$AG$5:$AG$22,$B37,'Episode Detail'!$AL$5:$AL$22,"No") -> 0 | I37: =SUMIFS('Episode Detail'!$AE$5:$AE$22,'Episode Detail'!$AG$5:$AG$22,$B37,'Episode Detail'!$AL$5:$AL$22,"No") -> 0 | J37: =IFERROR(AVERAGEIFS('Episode Detail'!$Q$5:$Q$22,'Episode Detail'!$AG$5:$AG$22,$B37,'Episode Detail'!$S$5:$S$22,"Yes",'Episode Detail'!$AL$5:$AL$22,"No"),"")
B38: isolation_error | D38: =COUNTIFS('Episode Detail'!$AG$5:$AG$22,$B38,'Episode Detail'!$AL$5:$AL$22,"No") -> 0 | E38: =SUMIFS('Episode Detail'!$U$5:$U$22,'Episode Detail'!$AG$5:$AG$22,$B38,'Episode Detail'!$AL$5:$AL$22,"No") -> 0 | F38: =SUMIFS('Episode Detail'!$AB$5:$AB$22,'Episode Detail'!$AG$5:$AG$22,$B38,'Episode Detail'!$AP$5:$AP$22,"Open",'Episode Detail'!$AL$5:$AL$22,"No") -> 0 | G38: =SUMIFS('Episode Detail'!$AC$5:$AC$22,'Episode Detail'!$AG$5:$AG$22,$B38,'Episode Detail'!$AL$5:$AL$22,"No") -> 0 | H38: =SUMIFS('Episode Detail'!$AD$5:$AD$22,'Episode Detail'!$AG$5:$AG$22,$B38,'Episode Detail'!$AL$5:$AL$22,"No") -> 0 | I38: =SUMIFS('Episode Detail'!$AE$5:$AE$22,'Episode Detail'!$AG$5:$AG$22,$B38,'Episode Detail'!$AL$5:$AL$22,"No") -> 0 | J38: =IFERROR(AVERAGEIFS('Episode Detail'!$Q$5:$Q$22,'Episode Detail'!$AG$5:$AG$22,$B38,'Episode Detail'!$S$5:$S$22,"Yes",'Episode Detail'!$AL$5:$AL$22,"No"),"")
B39: wrong_product_description | D39: =COUNTIFS('Episode Detail'!$AG$5:$AG$22,$B39,'Episode Detail'!$AL$5:$AL$22,"No") -> 0 | E39: =SUMIFS('Episode Detail'!$U$5:$U$22,'Episode Detail'!$AG$5:$AG$22,$B39,'Episode Detail'!$AL$5:$AL$22,"No") -> 0 | F39: =SUMIFS('Episode Detail'!$AB$5:$AB$22,'Episode Detail'!$AG$5:$AG$22,$B39,'Episode Detail'!$AP$5:$AP$22,"Open",'Episode Detail'!$AL$5:$AL$22,"No") -> 0 | G39: =SUMIFS('Episode Detail'!$AC$5:$AC$22,'Episode Detail'!$AG$5:$AG$22,$B39,'Episode Detail'!$AL$5:$AL$22,"No") -> 0 | H39: =SUMIFS('Episode Detail'!$AD$5:$AD$22,'Episode Detail'!$AG$5:$AG$22,$B39,'Episode Detail'!$AL$5:$AL$22,"No") -> 0 | I39: =SUMIFS('Episode Detail'!$AE$5:$AE$22,'Episode Detail'!$AG$5:$AG$22,$B39,'Episode Detail'!$AL$5:$AL$22,"No") -> 0 | J39: =IFERROR(AVERAGEIFS('Episode Detail'!$Q$5:$Q$22,'Episode Detail'!$AG$5:$AG$22,$B39,'Episode Detail'!$S$5:$S$22,"Yes",'Episode Detail'!$AL$5:$AL$22,"No"),"")
B40: wrong_code | D40: =COUNTIFS('Episode Detail'!$AG$5:$AG$22,$B40,'Episode Detail'!$AL$5:$AL$22,"No") -> 1 | E40: =SUMIFS('Episode Detail'!$U$5:$U$22,'Episode Detail'!$AG$5:$AG$22,$B40,'Episode Detail'!$AL$5:$AL$22,"No") -> 1 | F40: =SUMIFS('Episode Detail'!$AB$5:$AB$22,'Episode Detail'!$AG$5:$AG$22,$B40,'Episode Detail'!$AP$5:$AP$22,"Open",'Episode Detail'!$AL$5:$AL$22,"No") -> 2935 | G40: =SUMIFS('Episode Detail'!$AC$5:$AC$22,'Episode Detail'!$AG$5:$AG$22,$B40,'Episode Detail'!$AL$5:$AL$22,"No") -> 0 | H40: =SUMIFS('Episode Detail'!$AD$5:$AD$22,'Episode Detail'!$AG$5:$AG$22,$B40,'Episode Detail'!$AL$5:$AL$22,"No") -> 0 | I40: =SUMIFS('Episode Detail'!$AE$5:$AE$22,'Episode Detail'!$AG$5:$AG$22,$B40,'Episode Detail'!$AL$5:$AL$22,"No") -> 0 | J40: =IFERROR(AVERAGEIFS('Episode Detail'!$Q$5:$Q$22,'Episode Detail'!$AG$5:$AG$22,$B40,'Episode Detail'!$S$5:$S$22,"Yes",'Episode Detail'!$AL$5:$AL$22,"No"),"") -> 4
B41: system_error | D41: =COUNTIFS('Episode Detail'!$AG$5:$AG$22,$B41,'Episode Detail'!$AL$5:$AL$22,"No") -> 0 | E41: =SUMIFS('Episode Detail'!$U$5:$U$22,'Episode Detail'!$AG$5:$AG$22,$B41,'Episode Detail'!$AL$5:$AL$22,"No") -> 0 | F41: =SUMIFS('Episode Detail'!$AB$5:$AB$22,'Episode Detail'!$AG$5:$AG$22,$B41,'Episode Detail'!$AP$5:$AP$22,"Open",'Episode Detail'!$AL$5:$AL$22,"No") -> 0 | G41: =SUMIFS('Episode Detail'!$AC$5:$AC$22,'Episode Detail'!$AG$5:$AG$22,$B41,'Episode Detail'!$AL$5:$AL$22,"No") -> 0 | H41: =SUMIFS('Episode Detail'!$AD$5:$AD$22,'Episode Detail'!$AG$5:$AG$22,$B41,'Episode Detail'!$AL$5:$AL$22,"No") -> 0 | I41: =SUMIFS('Episode Detail'!$AE$5:$AE$22,'Episode Detail'!$AG$5:$AG$22,$B41,'Episode Detail'!$AL$5:$AL$22,"No") -> 0 | J41: =IFERROR(AVERAGEIFS('Episode Detail'!$Q$5:$Q$22,'Episode Detail'!$AG$5:$AG$22,$B41,'Episode Detail'!$S$5:$S$22,"Yes",'Episode Detail'!$AL$5:$AL$22,"No"),"")
...

Sheet Episode Detail
A1: Episode Detail — one row per (order, item, occurrence)
A2: As-at date: | B2: 46229 | C2: Promised lead time (days): | D2: Blue cells are parameters — edit these, not the formula columns.
A3: Lead time (days): | B3: 2
A4: Write-off threshold (working days): | B4: 7 | C4: Order Date | D4: Customer | E4: Main Account | F4: Channel | G4: Warehouse | H4: Inventory ID | I4: Item Description | J4: UOM | K4: Order Qty | L4: Unit Price (net) | M4: Backordered On | N4: Resolved On | O4: Window | P4: Days (calendar) | Q4: Days (working) | R4: Delay Label | S4: Start Date Verified? | T4: Episode No. | U4: Peak Backorder Qty | V4: Current Backorder Qty | W4: Shipped Qty | X4: Shipped Late Qty | Y4: Cancelled Qty | Z4: Partial Fills | AA4: Fill Rate % | AB4: Revenue at Risk | AC4: Delayed Revenue | AD4: Revenue-Days Delayed | AE4: Lost Revenue | AF4: Resolution Type | AG4: Reason Code | AH4: Reason Family | AI4: Reason Notes | AJ4: Reason Set By | AK4: Reason Set At | AL4: Excluded from KPI? | AM4: Exclusion Reason | AN4: Sync Run (opened) | AO4: Sync Run (resolved) | AP4: State | AQ4: Order 1st open row | AR4: Item 1st open row
A5: SO363506 | B5: SO | C5: 46213 | D5: Khetia Drapers Ltd - Plus | E5: Khetia Drapers Ltd | F5: Modern Trade T2 | G5: FGS | H5: SIFTP0015 | I5: Sifa TP Emb. Unwrap. Twinpack 20x2s White | J5: CASE | K5: 1356 | L5: 142.55 | M5: 46213 | O5: =IF(N5="",TEXT(M5,"d mmm yyyy")&" – ongoing",IF(TEXT(M5,"mmmyyyy")=TEXT(N5,"mmmyyyy"),TEXT(M5,"d")&" – "&TEXT(N5,"d mmm yyyy"),IF(TEXT(M5,"yyyy")=TEXT(N5,"yyyy"),TEXT(M5,"d mmm")&" – "&TEXT(N5,"d mmm yyyy"),TEXT(M5,"d mmm yyyy")&" – "&TEXT(N5,"d mmm yyyy")))) -> 10 Jul 2026 – ongoing | P5: =IF(N5="",$B$2-M5,N5-M5) -> 16 | Q5: =IF(N5="",NETWORKDAYS.INTL(M5,$B$2,"0000001")-1,NETWORKDAYS.INTL(M5,N5,"0000001")-1) -> 13 | R5: =IF(Q5=0,"Same Day",Q5&IF(Q5=1," Day Delay"," Days Delay")&IF(S5="Yes",""," (min.)")) -> 13 Days Delay | S5: Yes | T5: 1 | U5: 680 | V5: 420 | W5: 936 | X5: 0 | Y5: 0 | Z5: 2 | AA5: =IFERROR(W5/(K5-Y5),"") -> 0.69026549 | AB5: =V5*L5 -> 59871 | AC5: =X5*L5 -> 0 | AD5: =AC5*MAX(0,Q5-$B$3) -> 0 | AE5: =IF(AF5="cancelled",Y5*L5,IF(AND(N5="",Q5>$B$4),V5*L5,Y5*L5)) -> 59871 | AG5: out_of_stock_production | AH5: PRODUCTION | AI5: Mill line 2 down 11-14 Jul | AJ5: j.mwangi | AK5: 46214 | AL5: No | AN5: 48100 | AP5: =IF(ISBLANK(N5),"Open","Resolved") -> Open | AQ5: =IF(AND($AP5="Open",$AL5="No",COUNTIFS($A$5:$A5,$A5,$AP$5:$AP5,"Open",$AL$5:$AL5,"No")=1),1,0) -> 1 | AR5: =IF(AND($AP5="Open",$AL5="No",COUNTIFS($H$5:$H5,$H5,$AP$5:$AP5,"Open",$AL$5:$AL5,"No")=1),1,0) -> 1
A6: SO363491 | B6: SO | C6: 46213 | D6: Khetia Drapers Ltd - Gigamart | E6: Khetia Drapers Ltd | F6: Modern Trade T2 | G6: FGS | H6: SIFTP0015 | I6: Sifa TP Emb. Unwrap. Twinpack 20x2s White | J6: CASE | K6: 1086 | L6: 142.55 | M6: 46213 | O6: =IF(N6="",TEXT(M6,"d mmm yyyy")&" – ongoing",IF(TEXT(M6,"mmmyyyy")=TEXT(N6,"mmmyyyy"),TEXT(M6,"d")&" – "&TEXT(N6,"d mmm yyyy"),IF(TEXT(M6,"yyyy")=TEXT(N6,"yyyy"),TEXT(M6,"d mmm")&" – "&TEXT(N6,"d mmm yyyy"),TEXT(M6,"d mmm yyyy")&" – "&TEXT(N6,"d mmm yyyy")))) -> 10 Jul 2026 – ongoing | P6: =IF(N6="",$B$2-M6,N6-M6) -> 16 | Q6: =IF(N6="",NETWORKDAYS.INTL(M6,$B$2,"0000001")-1,NETWORKDAYS.INTL(M6,N6,"0000001")-1) -> 13 | R6: =IF(Q6=0,"Same Day",Q6&IF(Q6=1," Day Delay"," Days Delay")&IF(S6="Yes",""," (min.)")) -> 13 Days Delay | S6: Yes | T6: 1 | U6: 594 | V6: 528 | W6: 558 | X6: 0 | Y6: 0 | Z6: 1 | AA6: =IFERROR(W6/(K6-Y6),"") -> 0.51381215 | AB6: =V6*L6 -> 75266.4 | AC6: =X6*L6 -> 0 | AD6: =AC6*MAX(0,Q6-$B$3) -> 0 | AE6: =IF(AF6="cancelled",Y6*L6,IF(AND(N6="",Q6>$B$4),V6*L6,Y6*L6)) -> 75266.4 | AG6: out_of_stock_production | AH6: PRODUCTION | AI6: Same mill event | AJ6: j.mwangi | AK6: 46214 | AL6: No | AN6: 48103 | AP6: =IF(ISBLANK(N6),"Open","Resolved") -> Open | AQ6: =IF(AND($AP6="Open",$AL6="No",COUNTIFS($A$5:$A6,$A6,$AP$5:$AP6,"Open",$AL$5:$AL6,"No")=1),1,0) -> 1 | AR6: =IF(AND($AP6="Open",$AL6="No",COUNTIFS($H$5:$H6,$H6,$AP$5:$AP6,"Open",$AL$5:$AL6,"No")=1),1,0) -> 0
A7: SO363495 | B7: SO | C7: 46213 | D7: Khetia Drapers Ltd - Eldoret CBD | E7: Khetia Drapers Ltd | F7: Modern Trade T2 | G7: FGS | H7: COSTP0004 | I7: Cosy TP Emb. Wrap. 40s Singles White | J7: CASE | K7: 1128 | L7: 64.55 | M7: 46213 | O7: =IF(N7="",TEXT(M7,"d mmm yyyy")&" – ongoing",IF(TEXT(M7,"mmmyyyy")=TEXT(N7,"mmmyyyy"),TEXT(M7,"d")&" – "&TEXT(N7,"d mmm yyyy"),IF(TEXT(M7,"yyyy")=TEXT(N7,"yyyy"),TEXT(M7,"d mmm")&" – "&TEXT(N7,"d mmm yyyy"),TEXT(M7,"d mmm yyyy")&" – "&TEXT(N7,"d mmm yyyy")))) -> 10 Jul 2026 – ongoing | P7: =IF(N7="",$B$2-M7,N7-M7) -> 16 | Q7: =IF(N7="",NETWORKDAYS.INTL(M7,$B$2,"0000001")-1,NETWORKDAYS.INTL(M7,N7,"0000001")-1) -> 13 | R7: =IF(Q7=0,"Same Day",Q7&IF(Q7=1," Day Delay"," Days Delay")&IF(S7="Yes",""," (min.)")) -> 13 Days Delay | S7: Yes | T7: 1 | U7: 542 | V7: 510 | W7: 618 | X7: 0 | Y7: 0 | Z7: 1 | AA7: =IFERROR(W7/(K7-Y7),"") -> 0.54787234 | AB7: =V7*L7 -> 32920.5 | AC7: =X7*L7 -> 0 | AD7: =AC7*MAX(0,Q7-$B$3) -> 0 | AE7: =IF(AF7="cancelled",Y7*L7,IF(AND(N7="",Q7>$B$4),V7*L7,Y7*L7)) -> 32920.5 | AG7: raw_material_stockout | AH7: PRODUCTION | AI7: Parent reel short shipped | AJ7: j.mwangi | AK7: 46215 | AL7: No | AN7: 48106 | AP7: =IF(ISBLANK(N7),"Open","Resolved") -> Open | AQ7: =IF(AND($AP7="Open",$AL7="No",COUNTIFS($A$5:$A7,$A7,$AP$5:$AP7,"Open",$AL$5:$AL7,"No")=1),1,0) -> 1 | AR7: =IF(AND($AP7="Open",$AL7="No",COUNTIFS($H$5:$H7,$H7,$AP$5:$AP7,"Open",$AL$5:$AL7,"No")=1),1,0) -> 1
A8: SO363507 | B8: SO | C8: 46213 | D8: Khetia Drapers Ltd - Kakamega Poa | E8: Khetia Drapers Ltd | F8: Modern Trade T2 | G8: FGS | H8: COSTP0006 | I8: Cosy TP Emb. Unwrap. 4x10s White | J8: CASE | K8: 876 | L8: 64.55 | M8: 46213 | N8: 46225 | O8: =IF(N8="",TEXT(M8,"d mmm yyyy")&" – ongoing",IF(TEXT(M8,"mmmyyyy")=TEXT(N8,"mmmyyyy"),TEXT(M8,"d")&" – "&TEXT(N8,"d mmm yyyy"),IF(TEXT(M8,"yyyy")=TEXT(N8,"yyyy"),TEXT(M8,"d mmm")&" – "&TEXT(N8,"d mmm yyyy"),TEXT(M8,"d mmm yyyy")&" – "&TEXT(N8,"d mmm yyyy")))) -> 10 – 22 Jul 2026 | P8: =IF(N8="",$B$2-M8,N8-M8) -> 12 | Q8: =IF(N8="",NETWORKDAYS.INTL(M8,$B$2,"0000001")-1,NETWORKDAYS.INTL(M8,N8,"0000001")-1) -> 10 | R8: =IF(Q8=0,"Same Day",Q8&IF(Q8=1," Day Delay"," Days Delay")&IF(S8="Yes",""," (min.)")) -> 10 Days Delay | S8: Yes | T8: 1 | U8: 514 | V8: 0 | W8: 876 | X8: 514 | Y8: 0 | Z8: 3 | AA8: =IFERROR(W8/(K8-Y8),"") -> 1 | AB8: =V8*L8 -> 0 | AC8: =X8*L8 -> 33178.7 | AD8: =AC8*MAX(0,Q8-$B$3) -> 265429.6 | AE8: =IF(AF8="cancelled",Y8*L8,IF(AND(N8="",Q8>$B$4),V8*L8,Y8*L8)) -> 0 | AF8: shipped_full | AG8: out_of_stock_production | AH8: PRODUCTION | AI8: Cleared on 22 Jul run | AJ8: j.mwangi | AK8: 46215 | AL8: No | AN8: 48109 | AO8: 48189 | AP8: =IF(ISBLANK(N8),"Open","Resolved") -> Resolved | AQ8: =IF(AND($AP8="Open",$AL8="No",COUNTIFS($A$5:$A8,$A8,$AP$5:$AP8,"Open",$AL$5:$AL8,"No")=1),1,0) -> 0 | AR8: =IF(AND($AP8="Open",$AL8="No",COUNTIFS($H$5:$H8,$H8,$AP$5:$AP8,"Open",$AL$5:$AL8,"No")=1),1,0) -> 0
A9: SO363603 | B9: SO | C9: 46213 | D9: Khetia Drapers Ltd - Thika | E9: Khetia Drapers Ltd | F9: Modern Trade T2 | G9: FGS | H9: FAYTP0013 | I9: Fay TP Emb. Wrap. 40s Singles White | J9: CASE | K9: 965 | L9: 73.3 | M9: 46213 | N9: 46223 | O9: =IF(N9="",TEXT(M9,"d mmm yyyy")&" – ongoing",IF(TEXT(M9,"mmmyyyy")=TEXT(N9,"mmmyyyy"),TEXT(M9,"d")&" – "&TEXT(N9,"d mmm yyyy"),IF(TEXT(M9,"yyyy")=TEXT(N9,"yyyy"),TEXT(M9,"d mmm")&" – "&TEXT(N9,"d mmm yyyy"),TEXT(M9,"d mmm yyyy")&" – "&TEXT(N9,"d mmm yyyy")))) -> 10 – 20 Jul 2026 | P9: =IF(N9="",$B$2-M9,N9-M9) -> 10 | Q9: =IF(N9="",NETWORKDAYS.INTL(M9,$B$2,"0000001")-1,NETWORKDAYS.INTL(M9,N9,"0000001")-1) -> 8 | R9: =IF(Q9=0,"Same Day",Q9&IF(Q9=1," Day Delay"," Days Delay")&IF(S9="Yes",""," (min.)")) -> 8 Days Delay | S9: Yes | T9: 1 | U9: 478 | V9: 0 | W9: 890 | X9: 478 | Y9: 75 | Z9: 2 | AA9: =IFERROR(W9/(K9-Y9),"") -> 1 | AB9: =V9*L9 -> 0 | AC9: =X9*L9 -> 35037.4 | AD9: =AC9*MAX(0,Q9-$B$3) -> 210224.4 | AE9: =IF(AF9="cancelled",Y9*L9,IF(AND(N9="",Q9>$B$4),V9*L9,Y9*L9)) -> 5497.5 | AF9: shipped_partial | AG9: out_of_stock_production | AH9: PRODUCTION | AI9: 75 CASE cancelled by buyer | AJ9: j.mwangi | AK9: 46215 | AL9: No | AN9: 48112 | AO9: 48192 | AP9: =IF(ISBLANK(N9),"Open","Resolved") -> Resolved | AQ9: =IF(AND($AP9="Open",$AL9="No",COUNTIFS($A$5:$A9,$A9,$AP$5:$AP9,"Open",$AL$5:$AL9,"No")=1),1,0) -> 0 | AR9: =IF(AND($AP9="Open",$AL9="No",COUNTIFS($H$5:$H9,$H9,$AP$5:$AP9,"Open",$AL$5:$AL9,"No")=1),1,0) -> 0
A10: SO367035 | B10: SO | C10: 46226 | D10: Majid Al Futtaim Hypermarkets Ltd - Business Bay Square | E10: Majid Al Futtaim Hypermarkets Ltd | F10: Modern Trade T1 | G10: FGS | H10: FAYFL0010 | I10: Fay Aluminium Foil Catering (45x50m) | J10: ROLL | K10: 24 | L10: 2542.53 | M10: 46226 | O10: =IF(N10="",TEXT(M10,"d mmm yyyy")&" – ongoing",IF(TEXT(M10,"mmmyyyy")=TEXT(N10,"mmmyyyy"),TEXT(M10,"d")&" – "&TEXT(N10,"d mmm yyyy"),IF(TEXT(M10,"yyyy")=TEXT(N10,"yyyy"),TEXT(M10,"d mmm")&" – "&TEXT(N10,"d mmm yyyy"),TEXT(M10,"d mmm yyyy")&" – "&TEXT(N10,"d mmm yyyy")))) -> 23 Jul 2026 – ongoing | P10: =IF(N10="",$B$2-M10,N10-M10) -> 3 | Q10: =IF(N10="",NETWORKDAYS.INTL(M10,$B$2,"0000001")-1,NETWORKDAYS.INTL(M10,N10,"0000001")-1) -> 2 | R10: =IF(Q10=0,"Same Day",Q10&IF(Q10=1," Day Delay"," Days Delay")&IF(S10="Yes",""," (min.)")) -> 2 Days Delay | S10: Yes | T10: 1 | U10: 24 | V10: 24 | W10: 0 | X10: 0 | Y10: 0 | Z10: 0 | AA10: =IFERROR(W10/(K10-Y10),"") -> 0 | AB10: =V10*L10 -> 61020.72 | AC10: =X10*L10 -> 0 | AD10: =AC10*MAX(0,Q10-$B$3) -> 0 | AE10: =IF(AF10="cancelled",Y10*L10,IF(AND(N10="",Q10>$B$4),V10*L10,Y10*L10)) -> 0 | AG10: out_of_stock_procurement | AH10: PROCUREMENT | AI10: Import ETA 29 Jul | AJ10: a.otieno | AK10: 46226 | AL10: No | AN10: 48115 | AP10: =IF(ISBLANK(N10),"Open","Resolved") -> Open | AQ10: =IF(AND($AP10="Open",$AL10="No",COUNTIFS($A$5:$A10,$A10,$AP$5:$AP10,"Open",$AL$5:$AL10,"No")=1),1,0) -> 1 | AR10: =IF(AND($AP10="Open",$AL10="No",COUNTIFS($H$5:$H10,$H10,$AP$5:$AP10,"Open",$AL$5:$AL10,"No")=1),1,0) -> 1
A11: SO367021 | B11: SO | C11: 46226 | D11: Majid Al Futtaim Hypermarkets Ltd - The Hub | E11: Majid Al Futtaim Hypermarkets Ltd | F11: Modern Trade T1 | G11: FGS | H11: FAYFL0010 | I11: Fay Aluminium Foil Catering (45x50m) | J11: ROLL | K11: 18 | L11: 1649.14 | M11: 46226 | O11: =IF(N11="",TEXT(M11,"d mmm yyyy")&" – ongoing",IF(TEXT(M11,"mmmyyyy")=TEXT(N11,"mmmyyyy"),TEXT(M11,"d")&" – "&TEXT(N11,"d mmm yyyy"),IF(TEXT(M11,"yyyy")=TEXT(N11,"yyyy"),TEXT(M11,"d mmm")&" – "&TEXT(N11,"d mmm yyyy"),TEXT(M11,"d mmm yyyy")&" – "&TEXT(N11,"d mmm yyyy")))) -> 23 Jul 2026 – ongoing | P11: =IF(N11="",$B$2-M11,N11-M11) -> 3 | Q11: =IF(N11="",NETWORKDAYS.INTL(M11,$B$2,"0000001")-1,NETWORKDAYS.INTL(M11,N11,"0000001")-1) -> 2 | R11: =IF(Q11=0,"Same Day",Q11&IF(Q11=1," Day Delay"," Days Delay")&IF(S11="Yes",""," (min.)")) -> 2 Days Delay | S11: Yes | T11: 1 | U11: 18 | V11: 18 | W11: 0 | X11: 0 | Y11: 0 | Z11: 0 | AA11: =IFERROR(W11/(K11-Y11),"") -> 0 | AB11: =V11*L11 -> 29684.52 | AC11: =X11*L11 -> 0 | AD11: =AC11*MAX(0,Q11-$B$3) -> 0 | AE11: =IF(AF11="cancelled",Y11*L11,IF(AND(N11="",Q11>$B$4),V11*L11,Y11*L11)) -> 0 | AG11: out_of_stock_procurement | AH11: PROCUREMENT | AI11: Same import | AJ11: a.otieno | AK11: 46226 | AL11: No | AN11: 48118 | AP11: =IF(ISBLANK(N11),"Open","Resolved") -> Open | AQ11: =IF(AND($AP11="Open",$AL11="No",COUNTIFS($A$5:$A11,$A11,$AP$5:$AP11,"Open",$AL$5:$AL11,"No")=1),1,0) -> 1 | AR11: =IF(AND($AP11="Open",$AL11="No",COUNTIFS($H$5:$H11,$H11,$AP$5:$AP11,"Open",$AL$5:$AL11,"No")=1),1,0) -> 0
A12: SO364962 | B12: SO | C12: 46219 | D12: Quick Mart Ltd- Nakuru Statehouse | E12: Quick Mart Ltd | F12: Modern Trade T1 | G12: FGS | H12: FAYFL0010 | I12: Fay Aluminium Foil Catering (45x50m) | J12: ROLL | K12: 12 | L12: 2542.53 | M12: 46219 | O12: =IF(N12="",TEXT(M12,"d mmm yyyy")&" – ongoing",IF(TEXT(M12,"mmmyyyy")=TEXT(N12,"mmmyyyy"),TEXT(M12,"d")&" – "&TEXT(N12,"d mmm yyyy"),IF(TEXT(M12,"yyyy")=TEXT(N12,"yyyy"),TEXT(M12,"d mmm")&" – "&TEXT(N12,"d mmm yyyy"),TEXT(M12,"d mmm yyyy")&" – "&TEXT(N12,"d mmm yyyy")))) -> 16 Jul 2026 – ongoing | P12: =IF(N12="",$B$2-M12,N12-M12) -> 10 | Q12: =IF(N12="",NETWORKDAYS.INTL(M12,$B$2,"0000001")-1,NETWORKDAYS.INTL(M12,N12,"0000001")-1) -> 8 | R12: =IF(Q12=0,"Same Day",Q12&IF(Q12=1," Day Delay"," Days Delay")&IF(S12="Yes",""," (min.)")) -> 8 Days Delay | S12: Yes | T12: 1 | U12: 12 | V12: 12 | W12: 0 | X12: 0 | Y12: 0 | Z12: 0 | AA12: =IFERROR(W12/(K12-Y12),"") -> 0 | AB12: =V12*L12 -> 30510.36 | AC12: =X12*L12 -> 0 | AD12: =AC12*MAX(0,Q12-$B$3) -> 0 | AE12: =IF(AF12="cancelled",Y12*L12,IF(AND(N12="",Q12>$B$4),V12*L12,Y12*L12)) -> 30510.36 | AG12: out_of_stock_procurement | AH12: PROCUREMENT | AI12: Same import | AJ12: a.otieno | AK12: 46220 | AL12: No | AN12: 48121 | AP12: =IF(ISBLANK(N12),"Open","Resolved") -> Open | AQ12: =IF(AND($AP12="Open",$AL12="No",COUNTIFS($A$5:$A12,$A12,$AP$5:$AP12,"Open",$AL$5:$AL12,"No")=1),1,0) -> 1 | AR12: =IF(AND($AP12="Open",$AL12="No",COUNTIFS($H$5:$H12,$H12,$AP$5:$AP12,"Open",$AL$5:$AL12,"No")=1),1,0) -> 0
A13: SO364948 | B13: SO | C13: 46218 | D13: Quick Mart Ltd - Rongai | E13: Quick Mart Ltd | F13: Modern Trade T1 | G13: FGS | H13: FAYCL0009 | I13: Fay Cling Film Catering 30cmx300m GP | J13: PIECE | K13: 6 | L13: 2756.9 | M13: 46218 | O13: =IF(N13="",TEXT(M13,"d mmm yyyy")&" – ongoing",IF(TEXT(M13,"mmmyyyy")=TEXT(N13,"mmmyyyy"),TEXT(M13,"d")&" – "&TEXT(N13,"d mmm yyyy"),IF(TEXT(M13,"yyyy")=TEXT(N13,"yyyy"),TEXT(M13,"d mmm")&" – "&TEXT(N13,"d mmm yyyy"),TEXT(M13,"d mmm yyyy")&" – "&TEXT(N13,"d mmm yyyy")))) -> 15 Jul 2026 – ongoing | P13: =IF(N13="",$B$2-M13,N13-M13) -> 11 | Q13: =IF(N13="",NETWORKDAYS.INTL(M13,$B$2,"0000001")-1,NETWORKDAYS.INTL(M13,N13,"0000001")-1) -> 9 | R13: =IF(Q13=0,"Same Day",Q13&IF(Q13=1," Day Delay"," Days Delay")&IF(S13="Yes",""," (min.)")) -> 9 Days Delay | S13: Yes | T13: 1 | U13: 6 | V13: 6 | W13: 0 | X13: 0 | Y13: 0 | Z13: 0 | AA13: =IFERROR(W13/(K13-Y13),"") -> 0 | AB13: =V13*L13 -> 16541.4 | AC13: =X13*L13 -> 0 | AD13: =AC13*MAX(0,Q13-$B$3) -> 0 | AE13: =IF(AF13="cancelled",Y13*L13,IF(AND(N13="",Q13>$B$4),V13*L13,Y13*L13)) -> 16541.4 | AG13: conversion_delays | AH13: PRODUCTION | AI13: Awaiting converting slot | AJ13: a.otieno | AK13: 46220 | AL13: No | AN13: 48124 | AP13: =IF(ISBLANK(N13),"Open","Resolved") -> Open | AQ13: =IF(AND($AP13="Open",$AL13="No",COUNTIFS($A$5:$A13,$A13,$AP$5:$AP13,"Open",$AL$5:$AL13,"No")=1),1,0) -> 1 | AR13: =IF(AND($AP13="Open",$AL13="No",COUNTIFS($H$5:$H13,$H13,$AP$5:$AP13,"Open",$AL$5:$AL13,"No")=1),1,0) -> 1
A14: SO364955 | B14: SO | C14: 46218 | D14: Quick Mart Ltd - Nakuru | E14: Quick Mart Ltd | F14: Modern Trade T1 | G14: FGS | H14: FAYCL0009 | I14: Fay Cling Film Catering 30cmx300m GP | J14: PIECE | K14: 6 | L14: 2756.9 | M14: 46218 | O14: =IF(N14="",TEXT(M14,"d mmm yyyy")&" – ongoing",IF(TEXT(M14,"mmmyyyy")=TEXT(N14,"mmmyyyy"),TEXT(M14,"d")&" – "&TEXT(N14,"d mmm yyyy"),IF(TEXT(M14,"yyyy")=TEXT(N14,"yyyy"),TEXT(M14,"d mmm")&" – "&TEXT(N14,"d mmm yyyy"),TEXT(M14,"d mmm yyyy")&" – "&TEXT(N14,"d mmm yyyy")))) -> 15 Jul 2026 – ongoing | P14: =IF(N14="",$B$2-M14,N14-M14) -> 11 | Q14: =IF(N14="",NETWORKDAYS.INTL(M14,$B$2,"0000001")-1,NETWORKDAYS.INTL(M14,N14,"0000001")-1) -> 9 | R14: =IF(Q14=0,"Same Day",Q14&IF(Q14=1," Day Delay"," Days Delay")&IF(S14="Yes",""," (min.)")) -> 9 Days Delay | S14: Yes | T14: 1 | U14: 6 | V14: 6 | W14: 0 | X14: 0 | Y14: 0 | Z14: 0 | AA14: =IFERROR(W14/(K14-Y14),"") -> 0 | AB14: =V14*L14 -> 16541.4 | AC14: =X14*L14 -> 0 | AD14: =AC14*MAX(0,Q14-$B$3) -> 0 | AE14: =IF(AF14="cancelled",Y14*L14,IF(AND(N14="",Q14>$B$4),V14*L14,Y14*L14)) -> 16541.4 | AG14: conversion_delays | AH14: PRODUCTION | AI14: Awaiting converting slot | AJ14: a.otieno | AK14: 46220 | AL14: No | AN14: 48127 | AP14: =IF(ISBLANK(N14),"Open","Resolved") -> Open | AQ14: =IF(AND($AP14="Open",$AL14="No",COUNTIFS($A$5:$A14,$A14,$AP$5:$AP14,"Open",$AL$5:$AL14,"No")=1),1,0) -> 1 | AR14: =IF(AND($AP14="Open",$AL14="No",COUNTIFS($H$5:$H14,$H14,$AP$5:$AP14,"Open",$AL$5:$AL14,"No")=1),1,0) -> 0
A15: SO365985 | B15: SO | C15: 46223 | D15: Sam West Distributors LTD | E15: Sam West Distributors LTD | F15: General Trade | G15: FGS | H15: TISTP0008 | I15: Tishu Poa TP Emb. Wrap. 4x10s White 100s | J15: CASE | K15: 980 | L15: 860.17 | M15: 46223 | N15: 46225 | O15: =IF(N15="",TEXT(M15,"d mmm yyyy")&" – ongoing",IF(TEXT(M15,"mmmyyyy")=TEXT(N15,"mmmyyyy"),TEXT(M15,"d")&" – "&TEXT(N15,"d mmm yyyy"),IF(TEXT(M15,"yyyy")=TEXT(N15,"yyyy"),TEXT(M15,"d mmm")&" – "&TEXT(N15,"d mmm yyyy"),TEXT(M15,"d mmm yyyy")&" – "&TEXT(N15,"d mmm yyyy")))) -> 20 – 22 Jul 2026 | P15: =IF(N15="",$B$2-M15,N15-M15) -> 2 | Q15: =IF(N15="",NETWORKDAYS.INTL(M15,$B$2,"0000001")-1,NETWORKDAYS.INTL(M15,N15,"0000001")-1) -> 2 | R15: =IF(Q15=0,"Same Day",Q15&IF(Q15=1," Day Delay"," Days Delay")&IF(S15="Yes",""," (min.)")) -> 2 Days Delay | S15: Yes | T15: 1 | U15: 262 | V15: 0 | W15: 980 | X15: 262 | Y15: 0 | Z15: 3 | AA15: =IFERROR(W15/(K15-Y15),"") -> 1 | AB15: =V15*L15 -> 0 | AC15: =X15*L15 -> 225364.54 | AD15: =AC15*MAX(0,Q15-$B$3) -> 0 | AE15: =IF(AF15="cancelled",Y15*L15,IF(AND(N15="",Q15>$B$4),V15*L15,Y15*L15)) -> 0 | AF15: shipped_full | AG15: transfer_delays | AH15: LOGISTICS | AI15: Inter-warehouse transfer 2 days late | AJ15: p.kamau | AK15: 46224 | AL15: No | AN15: 48130 | AO15: 48210 | AP15: =IF(ISBLANK(N15),"Open","Resolved") -> Resolved | AQ15: =IF(AND($AP15="Open",$AL15="No",COUNTIFS($A$5:$A15,$A15,$AP$5:$AP15,"Open",$AL$5:$AL15,"No")=1),1,0) -> 0 | AR15: =IF(AND($AP15="Open",$AL15="No",COUNTIFS($H$5:$H15,$H15,$AP$5:$AP15,"Open",$AL$5:$AL15,"No")=1),1,0) -> 0
